Workbook

Sheet ФАКТ 2024
E1: 01.2024 | F1: 02.2024 | G1: 03.2024 | H1: 04.2024 | I1: 05.2024 | J1: 06.2024 | K1: 07.2024 | L1: 08.2024 | M1: 09.2024 | N1: 10.2024 | O1: 11.2024 | P1: 12.2024 | Q1: 45658
A2: КЛО_МРЦ | B2: Киев,Фора МРЦ Оросительная,5 | C2: ИТОГО 2024 | D2: % К ОБОРОТУ | E2: 45292 | F2: 45323 | G2: 45352 | H2: 45383 | I2: 45413 | J2: 45444 | K2: 45474 | L2: 45505 | M2: 45536 | N2: 45566 | O2: 45597 | P2: 45627 | Q2: 45658
A3: Доходы
A4: Код | B4: 1. Выручка | C4: 681330.86 | D4: 5.1821135e-05 | E4: 183621.9 | F4: 105830.36 | G4: 83405.79 | H4: 165711.28 | I4: 142761.53 | J4: 109287.22 | K4: 146074.91 | L4: 124682.94 | M4: =SUM(M5:M13) -> 171168.47 | N4: 128016.34 | O4: 68150.28 | P4: 40121.3 | Q4: 56312.5
A5: 70200000 | B5: ДоходРеалТовара | C5: 681330.86 | D5: 5.1821135e-05 | E5: 183621.9 | F5: 105830.36 | G5: 83405.79 | H5: 165711.28 | I5: 142761.53 | J5: 109287.22 | K5: 146074.91 | L5: 124682.94 | M5: 171168.47 | N5: 128016.34 | O5: 68150.28 | P5: 40121.3 | Q5: 56312.5
A6: 70200001 | B6: ДоходРеалПрогрЛояльн | C6: 0 | D6: 0 | E6: 0 | F6: 0 | G6: 0 | H6: 0 | I6: 0 | J6: 0 | K6: 0 | L6: 0 | M6: 0 | N6: 0 | O6: 0 | P6: 0 | Q6: 0
A7: 70200002 | B7: ДоходРеалТВаучера | C7: 0 | D7: 0 | E7: 0 | F7: 0 | G7: 0 | H7: 0 | I7: 0 | J7: 0 | K7: 0 | L7: 0 | M7: 0 | N7: 0 | O7: 0 | P7: 0 | Q7: 0
A8: 70200003 | B8: ДоходРеалТовКомиссия | C8: 0 | D8: 0 | E8: 0 | F8: 0 | G8: 0 | H8: 0 | I8: 0 | J8: 0 | K8: 0 | L8: 0 | M8: 0 | N8: 0 | O8: 0 | P8: 0 | Q8: 0
A9: 70200004 | B9: ДоходРеалАгентсДог | C9: 0 | D9: 0 | E9: 0 | F9: 0 | G9: 0 | H9: 0 | I9: 0 | J9: 0 | K9: 0 | L9: 0 | M9: 0 | N9: 0 | O9: 0 | P9: 0 | Q9: 0
A10: 70200009 | B10: Недополучен.выручка | C10: 0 | D10: 0 | E10: 0 | F10: 0 | G10: 0 | H10: 0 | I10: 0 | J10: 0 | K10: 0 | L10: 0 | M10: 0 | N10: 0 | O10: 0 | P10: 0 | Q10: 0
A11: 70200200 | B11: ДоходРеалТовЭкспорт | C11: 0 | D11: 0 | E11: 0 | F11: 0 | G11: 0 | H11: 0 | I11: 0 | J11: 0 | K11: 0 | L11: 0 | M11: 0 | N11: 0 | O11: 0 | P11: 0 | Q11: 0
A12: 70400000 | B12: ВычетыДоходТовар | C12: 0 | D12: 0 | E12: 0 | F12: 0 | G12: 0 | H12: 0 | I12: 0 | J12: 0 | K12: 0 | L12: 0 | M12: 0 | N12: 0 | O12: 0 | P12: 0 | Q12: 0
A13: 70430000 | B13: ВычетыДоходАгентсДог | C13: 0 | D13: 0 | E13: 0 | F13: 0 | G13: 0 | H13: 0 | I13: 0 | J13: 0 | K13: 0 | L13: 0 | M13: 0 | N13: 0 | O13: 0 | P13: 0 | Q13: 0
A14: 1
A15: 1 | B15: 2. Себестоимость | C15: -882994.65 | D15: -6.7159419e-05 | E15: -196589.95 | F15: -110137.22 | G15: -91151.58 | H15: -175001.97 | I15: -310113.93 | J15: -107949.08 | K15: 334795.8 | L15: -116384.02 | M15: -176431.82 | N15: -328962.69 | O15: -74351.6 | P15: -43172.07 | Q15: -63168.81
A16: 90200000 | B16: СебестРеализТоваров | C16: -237145.18 | D16: -1.8036952e-05 | E16: 0 | F16: 0 | G16: 0 | H16: 0 | I16: -237145.18 | J16: 0 | K16: -35.23 | L16: -31.96 | M16: 0 | N16: -239193.28 | O16: 0 | P16: 0 | Q16: 0
A17: 90200001 | B17: СебестРеалТоваровПро | C17: -645849.47 | D17: -4.9122467e-05 | E17: -196589.95 | F17: -110137.22 | G17: -91151.58 | H17: -175001.97 | I17: -72968.75 | J17: -107949.08 | K17: 334831.03 | L17: -116352.06 | M17: -176431.82 | N17: -89769.41 | O17: -74351.6 | P17: -43172.07 | Q17: -63168.81
A18: 1
A19: 1 | B19: 3. Валовая маржа | C19: -201663.79 | D19: -1.5338284e-05 | E19: -12968.05 | F19: -4306.86 | G19: -7745.79 | H19: -9290.69 | I19: -167352.4 | J19: 1338.14 | K19: 480870.71 | L19: 8298.92 | M19: -5263.35 | N19: -200946.35 | O19: -6201.32 | P19: -3050.77 | Q19: -6856.31
A20: 1
A21: 1 | B21: 4. Бонусы | C21: 0 | D21: 0 | E21: 0 | F21: 0 | G21: 0 | H21: 0 | I21: 0 | J21: 0 | K21: 0 | L21: 0 | M21: 0 | N21: 0 | O21: 0 | P21: 0 | Q21: 0
A22: 71900700 | B22: ДоходОтБонусов | C22: 0 | D22: 0 | E22: 0 | F22: 0 | G22: 0 | H22: 0 | I22: 0 | J22: 0 | K22: 0 | L22: 0 | M22: 0 | N22: 0 | O22: 0 | P22: 0 | Q22: 0
A23: 1
A24: 1 | B24: 5. Прочее - Доходы | C24: 13424511 | D24: 0.0010210508 | E24: 2077536.5 | F24: 2423558.5 | G24: 3095621.3 | H24: 3170559.6 | I24: 2657235.3 | J24: 2074000.5 | K24: 1294218.6 | L24: 1904695 | M24: 749230.8 | N24: 2152332.6 | O24: 2114249.5 | P24: 1302730 | Q24: 3105094.5
A25: 70300000 | B25: ДоходРеалРабУсл | C25: 0 | D25: 0 | E25: 0 | F25: 0 | G25: 0 | H25: 0 | I25: 0 | J25: 0 | K25: 0 | L25: 0 | M25: 0 | N25: 0 | O25: 0 | P25: 0 | Q25: 0
A26: 70300200 | B26: ДохРазмРеклСобствНН | C26: 0 | D26: 0 | E26: 0 | F26: 0 | G26: 0 | H26: 0 | I26: 0 | J26: 0 | K26: 0 | L26: 0 | M26: 0 | N26: 0 | O26: 0 | P26: 0 | Q26: 0
A27: 70300700 | B27: ДохРеалУслЛогист | C27: 0 | D27: 0 | E27: 0 | F27: 0 | G27: 0 | H27: 0 | I27: 0 | J27: 0 | K27: 0 | L27: 0 | M27: 0 | N27: 0 | O27: 0 | P27: 0 | Q27: 0
A28: 70300800 | B28: ДоходДогКомиссии | C28: 0 | D28: 0 | E28: 0 | F28: 0 | G28: 0 | H28: 0 | I28: 0 | J28: 0 | K28: 0 | L28: 0 | M28: 0 | N28: 0 | O28: 0 | P28: 0 | Q28: 0
A29: 70300900 | B29: ДоходУслугКонечнПотр | C29: 0 | D29: 0 | E29: 0 | F29: 0 | G29: 0 | H29: 0 | I29: 0 | J29: 0 | K29: 0 | L29: 0 | M29: 0 | N29: 0 | O29: 0 | P29: 0 | Q29: 0
A30: 71200000 | B30: ДохРеалПрочОбАкт | C30: 0 | D30: 0 | E30: 0 | F30: 0 | G30: 0 | H30: 0 | I30: 0 | J30: 0 | K30: 0 | L30: 0 | M30: 0 | N30: 0 | O30: 0 | P30: 0 | Q30: 0
A31: 71200100 | B31: ДохРеалМакулатуры | C31: 0 | D31: 0 | E31: 0 | F31: 0 | G31: 0 | H31: 0 | I31: 0 | J31: 0 | K31: 0 | L31: 0 | M31: 0 | N31: 0 | O31: 0 | P31: 0 | Q31: 0
A32: 71300000 | B32: ДохАренОборудован | C32: 0 | D32: 0 | E32: 0 | F32: 0 | G32: 0 | H32: 0 | I32: 0 | J32: 0 | K32: 0 | L32: 0 | M32: 0 | N32: 0 | O32: 0 | P32: 0 | Q32: 0
A33: 71300200 | B33: ДохАренТранспорта | C33: 0 | D33: 0 | E33: 0 | F33: 0 | G33: 0 | H33: 0 | I33: 0 | J33: 0 | K33: 0 | L33: 0 | M33: 0 | N33: 0 | O33: 0 | P33: 0 | Q33: 0
A34: 71500000 | B34: ПолучШтрафПени | C34: 0 | D34: 0 | E34: 0 | F34: 0 | G34: 0 | H34: 0 | I34: 0 | J34: 0 | K34: 0 | L34: 0 | M34: 0 | N34: 0 | O34: 0 | P34: 0 | Q34: 0
A35: 71500100 | B35: ОтримШтрафиПеніКомер
A36: 71700000 | B36: ДохСписКредЗадолж | C36: 0 | D36: 0 | E36: 0 | F36: 0 | G36: 0 | H36: 0 | I36: 0 | J36: 0 | K36: 0 | L36: 0 | M36: 0 | N36: 0 | O36: 0 | P36: 0 | Q36: 0
A37: 71800000 | B37: ДохБесплПолОборАкт | C37: 0 | D37: 0 | E37: 0 | F37: 0 | G37: 0 | H37: 0 | I37: 0 | J37: 0 | K37: 0 | L37: 0 | M37: 0 | N37: 0 | O37: 0 | P37: 0 | Q37: 0
A38: 71800400 | B38: ДохБесплПолАктив.РЦ | C38: 0 | D38: 0 | E38: 0 | F38: 0 | G38: 0 | H38: 0 | I38: 0 | J38: 0 | K38: 0 | L38: 0 | M38: 0 | N38: 0 | O38: 0 | P38: 0 | Q38: 0
A39: 71900000 | B39: ПрочДоходОперДеят | C39: 13424511 | D39: 0.0010210508 | E39: 2077536.5 | F39: 2423558.5 | G39: 3095621.3 | H39: 3170559.6 | I39: 2657235.3 | J39: 2074000.5 | K39: 1294218.6 | L39: 1904695 | M39: 749230.8 | N39: 2152332.6 | O39: 2114249.5 | P39: 1302730 | Q39: 3105094.5
A40: 71900100 | B40: ПрочДоход% банка | C40: 0 | D40: 0 | E40: 0 | F40: 0 | G40: 0 | H40: 0 | I40: 0 | J40: 0 | K40: 0 | L40: 0 | M40: 0 | N40: 0 | O40: 0 | P40: 0 | Q40: 0
...

Sheet ФАКТ 2025
E1: 45658 | F1: 45689 | G1: 45717 | H1: 45748 | I1: 45778 | J1: 45809 | K1: 45839 | L1: 45870 | M1: 45901 | N1: 45931 | O1: 45962 | P1: 45992
A2: КЛО_МРЦ | B2: Киев,Фора МРЦ Оросительная,5 | C2: ИТОГО 2025 | D2: % К ОБОРОТУ | E2: 45658 | F2: 45689 | G2: 45717 | H2: 45748 | I2: 45778 | J2: 45809 | K2: 45839 | L2: 45870 | M2: 45901 | N2: 45931 | O2: 45962 | P2: 45992
A3: Доходы
A4: Код | B4: 1. Выручка | C4: 56312.5 | D4: 1.6139912e-06 | E4: 56312.5 | F4: 43272.3 | G4: 43860.04 | H4: 42136.95 | I4: 133672.61 | J4: 0 | K4: 0 | L4: 0 | M4: 0 | N4: 0 | O4: 0 | P4: 0
A5: 70200000 | B5: ДоходРеалТовара | C5: 56312.5 | D5: 1.6139912e-06 | E5: 56312.5 | F5: 43272.3 | G5: 43860.04 | H5: 42136.95 | I5: 133672.61 | J5: 0 | K5: 0 | L5: 0 | M5: 0 | N5: 0 | O5: 0 | P5: 0
A6: 70200001 | B6: ДоходРеалПрогрЛояльн | C6: 0 | D6: 0 | E6: 0 | F6: 0 | G6: 0 | H6: 0 | I6: 0 | J6: 0 | K6: 0 | L6: 0 | M6: 0 | N6: 0 | O6: 0 | P6: 0
A7: 70200002 | B7: ДоходРеалТВаучера | C7: 0 | D7: 0 | E7: 0 | F7: 0 | G7: 0 | H7: 0 | I7: 0 | J7: 0 | K7: 0 | L7: 0 | M7: 0 | N7: 0 | O7: 0 | P7: 0
A8: 70200003 | B8: ДоходРеалТовКомиссия | C8: 0 | D8: 0 | E8: 0 | F8: 0 | G8: 0 | H8: 0 | I8: 0 | J8: 0 | K8: 0 | L8: 0 | M8: 0 | N8: 0 | O8: 0 | P8: 0
A9: 70200004 | B9: ДоходРеалАгентсДог | C9: 0 | D9: 0 | E9: 0 | F9: 0 | G9: 0 | H9: 0 | I9: 0 | J9: 0 | K9: 0 | L9: 0 | M9: 0 | N9: 0 | O9: 0 | P9: 0
A10: 70200009 | B10: Недополучен.выручка | C10: 0 | D10: 0 | E10: 0 | F10: 0 | G10: 0 | H10: 0 | I10: 0 | J10: 0 | K10: 0 | L10: 0 | M10: 0 | N10: 0 | O10: 0 | P10: 0
A11: 70200200 | B11: ДоходРеалТовЭкспорт | C11: 0 | D11: 0 | E11: 0 | F11: 0 | G11: 0 | H11: 0 | I11: 0 | J11: 0 | K11: 0 | L11: 0 | M11: 0 | N11: 0 | O11: 0 | P11: 0
A12: 70400000 | B12: ВычетыДоходТовар | C12: 0 | D12: 0 | E12: 0 | F12: 0 | G12: 0 | H12: 0 | I12: 0 | J12: 0 | K12: 0 | L12: 0 | M12: 0 | N12: 0 | O12: 0 | P12: 0
A13: 70430000 | B13: ВычетыДоходАгентсДог | C13: 0 | D13: 0 | E13: 0 | F13: 0 | G13: 0 | H13: 0 | I13: 0 | J13: 0 | K13: 0 | L13: 0 | M13: 0 | N13: 0 | O13: 0 | P13: 0
A14: 1
A15: 1 | B15: 2. Себестоимость | C15: -63168.81 | D15: -1.8105022e-06 | E15: -63168.81 | F15: -27005.75 | G15: -51602.41 | H15: -62649.3 | I15: -108767.59 | J15: 0 | K15: 0 | L15: 0 | M15: 0 | N15: 0 | O15: 0 | P15: 0
A16: 90200000 | B16: СебестРеализТоваров | C16: 0 | D16: 0 | E16: 0 | F16: -27.4 | G16: 0 | H16: 0 | I16: -19296.99 | J16: 0 | K16: 0 | L16: 0 | M16: 0 | N16: 0 | O16: 0 | P16: 0
A17: 90200001 | B17: СебестРеалТоваровПро | C17: -63168.81 | D17: -1.8105022e-06 | E17: -63168.81 | F17: -26978.35 | G17: -51602.41 | H17: -62649.3 | I17: -89470.6 | J17: 0 | K17: 0 | L17: 0 | M17: 0 | N17: 0 | O17: 0 | P17: 0
A18: 1
A19: 1 | B19: 3. Валовая маржа | C19: -6856.31 | D19: -1.9651097e-07 | E19: -6856.31 | F19: 16266.55 | G19: -7742.37 | H19: -20512.35 | I19: 24905.02 | J19: 0 | K19: 0 | L19: 0 | M19: 0 | N19: 0 | O19: 0 | P19: 0
A20: 1
A21: 1 | B21: 4. Бонусы | C21: 0 | D21: 0 | E21: 0 | F21: 0 | G21: 0 | H21: 0 | I21: 0 | J21: 0 | K21: 0 | L21: 0 | M21: 0 | N21: 0 | O21: 0 | P21: 0
A22: 71900700 | B22: ДоходОтБонусов | C22: 0 | D22: 0 | E22: 0 | F22: 0 | G22: 0 | H22: 0 | I22: 0 | J22: 0 | K22: 0 | L22: 0 | M22: 0 | N22: 0 | O22: 0 | P22: 0
A23: 1
A24: 1 | B24: 5. Прочее - Доходы | C24: 3105094.5 | D24: 8.8996142e-05 | E24: 3105094.5 | F24: 1605268.9 | G24: 1724627.5 | H24: 1546722.8 | I24: 2920354.5 | J24: 0 | K24: 0 | L24: 0 | M24: 0 | N24: 0 | O24: 0 | P24: 0
A25: 70300000 | B25: ДоходРеалРабУсл | C25: 0 | D25: 0 | E25: 0 | F25: 0 | G25: 0 | H25: 0 | I25: 0 | J25: 0 | K25: 0 | L25: 0 | M25: 0 | N25: 0 | O25: 0 | P25: 0
A26: 70300200 | B26: ДохРазмРеклСобствНН | C26: 0 | D26: 0 | E26: 0 | F26: 0 | G26: 0 | H26: 0 | I26: 0 | J26: 0 | K26: 0 | L26: 0 | M26: 0 | N26: 0 | O26: 0 | P26: 0
A27: 70300700 | B27: ДохРеалУслЛогист | C27: 0 | D27: 0 | E27: 0 | F27: 0 | G27: 0 | H27: 0 | I27: 0 | J27: 0 | K27: 0 | L27: 0 | M27: 0 | N27: 0 | O27: 0 | P27: 0
A28: 70300800 | B28: ДоходДогКомиссии | C28: 0 | D28: 0 | E28: 0 | F28: 0 | G28: 0 | H28: 0 | I28: 0 | J28: 0 | K28: 0 | L28: 0 | M28: 0 | N28: 0 | O28: 0 | P28: 0
A29: 70300900 | B29: ДоходУслугКонечнПотр | C29: 0 | D29: 0 | E29: 0 | F29: 0 | G29: 0 | H29: 0 | I29: 0 | J29: 0 | K29: 0 | L29: 0 | M29: 0 | N29: 0 | O29: 0 | P29: 0
A30: 71200000 | B30: ДохРеалПрочОбАкт | C30: 0 | D30: 0 | E30: 0 | F30: 0 | G30: 0 | H30: 0 | I30: 0 | J30: 0 | K30: 0 | L30: 0 | M30: 0 | N30: 0 | O30: 0 | P30: 0
A31: 71200100 | B31: ДохРеалМакулатуры | C31: 0 | D31: 0 | E31: 0 | F31: 0 | G31: 9912 | H31: 13862.8 | I31: 12950 | J31: 0 | K31: 0 | L31: 0 | M31: 0 | N31: 0 | O31: 0 | P31: 0
A32: 71300000 | B32: ДохАренОборудован | C32: 0 | D32: 0 | E32: 0 | F32: 0 | G32: 0 | H32: 0 | I32: 0 | J32: 0 | K32: 0 | L32: 0 | M32: 0 | N32: 0 | O32: 0 | P32: 0
A33: 71300200 | B33: ДохАренТранспорта | C33: 0 | D33: 0 | E33: 0 | F33: 0 | G33: 0 | H33: 0 | I33: 0 | J33: 0 | K33: 0 | L33: 0 | M33: 0 | N33: 0 | O33: 0 | P33: 0
A34: 71500000 | B34: ПолучШтрафПени | C34: 0 | D34: 0 | E34: 0 | F34: 0 | G34: 0 | H34: 0 | I34: 0 | J34: 0 | K34: 0 | L34: 0 | M34: 0 | N34: 0 | O34: 0 | P34: 0
A35: 71500100 | B35: ОтримШтрафиПеніКомер
A36: 71700000 | B36: ДохСписКредЗадолж | C36: 0 | D36: 0 | E36: 0 | F36: 0 | G36: 0 | H36: 0 | I36: 0 | J36: 0 | K36: 0 | L36: 0 | M36: 0 | N36: 0 | O36: 0 | P36: 0
A37: 71800000 | B37: ДохБесплПолОборАкт | C37: 0 | D37: 0 | E37: 0 | F37: 0 | G37: 0 | H37: 0 | I37: 0 | J37: 0 | K37: 0 | L37: 0 | M37: 0 | N37: 0 | O37: 0 | P37: 0
A38: 71800400 | B38: ДохБесплПолАктив.РЦ | C38: 0 | D38: 0 | E38: 0 | F38: 0 | G38: 0 | H38: 0 | I38: 0 | J38: 0 | K38: 0 | L38: 0 | M38: 0 | N38: 0 | O38: 0 | P38: 0
A39: 71900000 | B39: ПрочДоходОперДеят | C39: 3105094.5 | D39: 8.8996142e-05 | E39: 3105094.5 | F39: 1605268.9 | G39: 1714715.5 | H39: 1532860 | I39: 2907404.5 | J39: 0 | K39: 0 | L39: 0 | M39: 0 | N39: 0 | O39: 0 | P39: 0
A40: 71900100 | B40: ПрочДоход% банка | C40: 0 | D40: 0 | E40: 0 | F40: 0 | G40: 0 | H40: 0 | I40: 0 | J40: 0 | K40: 0 | L40: 0 | M40: 0 | N40: 0 | O40: 0 | P40: 0
...

Sheet квітень
A1: КЛО_МРЦ | B1: Киев,Фора МРЦ Оросительная,5 | C1: ИТОГО 2024 | D1: % К ОБОРОТУ | E1: 45658 | F1: 45689 | G1: 45717 | H1: 45383 | I1: 45778 | J1: 45809 | K1: 45839 | L1: 45870 | M1: 45901 | N1: 45931 | O1: 45962 | P1: 45992
A2: Доходы
A3: Код | B3: 1. Выручка | C3: 185581.79 | D3: 4.1113201e-06 | E3: 56312.5 | F3: 43272.3 | G3: 43860.04 | H3: 42136.95 | I3: 0 | J3: 0 | K3: 0 | L3: 0 | M3: 0 | N3: 0 | O3: 0 | P3: 0
A4: 70200000 | B4: ДоходРеалТовара | C4: 185581.79 | D4: 4.1113201e-06 | E4: 56312.5 | F4: 43272.3 | G4: 43860.04 | H4: 42136.95 | I4: 0 | J4: 0 | K4: 0 | L4: 0 | M4: 0 | N4: 0 | O4: 0 | P4: 0
A5: 70200001 | B5: ДоходРеалПрогрЛояльн | C5: 0 | D5: 0 | E5: 0 | F5: 0 | G5: 0 | H5: 0 | I5: 0 | J5: 0 | K5: 0 | L5: 0 | M5: 0 | N5: 0 | O5: 0 | P5: 0
A6: 70200002 | B6: ДоходРеалТВаучера | C6: 0 | D6: 0 | E6: 0 | F6: 0 | G6: 0 | H6: 0 | I6: 0 | J6: 0 | K6: 0 | L6: 0 | M6: 0 | N6: 0 | O6: 0 | P6: 0
A7: 70200003 | B7: ДоходРеалТовКомиссия | C7: 0 | D7: 0 | E7: 0 | F7: 0 | G7: 0 | H7: 0 | I7: 0 | J7: 0 | K7: 0 | L7: 0 | M7: 0 | N7: 0 | O7: 0 | P7: 0
A8: 70200004 | B8: ДоходРеалАгентсДог | C8: 0 | D8: 0 | E8: 0 | F8: 0 | G8: 0 | H8: 0 | I8: 0 | J8: 0 | K8: 0 | L8: 0 | M8: 0 | N8: 0 | O8: 0 | P8: 0
A9: 70200009 | B9: Недополучен.выручка | C9: 0 | D9: 0 | E9: 0 | F9: 0 | G9: 0 | H9: 0 | I9: 0 | J9: 0 | K9: 0 | L9: 0 | M9: 0 | N9: 0 | O9: 0 | P9: 0
A10: 70200200 | B10: ДоходРеалТовЭкспорт | C10: 0 | D10: 0 | E10: 0 | F10: 0 | G10: 0 | H10: 0 | I10: 0 | J10: 0 | K10: 0 | L10: 0 | M10: 0 | N10: 0 | O10: 0 | P10: 0
A11: 70400000 | B11: ВычетыДоходТовар | C11: 0 | D11: 0 | E11: 0 | F11: 0 | G11: 0 | H11: 0 | I11: 0 | J11: 0 | K11: 0 | L11: 0 | M11: 0 | N11: 0 | O11: 0 | P11: 0
A12: 70430000 | B12: ВычетыДоходАгентсДог | C12: 0 | D12: 0 | E12: 0 | F12: 0 | G12: 0 | H12: 0 | I12: 0 | J12: 0 | K12: 0 | L12: 0 | M12: 0 | N12: 0 | O12: 0 | P12: 0
A13: 1
A14: 1 | B14: 2. Себестоимость | C14: -204426.27 | D14: -4.0635167e-06 | E14: -63168.81 | F14: -27005.75 | G14: -51602.41 | H14: -62649.3 | I14: 0 | J14: 0 | K14: 0 | L14: 0 | M14: 0 | N14: 0 | O14: 0 | P14: 0
A15: 90200000 | B15: СебестРеализТоваров | C15: -27.4 | D15: -7.8532048e-10 | E15: 0 | F15: -27.4 | G15: 0 | H15: 0 | I15: 0 | J15: 0 | K15: 0 | L15: 0 | M15: 0 | N15: 0 | O15: 0 | P15: 0
A16: 90200001 | B16: СебестРеалТоваровПро | C16: -204398.87 | D16: -4.0627314e-06 | E16: -63168.81 | F16: -26978.35 | G16: -51602.41 | H16: -62649.3 | I16: 0 | J16: 0 | K16: 0 | L16: 0 | M16: 0 | N16: 0 | O16: 0 | P16: 0
A17: 1
A18: 1 | B18: 3. Валовая маржа | C18: -18844.48 | D18: 4.7803375e-08 | E18: -6856.31 | F18: 16266.55 | G18: -7742.37 | H18: -20512.35 | I18: 0 | J18: 0 | K18: 0 | L18: 0 | M18: 0 | N18: 0 | O18: 0 | P18: 0
A19: 1
A20: 1 | B20: 4. Бонусы | C20: 0 | D20: 0 | E20: 0 | F20: 0 | G20: 0 | H20: 0 | I20: 0 | J20: 0 | K20: 0 | L20: 0 | M20: 0 | N20: 0 | O20: 0 | P20: 0
A21: 71900700 | B21: ДоходОтБонусов | C21: 0 | D21: 0 | E21: 0 | F21: 0 | G21: 0 | H21: 0 | I21: 0 | J21: 0 | K21: 0 | L21: 0 | M21: 0 | N21: 0 | O21: 0 | P21: 0
A22: 1
A23: 1 | B23: 5. Прочее - Доходы | C23: 7981713.7 | D23: 0 | E23: 3105094.5 | F23: 1605268.9 | G23: 1724627.5 | H23: 1546722.8 | I23: 0 | J23: 0 | K23: 0 | L23: 0 | M23: 0 | N23: 0 | O23: 0 | P23: 0
A24: 70300000 | B24: ДоходРеалРабУсл | C24: 0 | D24: 0 | E24: 0 | F24: 0 | G24: 0 | H24: 0 | I24: 0 | J24: 0 | K24: 0 | L24: 0 | M24: 0 | N24: 0 | O24: 0 | P24: 0
A25: 70300200 | B25: ДохРазмРеклСобствНН | C25: 0 | D25: 0 | E25: 0 | F25: 0 | G25: 0 | H25: 0 | I25: 0 | J25: 0 | K25: 0 | L25: 0 | M25: 0 | N25: 0 | O25: 0 | P25: 0
A26: 70300700 | B26: ДохРеалУслЛогист | C26: 0 | D26: 0 | E26: 0 | F26: 0 | G26: 0 | H26: 0 | I26: 0 | J26: 0 | K26: 0 | L26: 0 | M26: 0 | N26: 0 | O26: 0 | P26: 0
A27: 70300800 | B27: ДоходДогКомиссии | C27: 0 | D27: 0 | E27: 0 | F27: 0 | G27: 0 | H27: 0 | I27: 0 | J27: 0 | K27: 0 | L27: 0 | M27: 0 | N27: 0 | O27: 0 | P27: 0
A28: 70300900 | B28: ДоходУслугКонечнПотр | C28: 0 | D28: 0 | E28: 0 | F28: 0 | G28: 0 | H28: 0 | I28: 0 | J28: 0 | K28: 0 | L28: 0 | M28: 0 | N28: 0 | O28: 0 | P28: 0
A29: 71200000 | B29: ДохРеалПрочОбАкт | C29: 0 | D29: 0 | E29: 0 | F29: 0 | G29: 0 | H29: 0 | I29: 0 | J29: 0 | K29: 0 | L29: 0 | M29: 0 | N29: 0 | O29: 0 | P29: 0
A30: 71200100 | B30: ДохРеалМакулатуры | C30: 23774.8 | D30: 2.8409112e-07 | E30: 0 | F30: 0 | G30: 9912 | H30: 13862.8 | I30: 0 | J30: 0 | K30: 0 | L30: 0 | M30: 0 | N30: 0 | O30: 0 | P30: 0
A31: 71300000 | B31: ДохАренОборудован | C31: 0 | D31: 0 | E31: 0 | F31: 0 | G31: 0 | H31: 0 | I31: 0 | J31: 0 | K31: 0 | L31: 0 | M31: 0 | N31: 0 | O31: 0 | P31: 0
A32: 71300200 | B32: ДохАренТранспорта | C32: 0 | D32: 0 | E32: 0 | F32: 0 | G32: 0 | H32: 0 | I32: 0 | J32: 0 | K32: 0 | L32: 0 | M32: 0 | N32: 0 | O32: 0 | P32: 0
A33: 71500000 | B33: ПолучШтрафПени | C33: 0 | D33: 0 | E33: 0 | F33: 0 | G33: 0 | H33: 0 | I33: 0 | J33: 0 | K33: 0 | L33: 0 | M33: 0 | N33: 0 | O33: 0 | P33: 0
A34: 71500100 | B34: ОтримШтрафиПеніКомер | D34: 0
A35: 71700000 | B35: ДохСписКредЗадолж | C35: 0 | D35: 0 | E35: 0 | F35: 0 | G35: 0 | H35: 0 | I35: 0 | J35: 0 | K35: 0 | L35: 0 | M35: 0 | N35: 0 | O35: 0 | P35: 0
A36: 71800000 | B36: ДохБесплПолОборАкт | C36: 0 | D36: 0 | E36: 0 | F36: 0 | G36: 0 | H36: 0 | I36: 0 | J36: 0 | K36: 0 | L36: 0 | M36: 0 | N36: 0 | O36: 0 | P36: 0
A37: 71800400 | B37: ДохБесплПолАктив.РЦ | C37: 0 | D37: 0 | E37: 0 | F37: 0 | G37: 0 | H37: 0 | I37: 0 | J37: 0 | K37: 0 | L37: 0 | M37: 0 | N37: 0 | O37: 0 | P37: 0
A38: 71900000 | B38: ПрочДоходОперДеят | C38: 7957938.9 | D38: 0 | E38: 3105094.5 | F38: 1605268.9 | G38: 1714715.5 | H38: 1532860 | I38: 0 | J38: 0 | K38: 0 | L38: 0 | M38: 0 | N38: 0 | O38: 0 | P38: 0
A39: 71900100 | B39: ПрочДоход% банка | C39: 0 | D39: 0 | E39: 0 | F39: 0 | G39: 0 | H39: 0 | I39: 0 | J39: 0 | K39: 0 | L39: 0 | M39: 0 | N39: 0 | O39: 0 | P39: 0
A40: 71900500 | B40: ПрДоходИзлишки кассы | C40: 0 | D40: 0 | E40: 0 | F40: 0 | G40: 0 | H40: 0 | I40: 0 | J40: 0 | K40: 0 | L40: 0 | M40: 0 | N40: 0 | O40: 0 | P40: 0
...

Sheet червень
I1: 45658 | J1: 45689 | K1: 45717 | L1: 45748 | M1: 45778 | N1: 45809 | O1: 45839 | P1: 45870 | Q1: 45901 | R1: 45931 | S1: 45962 | T1: 45992
A2: 2 | E2: КЛО_МРЦ | F2: Киев,Фора МРЦ Оросительная,5 | G2: ИТОГО 2024 | H2: % К ОБОРОТУ | I2: 45658 | J2: 45689 | K2: 45717 | L2: 45383 | M2: 45778 | N2: 45809 | O2: 45839 | P2: 45870 | Q2: 45901 | R2: 45931 | S2: 45962 | T2: 45992
A3: 3 | B3: КЛО_МРЦДоходы | E3: Доходы
A4: 4 | C4: mapping Бюджет | D4: Разбивка по Офисам | E4: Код | F4: 1. Выручка | G4: 348023.38 | H4: 4.1113201e-06 | I4: 56312.5 | J4: 43272.3 | K4: 43860.04 | L4: 42136.95 | M4: 133672.61 | N4: 28768.98 | O4: 0 | P4: 0 | Q4: 0 | R4: 0 | S4: 0 | T4: 0
A5: 5 | B5: КЛО_МРЦ70200000 | C5: Валовая прибыль (без бонусов) | D5: ВСЕ | E5: 70200000 | F5: ДоходРеалТовара | G5: 348023.38 | H5: 4.1113201e-06 | I5: 56312.5 | J5: 43272.3 | K5: 43860.04 | L5: 42136.95 | M5: 133672.61 | N5: 28768.98 | O5: 0 | P5: 0 | Q5: 0 | R5: 0 | S5: 0 | T5: 0
A6: 6 | B6: КЛО_МРЦ70200001 | C6: Валовая прибыль (без бонусов) | D6: МАРКЕТИНГ | E6: 70200001 | F6: ДоходРеалПрогрЛояльн | G6: 0 | H6: 0 | I6: 0 | J6: 0 | K6: 0 | L6: 0 | M6: 0 | N6: 0 | O6: 0 | P6: 0 | Q6: 0 | R6: 0 | S6: 0 | T6: 0
A7: 7 | B7: КЛО_МРЦ70200002 | C7: Валовая прибыль (без бонусов) | D7: МАРКЕТИНГ | E7: 70200002 | F7: ДоходРеалТВаучера | G7: 0 | H7: 0 | I7: 0 | J7: 0 | K7: 0 | L7: 0 | M7: 0 | N7: 0 | O7: 0 | P7: 0 | Q7: 0 | R7: 0 | S7: 0 | T7: 0
A8: 8 | B8: КЛО_МРЦ70200003 | C8: Валовая прибыль (без бонусов) | E8: 70200003 | F8: ДоходРеалТовКомиссия | G8: 0 | H8: 0 | I8: 0 | J8: 0 | K8: 0 | L8: 0 | M8: 0 | N8: 0 | O8: 0 | P8: 0 | Q8: 0 | R8: 0 | S8: 0 | T8: 0
A9: 9 | B9: КЛО_МРЦ70200004 | C9: Валовая прибыль (без бонусов) | D9: Дирекция | E9: 70200004 | F9: ДоходРеалАгентсДог | G9: 0 | H9: 0 | I9: 0 | J9: 0 | K9: 0 | L9: 0 | M9: 0 | N9: 0 | O9: 0 | P9: 0 | Q9: 0 | R9: 0 | S9: 0 | T9: 0
A10: 10 | B10: КЛО_МРЦ70200009 | C10: Валовая прибыль (без бонусов) | D10: Дирекция | E10: 70200009 | F10: Недополучен.выручка | G10: 0 | H10: 0 | I10: 0 | J10: 0 | K10: 0 | L10: 0 | M10: 0 | N10: 0 | O10: 0 | P10: 0 | Q10: 0 | R10: 0 | S10: 0 | T10: 0
A11: 11 | B11: КЛО_МРЦ70200200 | C11: Валовая прибыль (без бонусов) | D11: Дирекция | E11: 70200200 | F11: ДоходРеалТовЭкспорт | G11: 0 | H11: 0 | I11: 0 | J11: 0 | K11: 0 | L11: 0 | M11: 0 | N11: 0 | O11: 0 | P11: 0 | Q11: 0 | R11: 0 | S11: 0 | T11: 0
A12: 12 | B12: КЛО_МРЦ70400000 | C12: Валовая прибыль (без бонусов) | D12: Дирекция | E12: 70400000 | F12: ВычетыДоходТовар | G12: 0 | H12: 0 | I12: 0 | J12: 0 | K12: 0 | L12: 0 | M12: 0 | N12: 0 | O12: 0 | P12: 0 | Q12: 0 | R12: 0 | S12: 0 | T12: 0
A13: 13 | B13: КЛО_МРЦ70430000 | C13: Валовая прибыль (без бонусов) | D13: Дирекция | E13: 70430000 | F13: ВычетыДоходАгентсДог | G13: 0 | H13: 0 | I13: 0 | J13: 0 | K13: 0 | L13: 0 | M13: 0 | N13: 0 | O13: 0 | P13: 0 | Q13: 0 | R13: 0 | S13: 0 | T13: 0
A14: 14 | E14: 1
A15: 15 | E15: 1 | F15: 2. Себестоимость | G15: -355115.64 | H15: -4.0635167e-06 | I15: -63168.81 | J15: -27005.75 | K15: -51602.41 | L15: -62649.3 | M15: -108767.59 | N15: -41921.78 | O15: 0 | P15: 0 | Q15: 0 | R15: 0 | S15: 0 | T15: 0
A16: 16 | B16: КЛО_МРЦ90200000 | C16: Валовая прибыль (без бонусов) | D16: КЛО | E16: 90200000 | F16: СебестРеализТоваров | G16: -19324.39 | H16: -7.8532048e-10 | I16: 0 | J16: -27.4 | K16: 0 | L16: 0 | M16: -19296.99 | N16: 0 | O16: 0 | P16: 0 | Q16: 0 | R16: 0 | S16: 0 | T16: 0
A17: 17 | B17: КЛО_МРЦ90200001 | C17: Валовая прибыль (без бонусов) | D17: КЛО | E17: 90200001 | F17: СебестРеалТоваровПро | G17: -335791.25 | H17: -4.0627314e-06 | I17: -63168.81 | J17: -26978.35 | K17: -51602.41 | L17: -62649.3 | M17: -89470.6 | N17: -41921.78 | O17: 0 | P17: 0 | Q17: 0 | R17: 0 | S17: 0 | T17: 0
A18: 18 | E18: 1
A19: 19 | E19: 1 | F19: 3. Валовая маржа | G19: -7092.26 | H19: 4.7803375e-08 | I19: -6856.31 | J19: 16266.55 | K19: -7742.37 | L19: -20512.35 | M19: 24905.02 | N19: -13152.8 | O19: 0 | P19: 0 | Q19: 0 | R19: 0 | S19: 0 | T19: 0
A20: 20 | E20: 1
A21: 21 | E21: 1 | F21: 4. Бонусы | G21: 0 | H21: 0 | I21: 0 | J21: 0 | K21: 0 | L21: 0 | M21: 0 | N21: 0 | O21: 0 | P21: 0 | Q21: 0 | R21: 0 | S21: 0 | T21: 0
A22: 22 | B22: КЛО_МРЦ71900700 | C22: Бонусы | D22: КЛО | E22: 71900700 | F22: ДоходОтБонусов | G22: 0 | H22: 0 | I22: 0 | J22: 0 | K22: 0 | L22: 0 | M22: 0 | N22: 0 | O22: 0 | P22: 0 | Q22: 0 | R22: 0 | S22: 0 | T22: 0
A23: 23 | E23: 1
A24: 24 | E24: 1 | F24: 5. Прочее - Доходы | G24: 13044252 | H24: 0 | I24: 3105094.5 | J24: 1605268.9 | K24: 1724627.5 | L24: 1546722.8 | M24: 2920354.5 | N24: 2142183.6 | O24: 0 | P24: 0 | Q24: 0 | R24: 0 | S24: 0 | T24: 0
A25: 25 | B25: КЛО_МРЦ70300000 | C25: Прочие доходы | D25: МАРКЕТИНГ | E25: 70300000 | F25: ДоходРеалРабУсл | G25: 0 | H25: 0 | I25: 0 | J25: 0 | K25: 0 | L25: 0 | M25: 0 | N25: 0 | O25: 0 | P25: 0 | Q25: 0 | R25: 0 | S25: 0 | T25: 0
A26: 26 | B26: КЛО_МРЦ70300200 | C26: Прочие доходы | D26: МАРКЕТИНГ | E26: 70300200 | F26: ДохРазмРеклСобствНН | G26: 0 | H26: 0 | I26: 0 | J26: 0 | K26: 0 | L26: 0 | M26: 0 | N26: 0 | O26: 0 | P26: 0 | Q26: 0 | R26: 0 | S26: 0 | T26: 0
A27: 27 | B27: КЛО_МРЦ70300700 | C27: Прочие доходы | D27: КЛО | E27: 70300700 | F27: ДохРеалУслЛогист | G27: 0 | H27: 0 | I27: 0 | J27: 0 | K27: 0 | L27: 0 | M27: 0 | N27: 0 | O27: 0 | P27: 0 | Q27: 0 | R27: 0 | S27: 0 | T27: 0
A28: 28 | B28: КЛО_МРЦ70300800 | C28: Прочие доходы | D28: ОПЕРАЦИОННЫЙ | E28: 70300800 | F28: ДоходДогКомиссии | G28: 0 | H28: 0 | I28: 0 | J28: 0 | K28: 0 | L28: 0 | M28: 0 | N28: 0 | O28: 0 | P28: 0 | Q28: 0 | R28: 0 | S28: 0 | T28: 0
A29: 29 | B29: КЛО_МРЦ70300900 | C29: Прочие доходы | D29: ОПЕРАЦИОННЫЙ | E29: 70300900 | F29: ДоходУслугКонечнПотр | G29: 0 | H29: 0 | I29: 0 | J29: 0 | K29: 0 | L29: 0 | M29: 0 | N29: 0 | O29: 0 | P29: 0 | Q29: 0 | R29: 0 | S29: 0 | T29: 0
A30: 30 | B30: КЛО_МРЦ71200000 | C30: Прочие доходы | D30: Дирекция | E30: 71200000 | F30: ДохРеалПрочОбАкт | G30: 0 | H30: 0 | I30: 0 | J30: 0 | K30: 0 | L30: 0 | M30: 0 | N30: 0 | O30: 0 | P30: 0 | Q30: 0 | R30: 0 | S30: 0 | T30: 0
A31: 31 | B31: КЛО_МРЦ71200100 | C31: Прочие доходы | D31: ОПЕРАЦИОННЫЙ+СБ | E31: 71200100 | F31: ДохРеалМакулатуры | G31: 36724.8 | H31: 2.8409112e-07 | I31: 0 | J31: 0 | K31: 9912 | L31: 13862.8 | M31: 12950 | N31: 0 | O31: 0 | P31: 0 | Q31: 0 | R31: 0 | S31: 0 | T31: 0
A32: 32 | B32: КЛО_МРЦ71300000 | C32: Прочие доходы | E32: 71300000 | F32: ДохАренОборудован | G32: 0 | H32: 0 | I32: 0 | J32: 0 | K32: 0 | L32: 0 | M32: 0 | N32: 0 | O32: 0 | P32: 0 | Q32: 0 | R32: 0 | S32: 0 | T32: 0
A33: 33 | B33: КЛО_МРЦ71300200 | C33: Прочие доходы | E33: 71300200 | F33: ДохАренТранспорта | G33: 0 | H33: 0 | I33: 0 | J33: 0 | K33: 0 | L33: 0 | M33: 0 | N33: 0 | O33: 0 | P33: 0 | Q33: 0 | R33: 0 | S33: 0 | T33: 0
A34: 34 | B34: КЛО_МРЦ71500000 | C34: Прочие доходы | D34: КЛО | E34: 71500000 | F34: ПолучШтрафПени | G34: 0 | H34: 0 | I34: 0 | J34: 0 | K34: 0 | L34: 0 | M34: 0 | N34: 0 | O34: 0 | P34: 0 | Q34: 0 | R34: 0 | S34: 0 | T34: 0
A35: 35 | B35: КЛО_МРЦ71500100 | C35: Прочие доходы | E35: 71500100 | F35: ОтримШтрафиПеніКомер | H35: 0
A36: 36 | B36: КЛО_МРЦ71700000 | C36: Прочие доходы | E36: 71700000 | F36: ДохСписКредЗадолж | G36: 0 | H36: 0 | I36: 0 | J36: 0 | K36: 0 | L36: 0 | M36: 0 | N36: 0 | O36: 0 | P36: 0 | Q36: 0 | R36: 0 | S36: 0 | T36: 0
A37: 37 | B37: КЛО_МРЦ71800000 | C37: Прочие доходы | D37: 0 | E37: 71800000 | F37: ДохБесплПолОборАкт | G37: 0 | H37: 0 | I37: 0 | J37: 0 | K37: 0 | L37: 0 | M37: 0 | N37: 0 | O37: 0 | P37: 0 | Q37: 0 | R37: 0 | S37: 0 | T37: 0
A38: 38 | B38: КЛО_МРЦ71800400 | C38: Прочие доходы | E38: 71800400 | F38: ДохБесплПолАктив.РЦ | G38: 0 | H38: 0 | I38: 0 | J38: 0 | K38: 0 | L38: 0 | M38: 0 | N38: 0 | O38: 0 | P38: 0 | Q38: 0 | R38: 0 | S38: 0 | T38: 0
A39: 39 | B39: КЛО_МРЦ71900000 | C39: Прочие доходы | D39: ВСЕ | E39: 71900000 | F39: ПрочДоходОперДеят | G39: 13007527 | H39: 0 | I39: 3105094.5 | J39: 1605268.9 | K39: 1714715.5 | L39: 1532860 | M39: 2907404.5 | N39: 2142183.6 | O39: 0 | P39: 0 | Q39: 0 | R39: 0 | S39: 0 | T39: 0
A40: 40 | B40: КЛО_МРЦ71900100 | C40: Прочие доходы | D40: ФИНАНСОВЫЙ | E40: 71900100 | F40: ПрочДоход% банка | G40: 0 | H40: 0 | I40: 0 | J40: 0 | K40: 0 | L40: 0 | M40: 0 | N40: 0 | O40: 0 | P40: 0 | Q40: 0 | R40: 0 | S40: 0 | T40: 0
...

Sheet липень
I1: 45658 | J1: 45689 | K1: 45717 | L1: 45748 | M1: 45778 | N1: 45809 | O1: 45839 | P1: 45870 | Q1: 45901 | R1: 45931 | S1: 45962 | T1: 45992
A2: 2 | E2: КЛО_МРЦ | F2: Киев,Фора МРЦ Оросительная,5 | G2: ИТОГО 2024 | H2: % К ОБОРОТУ | I2: 45658 | J2: 45689 | K2: 45717 | L2: 45383 | M2: 45778 | N2: 45809 | O2: 45839 | P2: 45870 | Q2: 45901 | R2: 45931 | S2: 45962 | T2: 45992
A3: 3 | B3: КЛО_МРЦДоходы | E3: Доходы
A4: 4 | C4: mapping Бюджет | D4: Разбивка по Офисам | E4: Код | F4: 1. Выручка | G4: 410966 | H4: 4.1113201e-06 | I4: 56312.5 | J4: 43272.3 | K4: 43860.04 | L4: 42136.95 | M4: 133672.61 | N4: 28768.98 | O4: 62942.62 | P4: 0 | Q4: 0 | R4: 0 | S4: 0 | T4: 0
A5: 5 | B5: КЛО_МРЦ70200000 | C5: Валовая прибыль (без бонусов) | D5: ВСЕ | E5: 70200000 | F5: ДоходРеалТовара | G5: 410966 | H5: 4.1113201e-06 | I5: 56312.5 | J5: 43272.3 | K5: 43860.04 | L5: 42136.95 | M5: 133672.61 | N5: 28768.98 | O5: 62942.62 | P5: 0 | Q5: 0 | R5: 0 | S5: 0 | T5: 0
A6: 6 | B6: КЛО_МРЦ70200001 | C6: Валовая прибыль (без бонусов) | D6: МАРКЕТИНГ | E6: 70200001 | F6: ДоходРеалПрогрЛояльн | G6: 0 | H6: 0 | I6: 0 | J6: 0 | K6: 0 | L6: 0 | M6: 0 | N6: 0 | O6: 0 | P6: 0 | Q6: 0 | R6: 0 | S6: 0 | T6: 0
A7: 7 | B7: КЛО_МРЦ70200002 | C7: Валовая прибыль (без бонусов) | D7: МАРКЕТИНГ | E7: 70200002 | F7: ДоходРеалТВаучера | G7: 0 | H7: 0 | I7: 0 | J7: 0 | K7: 0 | L7: 0 | M7: 0 | N7: 0 | O7: 0 | P7: 0 | Q7: 0 | R7: 0 | S7: 0 | T7: 0
A8: 8 | B8: КЛО_МРЦ70200003 | C8: Валовая прибыль (без бонусов) | E8: 70200003 | F8: ДоходРеалТовКомиссия | G8: 0 | H8: 0 | I8: 0 | J8: 0 | K8: 0 | L8: 0 | M8: 0 | N8: 0 | O8: 0 | P8: 0 | Q8: 0 | R8: 0 | S8: 0 | T8: 0
A9: 9 | B9: КЛО_МРЦ70200004 | C9: Валовая прибыль (без бонусов) | D9: Дирекция | E9: 70200004 | F9: ДоходРеалАгентсДог | G9: 0 | H9: 0 | I9: 0 | J9: 0 | K9: 0 | L9: 0 | M9: 0 | N9: 0 | O9: 0 | P9: 0 | Q9: 0 | R9: 0 | S9: 0 | T9: 0
A10: 10 | B10: КЛО_МРЦ70200009 | C10: Валовая прибыль (без бонусов) | D10: Дирекция | E10: 70200009 | F10: Недополучен.выручка | G10: 0 | H10: 0 | I10: 0 | J10: 0 | K10: 0 | L10: 0 | M10: 0 | N10: 0 | O10: 0 | P10: 0 | Q10: 0 | R10: 0 | S10: 0 | T10: 0
A11: 11 | B11: КЛО_МРЦ70200200 | C11: Валовая прибыль (без бонусов) | D11: Дирекция | E11: 70200200 | F11: ДоходРеалТовЭкспорт | G11: 0 | H11: 0 | I11: 0 | J11: 0 | K11: 0 | L11: 0 | M11: 0 | N11: 0 | O11: 0 | P11: 0 | Q11: 0 | R11: 0 | S11: 0 | T11: 0
A12: 12 | B12: КЛО_МРЦ70400000 | C12: Валовая прибыль (без бонусов) | D12: Дирекция | E12: 70400000 | F12: ВычетыДоходТовар | G12: 0 | H12: 0 | I12: 0 | J12: 0 | K12: 0 | L12: 0 | M12: 0 | N12: 0 | O12: 0 | P12: 0 | Q12: 0 | R12: 0 | S12: 0 | T12: 0
A13: 13 | B13: КЛО_МРЦ70430000 | C13: Валовая прибыль (без бонусов) | D13: Дирекция | E13: 70430000 | F13: ВычетыДоходАгентсДог | G13: 0 | H13: 0 | I13: 0 | J13: 0 | K13: 0 | L13: 0 | M13: 0 | N13: 0 | O13: 0 | P13: 0 | Q13: 0 | R13: 0 | S13: 0 | T13: 0
A14: 14 | E14: 1
A15: 15 | E15: 1 | F15: 2. Себестоимость | G15: -443532.91 | H15: -4.0635167e-06 | I15: -63168.81 | J15: -27005.75 | K15: -51602.41 | L15: -62649.3 | M15: -108767.59 | N15: -41921.78 | O15: -88417.27 | P15: 0 | Q15: 0 | R15: 0 | S15: 0 | T15: 0
A16: 16 | B16: КЛО_МРЦ90200000 | C16: Валовая прибыль (без бонусов) | D16: КЛО | E16: 90200000 | F16: СебестРеализТоваров | G16: -19324.39 | H16: -7.8532048e-10 | I16: 0 | J16: -27.4 | K16: 0 | L16: 0 | M16: -19296.99 | N16: 0 | O16: 0 | P16: 0 | Q16: 0 | R16: 0 | S16: 0 | T16: 0
A17: 17 | B17: КЛО_МРЦ90200001 | C17: Валовая прибыль (без бонусов) | D17: КЛО | E17: 90200001 | F17: СебестРеалТоваровПро | G17: -424208.52 | H17: -4.0627314e-06 | I17: -63168.81 | J17: -26978.35 | K17: -51602.41 | L17: -62649.3 | M17: -89470.6 | N17: -41921.78 | O17: -88417.27 | P17: 0 | Q17: 0 | R17: 0 | S17: 0 | T17: 0
A18: 18 | E18: 1
A19: 19 | E19: 1 | F19: 3. Валовая маржа | G19: -32566.91 | H19: 4.7803375e-08 | I19: -6856.31 | J19: 16266.55 | K19: -7742.37 | L19: -20512.35 | M19: 24905.02 | N19: -13152.8 | O19: -25474.65 | P19: 0 | Q19: 0 | R19: 0 | S19: 0 | T19: 0
A20: 20 | E20: 1
A21: 21 | E21: 1 | F21: 4. Бонусы | G21: 0 | H21: 0 | I21: 0 | J21: 0 | K21: 0 | L21: 0 | M21: 0 | N21: 0 | O21: 0 | P21: 0 | Q21: 0 | R21: 0 | S21: 0 | T21: 0
A22: 22 | B22: КЛО_МРЦ71900700 | C22: Бонусы | D22: КЛО | E22: 71900700 | F22: ДоходОтБонусов | G22: 0 | H22: 0 | I22: 0 | J22: 0 | K22: 0 | L22: 0 | M22: 0 | N22: 0 | O22: 0 | P22: 0 | Q22: 0 | R22: 0 | S22: 0 | T22: 0
A23: 23 | E23: 1
A24: 24 | E24: 1 | F24: 5. Прочее - Доходы | G24: 14938470 | H24: 0 | I24: 3105094.5 | J24: 1605268.9 | K24: 1724627.5 | L24: 1546722.8 | M24: 2920354.5 | N24: 2142183.6 | O24: 1894218 | P24: 0 | Q24: 0 | R24: 0 | S24: 0 | T24: 0
A25: 25 | B25: КЛО_МРЦ70300000 | C25: Прочие доходы | D25: МАРКЕТИНГ | E25: 70300000 | F25: ДоходРеалРабУсл | G25: 0 | H25: 0 | I25: 0 | J25: 0 | K25: 0 | L25: 0 | M25: 0 | N25: 0 | O25: 0 | P25: 0 | Q25: 0 | R25: 0 | S25: 0 | T25: 0
A26: 26 | B26: КЛО_МРЦ70300200 | C26: Прочие доходы | D26: МАРКЕТИНГ | E26: 70300200 | F26: ДохРазмРеклСобствНН | G26: 0 | H26: 0 | I26: 0 | J26: 0 | K26: 0 | L26: 0 | M26: 0 | N26: 0 | O26: 0 | P26: 0 | Q26: 0 | R26: 0 | S26: 0 | T26: 0
A27: 27 | B27: КЛО_МРЦ70300700 | C27: Прочие доходы | D27: КЛО | E27: 70300700 | F27: ДохРеалУслЛогист | G27: 0 | H27: 0 | I27: 0 | J27: 0 | K27: 0 | L27: 0 | M27: 0 | N27: 0 | O27: 0 | P27: 0 | Q27: 0 | R27: 0 | S27: 0 | T27: 0
A28: 28 | B28: КЛО_МРЦ70300800 | C28: Прочие доходы | D28: ОПЕРАЦИОННЫЙ | E28: 70300800 | F28: ДоходДогКомиссии | G28: 0 | H28: 0 | I28: 0 | J28: 0 | K28: 0 | L28: 0 | M28: 0 | N28: 0 | O28: 0 | P28: 0 | Q28: 0 | R28: 0 | S28: 0 | T28: 0
A29: 29 | B29: КЛО_МРЦ70300900 | C29: Прочие доходы | D29: ОПЕРАЦИОННЫЙ | E29: 70300900 | F29: ДоходУслугКонечнПотр | G29: 0 | H29: 0 | I29: 0 | J29: 0 | K29: 0 | L29: 0 | M29: 0 | N29: 0 | O29: 0 | P29: 0 | Q29: 0 | R29: 0 | S29: 0 | T29: 0
A30: 30 | B30: КЛО_МРЦ71200000 | C30: Прочие доходы | D30: Дирекция | E30: 71200000 | F30: ДохРеалПрочОбАкт | G30: 0 | H30: 0 | I30: 0 | J30: 0 | K30: 0 | L30: 0 | M30: 0 | N30: 0 | O30: 0 | P30: 0 | Q30: 0 | R30: 0 | S30: 0 | T30: 0
A31: 31 | B31: КЛО_МРЦ71200100 | C31: Прочие доходы | D31: ОПЕРАЦИОННЫЙ+СБ | E31: 71200100 | F31: ДохРеалМакулатуры | G31: 45166.8 | H31: 2.8409112e-07 | I31: 0 | J31: 0 | K31: 9912 | L31: 13862.8 | M31: 12950 | N31: 0 | O31: 8442 | P31: 0 | Q31: 0 | R31: 0 | S31: 0 | T31: 0
A32: 32 | B32: КЛО_МРЦ71300000 | C32: Прочие доходы | E32: 71300000 | F32: ДохАренОборудован | G32: 0 | H32: 0 | I32: 0 | J32: 0 | K32: 0 | L32: 0 | M32: 0 | N32: 0 | O32: 0 | P32: 0 | Q32: 0 | R32: 0 | S32: 0 | T32: 0
A33: 33 | B33: КЛО_МРЦ71300200 | C33: Прочие доходы | E33: 71300200 | F33: ДохАренТранспорта | G33: 0 | H33: 0 | I33: 0 | J33: 0 | K33: 0 | L33: 0 | M33: 0 | N33: 0 | O33: 0 | P33: 0 | Q33: 0 | R33: 0 | S33: 0 | T33: 0
A34: 34 | B34: КЛО_МРЦ71500000 | C34: Прочие доходы | D34: КЛО | E34: 71500000 | F34: ПолучШтрафПени | G34: 0 | H34: 0 | I34: 0 | J34: 0 | K34: 0 | L34: 0 | M34: 0 | N34: 0 | O34: 0 | P34: 0 | Q34: 0 | R34: 0 | S34: 0 | T34: 0
A35: 35 | B35: КЛО_МРЦ71500100 | C35: Прочие доходы | E35: 71500100 | F35: ОтримШтрафиПеніКомер | H35: 0
A36: 36 | B36: КЛО_МРЦ71700000 | C36: Прочие доходы | E36: 71700000 | F36: ДохСписКредЗадолж | G36: 0 | H36: 0 | I36: 0 | J36: 0 | K36: 0 | L36: 0 | M36: 0 | N36: 0 | O36: 0 | P36: 0 | Q36: 0 | R36: 0 | S36: 0 | T36: 0
A37: 37 | B37: КЛО_МРЦ71800000 | C37: Прочие доходы | D37: 0 | E37: 71800000 | F37: ДохБесплПолОборАкт | G37: 0 | H37: 0 | I37: 0 | J37: 0 | K37: 0 | L37: 0 | M37: 0 | N37: 0 | O37: 0 | P37: 0 | Q37: 0 | R37: 0 | S37: 0 | T37: 0
A38: 38 | B38: КЛО_МРЦ71800400 | C38: Прочие доходы | E38: 71800400 | F38: ДохБесплПолАктив.РЦ | G38: 0 | H38: 0 | I38: 0 | J38: 0 | K38: 0 | L38: 0 | M38: 0 | N38: 0 | O38: 0 | P38: 0 | Q38: 0 | R38: 0 | S38: 0 | T38: 0
A39: 39 | B39: КЛО_МРЦ71900000 | C39: Прочие доходы | D39: ВСЕ | E39: 71900000 | F39: ПрочДоходОперДеят | G39: 14893303 | H39: 0 | I39: 3105094.5 | J39: 1605268.9 | K39: 1714715.5 | L39: 1532860 | M39: 2907404.5 | N39: 2142183.6 | O39: 1885776 | P39: 0 | Q39: 0 | R39: 0 | S39: 0 | T39: 0
A40: 40 | B40: КЛО_МРЦ71900100 | C40: Прочие доходы | D40: ФИНАНСОВЫЙ | E40: 71900100 | F40: ПрочДоход% банка | G40: 0 | H40: 0 | I40: 0 | J40: 0 | K40: 0 | L40: 0 | M40: 0 | N40: 0 | O40: 0 | P40: 0 | Q40: 0 | R40: 0 | S40: 0 | T40: 0
...

Sheet вересень
I1: 45658 | J1: 45689 | K1: 45717 | L1: 45748 | M1: 45778 | N1: 45809 | O1: 45839 | P1: 45870 | Q1: 45901 | R1: 45931 | S1: 45962 | T1: 45992
A2: 2 | E2: КЛО_МРЦ | F2: Киев,Фора МРЦ Оросительная,5 | G2: ИТОГО 2024 | H2: % К ОБОРОТУ | I2: 45658 | J2: 45689 | K2: 45717 | L2: 45383 | M2: 45778 | N2: 45809 | O2: 45839 | P2: 45870 | Q2: 45901 | R2: 45931 | S2: 45962 | T2: 45992
A3: 3 | B3: КЛО_МРЦДоходы | E3: Доходы
A4: 4 | C4: mapping Бюджет | D4: Разбивка по Офисам | E4: Код | F4: 1. Выручка | G4: 583523.2 | H4: 4.1113201e-06 | I4: 56312.5 | J4: 43272.3 | K4: 43860.04 | L4: 42136.95 | M4: 133672.61 | N4: 28768.98 | O4: 62942.62 | P4: 105747.07 | Q4: 66810.13 | R4: 0 | S4: 0 | T4: 0
A5: 5 | B5: КЛО_МРЦ70200000 | C5: Валовая прибыль (без бонусов) | D5: ВСЕ | E5: 70200000 | F5: ДоходРеалТовара | G5: 583523.2 | H5: 4.1113201e-06 | I5: 56312.5 | J5: 43272.3 | K5: 43860.04 | L5: 42136.95 | M5: 133672.61 | N5: 28768.98 | O5: 62942.62 | P5: 105747.07 | Q5: 66810.13 | R5: 0 | S5: 0 | T5: 0
A6: 6 | B6: КЛО_МРЦ70200001 | C6: Валовая прибыль (без бонусов) | D6: МАРКЕТИНГ | E6: 70200001 | F6: ДоходРеалПрогрЛояльн | G6: 0 | H6: 0 | I6: 0 | J6: 0 | K6: 0 | L6: 0 | M6: 0 | N6: 0 | O6: 0 | P6: 0 | Q6: 0 | R6: 0 | S6: 0 | T6: 0
A7: 7 | B7: КЛО_МРЦ70200002 | C7: Валовая прибыль (без бонусов) | D7: МАРКЕТИНГ | E7: 70200002 | F7: ДоходРеалТВаучера | G7: 0 | H7: 0 | I7: 0 | J7: 0 | K7: 0 | L7: 0 | M7: 0 | N7: 0 | O7: 0 | P7: 0 | Q7: 0 | R7: 0 | S7: 0 | T7: 0
A8: 8 | B8: КЛО_МРЦ70200003 | C8: Валовая прибыль (без бонусов) | E8: 70200003 | F8: ДоходРеалТовКомиссия | G8: 0 | H8: 0 | I8: 0 | J8: 0 | K8: 0 | L8: 0 | M8: 0 | N8: 0 | O8: 0 | P8: 0 | Q8: 0 | R8: 0 | S8: 0 | T8: 0
A9: 9 | B9: КЛО_МРЦ70200004 | C9: Валовая прибыль (без бонусов) | D9: Дирекция | E9: 70200004 | F9: ДоходРеалАгентсДог | G9: 0 | H9: 0 | I9: 0 | J9: 0 | K9: 0 | L9: 0 | M9: 0 | N9: 0 | O9: 0 | P9: 0 | Q9: 0 | R9: 0 | S9: 0 | T9: 0
A10: 10 | B10: КЛО_МРЦ70200009 | C10: Валовая прибыль (без бонусов) | D10: Дирекция | E10: 70200009 | F10: Недополучен.выручка | G10: 0 | H10: 0 | I10: 0 | J10: 0 | K10: 0 | L10: 0 | M10: 0 | N10: 0 | O10: 0 | P10: 0 | Q10: 0 | R10: 0 | S10: 0 | T10: 0
A11: 11 | B11: КЛО_МРЦ70200200 | C11: Валовая прибыль (без бонусов) | D11: Дирекция | E11: 70200200 | F11: ДоходРеалТовЭкспорт | G11: 0 | H11: 0 | I11: 0 | J11: 0 | K11: 0 | L11: 0 | M11: 0 | N11: 0 | O11: 0 | P11: 0 | Q11: 0 | R11: 0 | S11: 0 | T11: 0
A12: 12 | B12: КЛО_МРЦ70400000 | C12: Валовая прибыль (без бонусов) | D12: Дирекция | E12: 70400000 | F12: ВычетыДоходТовар | G12: 0 | H12: 0 | I12: 0 | J12: 0 | K12: 0 | L12: 0 | M12: 0 | N12: 0 | O12: 0 | P12: 0 | Q12: 0 | R12: 0 | S12: 0 | T12: 0
A13: 13 | B13: КЛО_МРЦ70430000 | C13: Валовая прибыль (без бонусов) | D13: Дирекция | E13: 70430000 | F13: ВычетыДоходАгентсДог | G13: 0 | H13: 0 | I13: 0 | J13: 0 | K13: 0 | L13: 0 | M13: 0 | N13: 0 | O13: 0 | P13: 0 | Q13: 0 | R13: 0 | S13: 0 | T13: 0
A14: 14 | E14: 1
A15: 15 | E15: 1 | F15: 2. Себестоимость | G15: -870181.49 | H15: -4.0635167e-06 | I15: -63168.81 | J15: -27005.75 | K15: -51602.41 | L15: -62649.3 | M15: -108767.59 | N15: -41921.78 | O15: -88417.27 | P15: -332714.32 | Q15: -93934.26 | R15: 0 | S15: 0 | T15: 0
A16: 16 | B16: КЛО_МРЦ90200000 | C16: Валовая прибыль (без бонусов) | D16: КЛО | E16: 90200000 | F16: СебестРеализТоваров | G16: -293622.97 | H16: -7.8532048e-10 | I16: 0 | J16: -27.4 | K16: 0 | L16: 0 | M16: -19296.99 | N16: 0 | O16: 0 | P16: -274298.58 | Q16: 0 | R16: 0 | S16: 0 | T16: 0
A17: 17 | B17: КЛО_МРЦ90200001 | C17: Валовая прибыль (без бонусов) | D17: КЛО | E17: 90200001 | F17: СебестРеалТоваровПро | G17: -576558.52 | H17: -4.0627314e-06 | I17: -63168.81 | J17: -26978.35 | K17: -51602.41 | L17: -62649.3 | M17: -89470.6 | N17: -41921.78 | O17: -88417.27 | P17: -58415.74 | Q17: -93934.26 | R17: 0 | S17: 0 | T17: 0
A18: 18 | E18: 1
A19: 19 | E19: 1 | F19: 3. Валовая маржа | G19: -286658.29 | H19: 4.7803375e-08 | I19: -6856.31 | J19: 16266.55 | K19: -7742.37 | L19: -20512.35 | M19: 24905.02 | N19: -13152.8 | O19: -25474.65 | P19: -226967.25 | Q19: -27124.13 | R19: 0 | S19: 0 | T19: 0
A20: 20 | E20: 1
A21: 21 | E21: 1 | F21: 4. Бонусы | G21: 0 | H21: 0 | I21: 0 | J21: 0 | K21: 0 | L21: 0 | M21: 0 | N21: 0 | O21: 0 | P21: 0 | Q21: 0 | R21: 0 | S21: 0 | T21: 0
A22: 22 | B22: КЛО_МРЦ71900700 | C22: Бонусы | D22: КЛО | E22: 71900700 | F22: ДоходОтБонусов | G22: 0 | H22: 0 | I22: 0 | J22: 0 | K22: 0 | L22: 0 | M22: 0 | N22: 0 | O22: 0 | P22: 0 | Q22: 0 | R22: 0 | S22: 0 | T22: 0
A23: 23 | E23: 1
A24: 24 | E24: 1 | F24: 5. Прочее - Доходы | G24: 19980900 | H24: 0 | I24: 3105094.5 | J24: 1605268.9 | K24: 1724627.5 | L24: 1546722.8 | M24: 2920354.5 | N24: 2142183.6 | O24: 1894218 | P24: 2368853 | Q24: 2673577.7 | R24: 0 | S24: 0 | T24: 0
A25: 25 | B25: КЛО_МРЦ70300000 | C25: Прочие доходы | D25: МАРКЕТИНГ | E25: 70300000 | F25: ДоходРеалРабУсл | G25: 0 | H25: 0 | I25: 0 | J25: 0 | K25: 0 | L25: 0 | M25: 0 | N25: 0 | O25: 0 | P25: 0 | Q25: 0 | R25: 0 | S25: 0 | T25: 0
A26: 26 | B26: КЛО_МРЦ70300200 | C26: Прочие доходы | D26: МАРКЕТИНГ | E26: 70300200 | F26: ДохРазмРеклСобствНН | G26: 0 | H26: 0 | I26: 0 | J26: 0 | K26: 0 | L26: 0 | M26: 0 | N26: 0 | O26: 0 | P26: 0 | Q26: 0 | R26: 0 | S26: 0 | T26: 0
A27: 27 | B27: КЛО_МРЦ70300700 | C27: Прочие доходы | D27: КЛО | E27: 70300700 | F27: ДохРеалУслЛогист | G27: 0 | H27: 0 | I27: 0 | J27: 0 | K27: 0 | L27: 0 | M27: 0 | N27: 0 | O27: 0 | P27: 0 | Q27: 0 | R27: 0 | S27: 0 | T27: 0
A28: 28 | B28: КЛО_МРЦ70300800 | C28: Прочие доходы | D28: ОПЕРАЦИОННЫЙ | E28: 70300800 | F28: ДоходДогКомиссии | G28: 0 | H28: 0 | I28: 0 | J28: 0 | K28: 0 | L28: 0 | M28: 0 | N28: 0 | O28: 0 | P28: 0 | Q28: 0 | R28: 0 | S28: 0 | T28: 0
A29: 29 | B29: КЛО_МРЦ70300900 | C29: Прочие доходы | D29: ОПЕРАЦИОННЫЙ | E29: 70300900 | F29: ДоходУслугКонечнПотр | G29: 0 | H29: 0 | I29: 0 | J29: 0 | K29: 0 | L29: 0 | M29: 0 | N29: 0 | O29: 0 | P29: 0 | Q29: 0 | R29: 0 | S29: 0 | T29: 0
A30: 30 | B30: КЛО_МРЦ71200000 | C30: Прочие доходы | D30: Дирекция | E30: 71200000 | F30: ДохРеалПрочОбАкт | G30: 0 | H30: 0 | I30: 0 | J30: 0 | K30: 0 | L30: 0 | M30: 0 | N30: 0 | O30: 0 | P30: 0 | Q30: 0 | R30: 0 | S30: 0 | T30: 0
A31: 31 | B31: КЛО_МРЦ71200100 | C31: Прочие доходы | D31: ОПЕРАЦИОННЫЙ+СБ | E31: 71200100 | F31: ДохРеалМакулатуры | G31: 79886.8 | H31: 2.8409112e-07 | I31: 0 | J31: 0 | K31: 9912 | L31: 13862.8 | M31: 12950 | N31: 0 | O31: 8442 | P31: 17626 | Q31: 17094 | R31: 0 | S31: 0 | T31: 0
A32: 32 | B32: КЛО_МРЦ71300000 | C32: Прочие доходы | E32: 71300000 | F32: ДохАренОборудован | G32: 0 | H32: 0 | I32: 0 | J32: 0 | K32: 0 | L32: 0 | M32: 0 | N32: 0 | O32: 0 | P32: 0 | Q32: 0 | R32: 0 | S32: 0 | T32: 0
A33: 33 | B33: КЛО_МРЦ71300200 | C33: Прочие доходы | E33: 71300200 | F33: ДохАренТранспорта | G33: 0 | H33: 0 | I33: 0 | J33: 0 | K33: 0 | L33: 0 | M33: 0 | N33: 0 | O33: 0 | P33: 0 | Q33: 0 | R33: 0 | S33: 0 | T33: 0
A34: 34 | B34: КЛО_МРЦ71500000 | C34: Прочие доходы | D34: КЛО | E34: 71500000 | F34: ПолучШтрафПени | G34: 0 | H34: 0 | I34: 0 | J34: 0 | K34: 0 | L34: 0 | M34: 0 | N34: 0 | O34: 0 | P34: 0 | Q34: 0 | R34: 0 | S34: 0 | T34: 0
A35: 35 | B35: КЛО_МРЦ71500100 | C35: Прочие доходы | E35: 71500100 | F35: ОтримШтрафиПеніКомер | H35: 0
A36: 36 | B36: КЛО_МРЦ71700000 | C36: Прочие доходы | E36: 71700000 | F36: ДохСписКредЗадолж | G36: 0 | H36: 0 | I36: 0 | J36: 0 | K36: 0 | L36: 0 | M36: 0 | N36: 0 | O36: 0 | P36: 0 | Q36: 0 | R36: 0 | S36: 0 | T36: 0
A37: 37 | B37: КЛО_МРЦ71800000 | C37: Прочие доходы | D37: 0 | E37: 71800000 | F37: ДохБесплПолОборАкт | G37: 0 | H37: 0 | I37: 0 | J37: 0 | K37: 0 | L37: 0 | M37: 0 | N37: 0 | O37: 0 | P37: 0 | Q37: 0 | R37: 0 | S37: 0 | T37: 0
A38: 38 | B38: КЛО_МРЦ71800400 | C38: Прочие доходы | E38: 71800400 | F38: ДохБесплПолАктив.РЦ | G38: 0 | H38: 0 | I38: 0 | J38: 0 | K38: 0 | L38: 0 | M38: 0 | N38: 0 | O38: 0 | P38: 0 | Q38: 0 | R38: 0 | S38: 0 | T38: 0
A39: 39 | B39: КЛО_МРЦ71900000 | C39: Прочие доходы | D39: ВСЕ | E39: 71900000 | F39: ПрочДоходОперДеят | G39: 19901014 | H39: 0 | I39: 3105094.5 | J39: 1605268.9 | K39: 1714715.5 | L39: 1532860 | M39: 2907404.5 | N39: 2142183.6 | O39: 1885776 | P39: 2351227 | Q39: 2656483.7 | R39: 0 | S39: 0 | T39: 0
A40: 40 | B40: КЛО_МРЦ71900100 | C40: Прочие доходы | D40: ФИНАНСОВЫЙ | E40: 71900100 | F40: ПрочДоход% банка | G40: 0 | H40: 0 | I40: 0 | J40: 0 | K40: 0 | L40: 0 | M40: 0 | N40: 0 | O40: 0 | P40: 0 | Q40: 0 | R40: 0 | S40: 0 | T40: 0
...

Sheet жовтень
I1: 45658 | J1: 45689 | K1: 45717 | L1: 45748 | M1: 45778 | N1: 45809 | O1: 45839 | P1: 45870 | Q1: 45901 | R1: 45931 | S1: 45962 | T1: 45992
A2: 2 | E2: КЛО_МРЦ | F2: Киев,Фора МРЦ Оросительная,5 | G2: ИТОГО 2024 | H2: % К ОБОРОТУ | I2: 45658 | J2: 45689 | K2: 45717 | L2: 45383 | M2: 45778 | N2: 45809 | O2: 45839 | P2: 45870 | Q2: 45901 | R2: 45931 | S2: 45962 | T2: 45992
A3: 3 | B3: КЛО_МРЦДоходы | E3: Доходы
A4: 4 | C4: mapping Бюджет | D4: Разбивка по Офисам | E4: Код | F4: 1. Выручка | G4: 663725.38 | H4: 4.1113201e-06 | I4: 56312.5 | J4: 43272.3 | K4: 43860.04 | L4: 42136.95 | M4: 133672.61 | N4: 28768.98 | O4: 62942.62 | P4: 105747.07 | Q4: 66810.13 | R4: 80202.18 | S4: 0 | T4: 0
A5: 5 | B5: КЛО_МРЦ70200000 | C5: Валовая прибыль (без бонусов) | D5: ВСЕ | E5: 70200000 | F5: ДоходРеалТовара | G5: 663725.38 | H5: 4.1113201e-06 | I5: 56312.5 | J5: 43272.3 | K5: 43860.04 | L5: 42136.95 | M5: 133672.61 | N5: 28768.98 | O5: 62942.62 | P5: 105747.07 | Q5: 66810.13 | R5: 80202.18 | S5: 0 | T5: 0
A6: 6 | B6: КЛО_МРЦ70200001 | C6: Валовая прибыль (без бонусов) | D6: МАРКЕТИНГ | E6: 70200001 | F6: ДоходРеалПрогрЛояльн | G6: 0 | H6: 0 | I6: 0 | J6: 0 | K6: 0 | L6: 0 | M6: 0 | N6: 0 | O6: 0 | P6: 0 | Q6: 0 | R6: 0 | S6: 0 | T6: 0
A7: 7 | B7: КЛО_МРЦ70200002 | C7: Валовая прибыль (без бонусов) | D7: МАРКЕТИНГ | E7: 70200002 | F7: ДоходРеалТВаучера | G7: 0 | H7: 0 | I7: 0 | J7: 0 | K7: 0 | L7: 0 | M7: 0 | N7: 0 | O7: 0 | P7: 0 | Q7: 0 | R7: 0 | S7: 0 | T7: 0
A8: 8 | B8: КЛО_МРЦ70200003 | C8: Валовая прибыль (без бонусов) | E8: 70200003 | F8: ДоходРеалТовКомиссия | G8: 0 | H8: 0 | I8: 0 | J8: 0 | K8: 0 | L8: 0 | M8: 0 | N8: 0 | O8: 0 | P8: 0 | Q8: 0 | R8: 0 | S8: 0 | T8: 0
A9: 9 | B9: КЛО_МРЦ70200004 | C9: Валовая прибыль (без бонусов) | D9: Дирекция | E9: 70200004 | F9: ДоходРеалАгентсДог | G9: 0 | H9: 0 | I9: 0 | J9: 0 | K9: 0 | L9: 0 | M9: 0 | N9: 0 | O9: 0 | P9: 0 | Q9: 0 | R9: 0 | S9: 0 | T9: 0
A10: 10 | B10: КЛО_МРЦ70200009 | C10: Валовая прибыль (без бонусов) | D10: Дирекция | E10: 70200009 | F10: Недополучен.выручка | G10: 0 | H10: 0 | I10: 0 | J10: 0 | K10: 0 | L10: 0 | M10: 0 | N10: 0 | O10: 0 | P10: 0 | Q10: 0 | R10: 0 | S10: 0 | T10: 0
A11: 11 | B11: КЛО_МРЦ70200200 | C11: Валовая прибыль (без бонусов) | D11: Дирекция | E11: 70200200 | F11: ДоходРеалТовЭкспорт | G11: 0 | H11: 0 | I11: 0 | J11: 0 | K11: 0 | L11: 0 | M11: 0 | N11: 0 | O11: 0 | P11: 0 | Q11: 0 | R11: 0 | S11: 0 | T11: 0
A12: 12 | B12: КЛО_МРЦ70400000 | C12: Валовая прибыль (без бонусов) | D12: Дирекция | E12: 70400000 | F12: ВычетыДоходТовар | G12: 0 | H12: 0 | I12: 0 | J12: 0 | K12: 0 | L12: 0 | M12: 0 | N12: 0 | O12: 0 | P12: 0 | Q12: 0 | R12: 0 | S12: 0 | T12: 0
A13: 13 | B13: КЛО_МРЦ70430000 | C13: Валовая прибыль (без бонусов) | D13: Дирекция | E13: 70430000 | F13: ВычетыДоходАгентсДог | G13: 0 | H13: 0 | I13: 0 | J13: 0 | K13: 0 | L13: 0 | M13: 0 | N13: 0 | O13: 0 | P13: 0 | Q13: 0 | R13: 0 | S13: 0 | T13: 0
A14: 14 | E14: 1
A15: 15 | E15: 1 | F15: 2. Себестоимость | G15: -973664.21 | H15: -4.0635167e-06 | I15: -63168.81 | J15: -27005.75 | K15: -51602.41 | L15: -62649.3 | M15: -108767.59 | N15: -41921.78 | O15: -88417.27 | P15: -332714.32 | Q15: -93934.26 | R15: -103482.72 | S15: 0 | T15: 0
A16: 16 | B16: КЛО_МРЦ90200000 | C16: Валовая прибыль (без бонусов) | D16: КЛО | E16: 90200000 | F16: СебестРеализТоваров | G16: -314377.51 | H16: -7.8532048e-10 | I16: 0 | J16: -27.4 | K16: 0 | L16: 0 | M16: -19296.99 | N16: 0 | O16: 0 | P16: -274298.58 | Q16: 0 | R16: -20754.54 | S16: 0 | T16: 0
A17: 17 | B17: КЛО_МРЦ90200001 | C17: Валовая прибыль (без бонусов) | D17: КЛО | E17: 90200001 | F17: СебестРеалТоваровПро | G17: -659286.7 | H17: -4.0627314e-06 | I17: -63168.81 | J17: -26978.35 | K17: -51602.41 | L17: -62649.3 | M17: -89470.6 | N17: -41921.78 | O17: -88417.27 | P17: -58415.74 | Q17: -93934.26 | R17: -82728.18 | S17: 0 | T17: 0
A18: 18 | E18: 1
A19: 19 | E19: 1 | F19: 3. Валовая маржа | G19: -309938.83 | H19: 4.7803375e-08 | I19: -6856.31 | J19: 16266.55 | K19: -7742.37 | L19: -20512.35 | M19: 24905.02 | N19: -13152.8 | O19: -25474.65 | P19: -226967.25 | Q19: -27124.13 | R19: -23280.54 | S19: 0 | T19: 0
A20: 20 | E20: 1
A21: 21 | E21: 1 | F21: 4. Бонусы | G21: 0 | H21: 0 | I21: 0 | J21: 0 | K21: 0 | L21: 0 | M21: 0 | N21: 0 | O21: 0 | P21: 0 | Q21: 0 | R21: 0 | S21: 0 | T21: 0
A22: 22 | B22: КЛО_МРЦ71900700 | C22: Бонусы | D22: КЛО | E22: 71900700 | F22: ДоходОтБонусов | G22: 0 | H22: 0 | I22: 0 | J22: 0 | K22: 0 | L22: 0 | M22: 0 | N22: 0 | O22: 0 | P22: 0 | Q22: 0 | R22: 0 | S22: 0 | T22: 0
A23: 23 | E23: 1
A24: 24 | E24: 1 | F24: 5. Прочее - Доходы | G24: 23673814 | H24: 0 | I24: 3105094.5 | J24: 1605268.9 | K24: 1724627.5 | L24: 1546722.8 | M24: 2920354.5 | N24: 2142183.6 | O24: 1894218 | P24: 2368853 | Q24: 2673577.7 | R24: 3692914 | S24: 0 | T24: 0
A25: 25 | B25: КЛО_МРЦ70300000 | C25: Прочие доходы | D25: МАРКЕТИНГ | E25: 70300000 | F25: ДоходРеалРабУсл | G25: 0 | H25: 0 | I25: 0 | J25: 0 | K25: 0 | L25: 0 | M25: 0 | N25: 0 | O25: 0 | P25: 0 | Q25: 0 | R25: 0 | S25: 0 | T25: 0
A26: 26 | B26: КЛО_МРЦ70300200 | C26: Прочие доходы | D26: МАРКЕТИНГ | E26: 70300200 | F26: ДохРазмРеклСобствНН | G26: 0 | H26: 0 | I26: 0 | J26: 0 | K26: 0 | L26: 0 | M26: 0 | N26: 0 | O26: 0 | P26: 0 | Q26: 0 | R26: 0 | S26: 0 | T26: 0
A27: 27 | B27: КЛО_МРЦ70300700 | C27: Прочие доходы | D27: КЛО | E27: 70300700 | F27: ДохРеалУслЛогист | G27: 0 | H27: 0 | I27: 0 | J27: 0 | K27: 0 | L27: 0 | M27: 0 | N27: 0 | O27: 0 | P27: 0 | Q27: 0 | R27: 0 | S27: 0 | T27: 0
A28: 28 | B28: КЛО_МРЦ70300800 | C28: Прочие доходы | D28: ОПЕРАЦИОННЫЙ | E28: 70300800 | F28: ДоходДогКомиссии | G28: 0 | H28: 0 | I28: 0 | J28: 0 | K28: 0 | L28: 0 | M28: 0 | N28: 0 | O28: 0 | P28: 0 | Q28: 0 | R28: 0 | S28: 0 | T28: 0
A29: 29 | B29: КЛО_МРЦ70300900 | C29: Прочие доходы | D29: ОПЕРАЦИОННЫЙ | E29: 70300900 | F29: ДоходУслугКонечнПотр | G29: 0 | H29: 0 | I29: 0 | J29: 0 | K29: 0 | L29: 0 | M29: 0 | N29: 0 | O29: 0 | P29: 0 | Q29: 0 | R29: 0 | S29: 0 | T29: 0
A30: 30 | B30: КЛО_МРЦ71200000 | C30: Прочие доходы | D30: Дирекция | E30: 71200000 | F30: ДохРеалПрочОбАкт | G30: 0 | H30: 0 | I30: 0 | J30: 0 | K30: 0 | L30: 0 | M30: 0 | N30: 0 | O30: 0 | P30: 0 | Q30: 0 | R30: 0 | S30: 0 | T30: 0
A31: 31 | B31: КЛО_МРЦ71200100 | C31: Прочие доходы | D31: ОПЕРАЦИОННЫЙ+СБ | E31: 71200100 | F31: ДохРеалМакулатуры | G31: 93144.8 | H31: 2.8409112e-07 | I31: 0 | J31: 0 | K31: 9912 | L31: 13862.8 | M31: 12950 | N31: 0 | O31: 8442 | P31: 17626 | Q31: 17094 | R31: 13258 | S31: 0 | T31: 0
A32: 32 | B32: КЛО_МРЦ71300000 | C32: Прочие доходы | E32: 71300000 | F32: ДохАренОборудован | G32: 0 | H32: 0 | I32: 0 | J32: 0 | K32: 0 | L32: 0 | M32: 0 | N32: 0 | O32: 0 | P32: 0 | Q32: 0 | R32: 0 | S32: 0 | T32: 0
A33: 33 | B33: КЛО_МРЦ71300200 | C33: Прочие доходы | E33: 71300200 | F33: ДохАренТранспорта | G33: 0 | H33: 0 | I33: 0 | J33: 0 | K33: 0 | L33: 0 | M33: 0 | N33: 0 | O33: 0 | P33: 0 | Q33: 0 | R33: 0 | S33: 0 | T33: 0
A34: 34 | B34: КЛО_МРЦ71500000 | C34: Прочие доходы | D34: КЛО | E34: 71500000 | F34: ПолучШтрафПени | G34: 0 | H34: 0 | I34: 0 | J34: 0 | K34: 0 | L34: 0 | M34: 0 | N34: 0 | O34: 0 | P34: 0 | Q34: 0 | R34: 0 | S34: 0 | T34: 0
A35: 35 | B35: КЛО_МРЦ71500100 | C35: Прочие доходы | E35: 71500100 | F35: ОтримШтрафиПеніКомер | H35: 0
A36: 36 | B36: КЛО_МРЦ71700000 | C36: Прочие доходы | E36: 71700000 | F36: ДохСписКредЗадолж | G36: 0 | H36: 0 | I36: 0 | J36: 0 | K36: 0 | L36: 0 | M36: 0 | N36: 0 | O36: 0 | P36: 0 | Q36: 0 | R36: 0 | S36: 0 | T36: 0
A37: 37 | B37: КЛО_МРЦ71800000 | C37: Прочие доходы | D37: 0 | E37: 71800000 | F37: ДохБесплПолОборАкт | G37: 0 | H37: 0 | I37: 0 | J37: 0 | K37: 0 | L37: 0 | M37: 0 | N37: 0 | O37: 0 | P37: 0 | Q37: 0 | R37: 0 | S37: 0 | T37: 0
A38: 38 | B38: КЛО_МРЦ71800400 | C38: Прочие доходы | E38: 71800400 | F38: ДохБесплПолАктив.РЦ | G38: 0 | H38: 0 | I38: 0 | J38: 0 | K38: 0 | L38: 0 | M38: 0 | N38: 0 | O38: 0 | P38: 0 | Q38: 0 | R38: 0 | S38: 0 | T38: 0
A39: 39 | B39: КЛО_МРЦ71900000 | C39: Прочие доходы | D39: ВСЕ | E39: 71900000 | F39: ПрочДоходОперДеят | G39: 23580670 | H39: 0 | I39: 3105094.5 | J39: 1605268.9 | K39: 1714715.5 | L39: 1532860 | M39: 2907404.5 | N39: 2142183.6 | O39: 1885776 | P39: 2351227 | Q39: 2656483.7 | R39: 3679656 | S39: 0 | T39: 0
A40: 40 | B40: КЛО_МРЦ71900100 | C40: Прочие доходы | D40: ФИНАНСОВЫЙ | E40: 71900100 | F40: ПрочДоход% банка | G40: 0 | H40: 0 | I40: 0 | J40: 0 | K40: 0 | L40: 0 | M40: 0 | N40: 0 | O40: 0 | P40: 0 | Q40: 0 | R40: 0 | S40: 0 | T40: 0
...

Sheet листопад
I1: 45658 | J1: 45689 | K1: 45717 | L1: 45748 | M1: 45778 | N1: 45809 | O1: 45839 | P1: 45870 | Q1: 45901 | R1: 45931 | S1: 45962 | T1: 45992
A2: 2 | E2: КЛО_МРЦ | F2: Киев,Фора МРЦ Оросительная,5 | G2: ИТОГО 2024 | H2: % К ОБОРОТУ | I2: 45658 | J2: 45689 | K2: 45717 | L2: 45383 | M2: 45778 | N2: 45809 | O2: 45839 | P2: 45870 | Q2: 45901 | R2: 45931 | S2: 45962 | T2: 45992
A3: 3 | B3: КЛО_МРЦДоходы | E3: Доходы
A4: 4 | C4: mapping Бюджет | D4: Разбивка по Офисам | E4: Код | F4: 1. Выручка | G4: 737234.25 | H4: 4.1113201e-06 | I4: 56312.5 | J4: 43272.3 | K4: 43860.04 | L4: 42136.95 | M4: 133672.61 | N4: 28768.98 | O4: 62942.62 | P4: 105747.07 | Q4: 66810.13 | R4: 80202.18 | S4: 73508.87 | T4: 0
A5: 5 | B5: КЛО_МРЦ70200000 | C5: Валовая прибыль (без бонусов) | D5: ВСЕ | E5: 70200000 | F5: ДоходРеалТовара | G5: 737234.25 | H5: 4.1113201e-06 | I5: 56312.5 | J5: 43272.3 | K5: 43860.04 | L5: 42136.95 | M5: 133672.61 | N5: 28768.98 | O5: 62942.62 | P5: 105747.07 | Q5: 66810.13 | R5: 80202.18 | S5: 73508.87 | T5: 0
A6: 6 | B6: КЛО_МРЦ70200001 | C6: Валовая прибыль (без бонусов) | D6: МАРКЕТИНГ | E6: 70200001 | F6: ДоходРеалПрогрЛояльн | G6: 0 | H6: 0 | I6: 0 | J6: 0 | K6: 0 | L6: 0 | M6: 0 | N6: 0 | O6: 0 | P6: 0 | Q6: 0 | R6: 0 | S6: 0 | T6: 0
A7: 7 | B7: КЛО_МРЦ70200002 | C7: Валовая прибыль (без бонусов) | D7: МАРКЕТИНГ | E7: 70200002 | F7: ДоходРеалТВаучера | G7: 0 | H7: 0 | I7: 0 | J7: 0 | K7: 0 | L7: 0 | M7: 0 | N7: 0 | O7: 0 | P7: 0 | Q7: 0 | R7: 0 | S7: 0 | T7: 0
A8: 8 | B8: КЛО_МРЦ70200003 | C8: Валовая прибыль (без бонусов) | E8: 70200003 | F8: ДоходРеалТовКомиссия | G8: 0 | H8: 0 | I8: 0 | J8: 0 | K8: 0 | L8: 0 | M8: 0 | N8: 0 | O8: 0 | P8: 0 | Q8: 0 | R8: 0 | S8: 0 | T8: 0
A9: 9 | B9: КЛО_МРЦ70200004 | C9: Валовая прибыль (без бонусов) | D9: Дирекция | E9: 70200004 | F9: ДоходРеалАгентсДог | G9: 0 | H9: 0 | I9: 0 | J9: 0 | K9: 0 | L9: 0 | M9: 0 | N9: 0 | O9: 0 | P9: 0 | Q9: 0 | R9: 0 | S9: 0 | T9: 0
A10: 10 | B10: КЛО_МРЦ70200009 | C10: Валовая прибыль (без бонусов) | D10: Дирекция | E10: 70200009 | F10: Недополучен.выручка | G10: 0 | H10: 0 | I10: 0 | J10: 0 | K10: 0 | L10: 0 | M10: 0 | N10: 0 | O10: 0 | P10: 0 | Q10: 0 | R10: 0 | S10: 0 | T10: 0
A11: 11 | B11: КЛО_МРЦ70200200 | C11: Валовая прибыль (без бонусов) | D11: Дирекция | E11: 70200200 | F11: ДоходРеалТовЭкспорт | G11: 0 | H11: 0 | I11: 0 | J11: 0 | K11: 0 | L11: 0 | M11: 0 | N11: 0 | O11: 0 | P11: 0 | Q11: 0 | R11: 0 | S11: 0 | T11: 0
A12: 12 | B12: КЛО_МРЦ70400000 | C12: Валовая прибыль (без бонусов) | D12: Дирекция | E12: 70400000 | F12: ВычетыДоходТовар | G12: 0 | H12: 0 | I12: 0 | J12: 0 | K12: 0 | L12: 0 | M12: 0 | N12: 0 | O12: 0 | P12: 0 | Q12: 0 | R12: 0 | S12: 0 | T12: 0
A13: 13 | B13: КЛО_МРЦ70430000 | C13: Валовая прибыль (без бонусов) | D13: Дирекция | E13: 70430000 | F13: ВычетыДоходАгентсДог | G13: 0 | H13: 0 | I13: 0 | J13: 0 | K13: 0 | L13: 0 | M13: 0 | N13: 0 | O13: 0 | P13: 0 | Q13: 0 | R13: 0 | S13: 0 | T13: 0
A14: 14 | E14: 1
A15: 15 | E15: 1 | F15: 2. Себестоимость | G15: 1471181.6 | H15: -4.0635167e-06 | I15: -63168.81 | J15: -27005.75 | K15: -51602.41 | L15: -62649.3 | M15: -108767.59 | N15: -41921.78 | O15: -88417.27 | P15: -332714.32 | Q15: -93934.26 | R15: -103482.72 | S15: 2444845.8 | T15: 0
A16: 16 | B16: КЛО_МРЦ90200000 | C16: Валовая прибыль (без бонусов) | D16: КЛО | E16: 90200000 | F16: СебестРеализТоваров | G16: -319354.18 | H16: -7.8532048e-10 | I16: 0 | J16: -27.4 | K16: 0 | L16: 0 | M16: -19296.99 | N16: 0 | O16: 0 | P16: -274298.58 | Q16: 0 | R16: -20754.54 | S16: -4976.67 | T16: 0
A17: 17 | B17: КЛО_МРЦ90200001 | C17: Валовая прибыль (без бонусов) | D17: КЛО | E17: 90200001 | F17: СебестРеалТоваровПро | G17: 1790535.7 | H17: -4.0627314e-06 | I17: -63168.81 | J17: -26978.35 | K17: -51602.41 | L17: -62649.3 | M17: -89470.6 | N17: -41921.78 | O17: -88417.27 | P17: -58415.74 | Q17: -93934.26 | R17: -82728.18 | S17: 2449822.4 | T17: 0
A18: 18 | E18: 1
A19: 19 | E19: 1 | F19: 3. Валовая маржа | G19: 2208415.8 | H19: 4.7803375e-08 | I19: -6856.31 | J19: 16266.55 | K19: -7742.37 | L19: -20512.35 | M19: 24905.02 | N19: -13152.8 | O19: -25474.65 | P19: -226967.25 | Q19: -27124.13 | R19: -23280.54 | S19: 2518354.6 | T19: 0
A20: 20 | E20: 1
A21: 21 | E21: 1 | F21: 4. Бонусы | G21: 0 | H21: 0 | I21: 0 | J21: 0 | K21: 0 | L21: 0 | M21: 0 | N21: 0 | O21: 0 | P21: 0 | Q21: 0 | R21: 0 | S21: 0 | T21: 0
A22: 22 | B22: КЛО_МРЦ71900700 | C22: Бонусы | D22: КЛО | E22: 71900700 | F22: ДоходОтБонусов | G22: 0 | H22: 0 | I22: 0 | J22: 0 | K22: 0 | L22: 0 | M22: 0 | N22: 0 | O22: 0 | P22: 0 | Q22: 0 | R22: 0 | S22: 0 | T22: 0
A23: 23 | E23: 1
A24: 24 | E24: 1 | F24: 5. Прочее - Доходы | G24: 26639344 | H24: 0 | I24: 3105094.5 | J24: 1605268.9 | K24: 1724627.5 | L24: 1546722.8 | M24: 2920354.5 | N24: 2142183.6 | O24: 1894218 | P24: 2368853 | Q24: 2673577.7 | R24: 3692914 | S24: 2965529.5 | T24: 0
A25: 25 | B25: КЛО_МРЦ70300000 | C25: Прочие доходы | D25: МАРКЕТИНГ | E25: 70300000 | F25: ДоходРеалРабУсл | G25: 0 | H25: 0 | I25: 0 | J25: 0 | K25: 0 | L25: 0 | M25: 0 | N25: 0 | O25: 0 | P25: 0 | Q25: 0 | R25: 0 | S25: 0 | T25: 0
A26: 26 | B26: КЛО_МРЦ70300200 | C26: Прочие доходы | D26: МАРКЕТИНГ | E26: 70300200 | F26: ДохРазмРеклСобствНН | G26: 0 | H26: 0 | I26: 0 | J26: 0 | K26: 0 | L26: 0 | M26: 0 | N26: 0 | O26: 0 | P26: 0 | Q26: 0 | R26: 0 | S26: 0 | T26: 0
A27: 27 | B27: КЛО_МРЦ70300700 | C27: Прочие доходы | D27: КЛО | E27: 70300700 | F27: ДохРеалУслЛогист | G27: 0 | H27: 0 | I27: 0 | J27: 0 | K27: 0 | L27: 0 | M27: 0 | N27: 0 | O27: 0 | P27: 0 | Q27: 0 | R27: 0 | S27: 0 | T27: 0
A28: 28 | B28: КЛО_МРЦ70300800 | C28: Прочие доходы | D28: ОПЕРАЦИОННЫЙ | E28: 70300800 | F28: ДоходДогКомиссии | G28: 0 | H28: 0 | I28: 0 | J28: 0 | K28: 0 | L28: 0 | M28: 0 | N28: 0 | O28: 0 | P28: 0 | Q28: 0 | R28: 0 | S28: 0 | T28: 0
A29: 29 | B29: КЛО_МРЦ70300900 | C29: Прочие доходы | D29: ОПЕРАЦИОННЫЙ | E29: 70300900 | F29: ДоходУслугКонечнПотр | G29: 0 | H29: 0 | I29: 0 | J29: 0 | K29: 0 | L29: 0 | M29: 0 | N29: 0 | O29: 0 | P29: 0 | Q29: 0 | R29: 0 | S29: 0 | T29: 0
A30: 30 | B30: КЛО_МРЦ71200000 | C30: Прочие доходы | D30: Дирекция | E30: 71200000 | F30: ДохРеалПрочОбАкт | G30: 0 | H30: 0 | I30: 0 | J30: 0 | K30: 0 | L30: 0 | M30: 0 | N30: 0 | O30: 0 | P30: 0 | Q30: 0 | R30: 0 | S30: 0 | T30: 0
A31: 31 | B31: КЛО_МРЦ71200100 | C31: Прочие доходы | D31: ОПЕРАЦИОННЫЙ+СБ | E31: 71200100 | F31: ДохРеалМакулатуры | G31: 93144.8 | H31: 2.8409112e-07 | I31: 0 | J31: 0 | K31: 9912 | L31: 13862.8 | M31: 12950 | N31: 0 | O31: 8442 | P31: 17626 | Q31: 17094 | R31: 13258 | S31: 0 | T31: 0
A32: 32 | B32: КЛО_МРЦ71300000 | C32: Прочие доходы | E32: 71300000 | F32: ДохАренОборудован | G32: 0 | H32: 0 | I32: 0 | J32: 0 | K32: 0 | L32: 0 | M32: 0 | N32: 0 | O32: 0 | P32: 0 | Q32: 0 | R32: 0 | S32: 0 | T32: 0
A33: 33 | B33: КЛО_МРЦ71300200 | C33: Прочие доходы | E33: 71300200 | F33: ДохАренТранспорта | G33: 0 | H33: 0 | I33: 0 | J33: 0 | K33: 0 | L33: 0 | M33: 0 | N33: 0 | O33: 0 | P33: 0 | Q33: 0 | R33: 0 | S33: 0 | T33: 0
A34: 34 | B34: КЛО_МРЦ71500000 | C34: Прочие доходы | D34: КЛО | E34: 71500000 | F34: ПолучШтрафПени | G34: 0 | H34: 0 | I34: 0 | J34: 0 | K34: 0 | L34: 0 | M34: 0 | N34: 0 | O34: 0 | P34: 0 | Q34: 0 | R34: 0 | S34: 0 | T34: 0
A35: 35 | B35: КЛО_МРЦ71500100 | C35: Прочие доходы | E35: 71500100 | F35: ОтримШтрафиПеніКомер | H35: 0
