Workbook

Sheet Data
D1: {=INDEX(довід_обладнання!$B:$B,MATCH(D2,довід_обладнання!$A:$A,0),)} -> Гриль | E1: {=INDEX(довід_обладнання!$B:$B,MATCH(E2,довід_обладнання!$A:$A,0),)} -> Стрит-Фуд | F1: {=INDEX(довід_обладнання!$B:$B,MATCH(F2,довід_обладнання!$A:$A,0),)} -> 0 | G1: {=INDEX(довід_обладнання!$B:$B,MATCH(G2,довід_обладнання!$A:$A,0),)} -> 0 | H1: {=INDEX(довід_обладнання!$B:$B,MATCH(H2,довід_обладнання!$A:$A,0),)} -> Гриль | I1: {=INDEX(довід_обладнання!$B:$B,MATCH(I2,довід_обладнання!$A:$A,0),)} -> Гриль | J1: {=INDEX(довід_обладнання!$B:$B,MATCH(J2,довід_обладнання!$A:$A,0),)} -> Допёк | K1: {=INDEX(довід_обладнання!$B:$B,MATCH(K2,довід_обладнання!$A:$A,0),)} -> Гриль | ... AF1: {=INDEX(довід_обладнання!$B:$B,MATCH(AF2,довід_обладнання!$A:$A,0),)} -> Пиццерия
A2: Дата | B2: Час | C2: Магазин | D2: Витяжка ПКВ | E2: Гриль шаурма | F2: Ел. плита | G2: Модульна піч | H2: ПКВ | I2: ПКВ гриль | J2: ПКВ допік | K2: ПКВ копчення | L2: ПКВ піч | M2: Піч Піца1 | N2: Піч піца | O2: Піч піца1 | P2: Піч піца2 | Q2: Розстоєчна шафа | R2: Ротаційна піч | S2: Тензометрія ПКВ | T2: Тензометрія ПКВ гриль | U2: Тензометрія ПКВ допік | V2: Тензометрія ПКВ копчення | W2: Тензометрія Теплова вітрина | X2: Тензометрія Теплова вітрина1 | Y2: Тензометрія Теплова вітрина2 | Z2: Теплова вітрина | AA2: Теплова вітрина 1 | AB2: Теплова вітрина1 | AC2: Теплова вітрина2 | AD2: ЩС Піца | AE2: ЩС пекарня | AF2: ЩС піца | AG2: Filid | AH2: year | AI2: month | AJ2: Пиццерия | AK2: Гриль | AL2: Стрит-Фуд | AM2: Допёк | AN2: Пекарня
A3: 45717.25 | B3: 45717.25 | C3: 001, Київ, Йорданська 20 | H3: 204.032 | J3: 893.794 | AB3: 588.505 | AG3: {=INDEX(tex!C:C,MATCH(C3,tex!B:B,0),)} -> 47 | AH3: =YEAR(A3) -> 2025 | AI3: =MONTH(A3) -> 3 | AJ3: =SUMIFS($D3:$AF3,$D$1:$AF$1,AJ$2) -> 588.505 | AK3: =SUMIFS($D3:$AF3,$D$1:$AF$1,AK$2) -> 204.032 | AL3: =SUMIFS($D3:$AF3,$D$1:$AF$1,AL$2) -> 0 | AM3: =SUMIFS($D3:$AF3,$D$1:$AF$1,AM$2) -> 893.794 | AN3: =SUMIFS($D3:$AF3,$D$1:$AF$1,AN$2) -> 0
A4: 45717.25 | B4: 45717.25 | C4: 002, Київ, пр. Ак.Вернадського 16 | J4: 244.626 | AF4: 1409.811 | AG4: {=INDEX(tex!C:C,MATCH(C4,tex!B:B,0),)} -> 48 | AH4: =YEAR(A4) -> 2025 | AI4: =MONTH(A4) -> 3 | AJ4: =SUMIFS($D4:$AF4,$D$1:$AF$1,AJ$2) -> 1409.811 | AK4: =SUMIFS($D4:$AF4,$D$1:$AF$1,AK$2) -> 0 | AL4: =SUMIFS($D4:$AF4,$D$1:$AF$1,AL$2) -> 0 | AM4: =SUMIFS($D4:$AF4,$D$1:$AF$1,AM$2) -> 244.626 | AN4: =SUMIFS($D4:$AF4,$D$1:$AF$1,AN$2) -> 0
A5: 45717.25 | B5: 45717.25 | C5: 003, Київ, Шолуденка 16 | AF5: 1096.908 | AG5: {=INDEX(tex!C:C,MATCH(C5,tex!B:B,0),)} -> 92 | AH5: =YEAR(A5) -> 2025 | AI5: =MONTH(A5) -> 3 | AJ5: =SUMIFS($D5:$AF5,$D$1:$AF$1,AJ$2) -> 1096.908 | AK5: =SUMIFS($D5:$AF5,$D$1:$AF$1,AK$2) -> 0 | AL5: =SUMIFS($D5:$AF5,$D$1:$AF$1,AL$2) -> 0 | AM5: =SUMIFS($D5:$AF5,$D$1:$AF$1,AM$2) -> 0 | AN5: =SUMIFS($D5:$AF5,$D$1:$AF$1,AN$2) -> 0
A6: 45717.25 | B6: 45717.25 | C6: 005, Київ, Воскресенський пр-т, 20 | H6: 836.931 | J6: 1119.811 | AB6: 521.54 | AC6: 268.049 | AF6: 3382.601 | AG6: {=INDEX(tex!C:C,MATCH(C6,tex!B:B,0),)} -> 21 | AH6: =YEAR(A6) -> 2025 | AI6: =MONTH(A6) -> 3 | AJ6: =SUMIFS($D6:$AF6,$D$1:$AF$1,AJ$2) -> 3904.141 | AK6: =SUMIFS($D6:$AF6,$D$1:$AF$1,AK$2) -> 1104.98 | AL6: =SUMIFS($D6:$AF6,$D$1:$AF$1,AL$2) -> 0 | AM6: =SUMIFS($D6:$AF6,$D$1:$AF$1,AM$2) -> 1119.811 | AN6: =SUMIFS($D6:$AF6,$D$1:$AF$1,AN$2) -> 0
A7: 45717.25 | B7: 45717.25 | C7: 007, Київ, Будівельників 29 | H7: 384.792 | AB7: 263.266 | AF7: 2059.552 | AG7: {=INDEX(tex!C:C,MATCH(C7,tex!B:B,0),)} -> 112 | AH7: =YEAR(A7) -> 2025 | AI7: =MONTH(A7) -> 3 | AJ7: =SUMIFS($D7:$AF7,$D$1:$AF$1,AJ$2) -> 2322.818 | AK7: =SUMIFS($D7:$AF7,$D$1:$AF$1,AK$2) -> 384.792 | AL7: =SUMIFS($D7:$AF7,$D$1:$AF$1,AL$2) -> 0 | AM7: =SUMIFS($D7:$AF7,$D$1:$AF$1,AM$2) -> 0 | AN7: =SUMIFS($D7:$AF7,$D$1:$AF$1,AN$2) -> 0
A8: 45717.25 | B8: 45717.25 | C8: 008, Київ, Котляревського бул 2 | AG8: {=INDEX(tex!C:C,MATCH(C8,tex!B:B,0),)} -> 113 | AH8: =YEAR(A8) -> 2025 | AI8: =MONTH(A8) -> 3 | AJ8: =SUMIFS($D8:$AF8,$D$1:$AF$1,AJ$2) -> 0 | AK8: =SUMIFS($D8:$AF8,$D$1:$AF$1,AK$2) -> 0 | AL8: =SUMIFS($D8:$AF8,$D$1:$AF$1,AL$2) -> 0 | AM8: =SUMIFS($D8:$AF8,$D$1:$AF$1,AM$2) -> 0 | AN8: =SUMIFS($D8:$AF8,$D$1:$AF$1,AN$2) -> 0
A9: 45717.25 | B9: 45717.25 | C9: 010, Київ, Малишка 15 | J9: 1116.209 | AG9: {=INDEX(tex!C:C,MATCH(C9,tex!B:B,0),)} -> 117 | AH9: =YEAR(A9) -> 2025 | AI9: =MONTH(A9) -> 3 | AJ9: =SUMIFS($D9:$AF9,$D$1:$AF$1,AJ$2) -> 0 | AK9: =SUMIFS($D9:$AF9,$D$1:$AF$1,AK$2) -> 0 | AL9: =SUMIFS($D9:$AF9,$D$1:$AF$1,AL$2) -> 0 | AM9: =SUMIFS($D9:$AF9,$D$1:$AF$1,AM$2) -> 1116.209 | AN9: =SUMIFS($D9:$AF9,$D$1:$AF$1,AN$2) -> 0
A10: 45717.25 | B10: 45717.25 | C10: 011, Київ, Харківське шосе 9 | AG10: {=INDEX(tex!C:C,MATCH(C10,tex!B:B,0),)} -> 118 | AH10: =YEAR(A10) -> 2025 | AI10: =MONTH(A10) -> 3 | AJ10: =SUMIFS($D10:$AF10,$D$1:$AF$1,AJ$2) -> 0 | AK10: =SUMIFS($D10:$AF10,$D$1:$AF$1,AK$2) -> 0 | AL10: =SUMIFS($D10:$AF10,$D$1:$AF$1,AL$2) -> 0 | AM10: =SUMIFS($D10:$AF10,$D$1:$AF$1,AM$2) -> 0 | AN10: =SUMIFS($D10:$AF10,$D$1:$AF$1,AN$2) -> 0
A11: 45717.25 | B11: 45717.25 | C11: 013, Київ, Л.Каденюка пр 2/35 | AG11: {=INDEX(tex!C:C,MATCH(C11,tex!B:B,0),)} -> 123 | AH11: =YEAR(A11) -> 2025 | AI11: =MONTH(A11) -> 3 | AJ11: =SUMIFS($D11:$AF11,$D$1:$AF$1,AJ$2) -> 0 | AK11: =SUMIFS($D11:$AF11,$D$1:$AF$1,AK$2) -> 0 | AL11: =SUMIFS($D11:$AF11,$D$1:$AF$1,AL$2) -> 0 | AM11: =SUMIFS($D11:$AF11,$D$1:$AF$1,AM$2) -> 0 | AN11: =SUMIFS($D11:$AF11,$D$1:$AF$1,AN$2) -> 0
A12: 45717.25 | B12: 45717.25 | C12: 015, Київ, Гродненська 1/35 | AG12: {=INDEX(tex!C:C,MATCH(C12,tex!B:B,0),)} -> 131 | AH12: =YEAR(A12) -> 2025 | AI12: =MONTH(A12) -> 3 | AJ12: =SUMIFS($D12:$AF12,$D$1:$AF$1,AJ$2) -> 0 | AK12: =SUMIFS($D12:$AF12,$D$1:$AF$1,AK$2) -> 0 | AL12: =SUMIFS($D12:$AF12,$D$1:$AF$1,AL$2) -> 0 | AM12: =SUMIFS($D12:$AF12,$D$1:$AF$1,AM$2) -> 0 | AN12: =SUMIFS($D12:$AF12,$D$1:$AF$1,AN$2) -> 0
A13: 45717.25 | B13: 45717.25 | C13: 017, Київ, Миропільська 1 | AG13: {=INDEX(tex!C:C,MATCH(C13,tex!B:B,0),)} -> 149 | AH13: =YEAR(A13) -> 2025 | AI13: =MONTH(A13) -> 3 | AJ13: =SUMIFS($D13:$AF13,$D$1:$AF$1,AJ$2) -> 0 | AK13: =SUMIFS($D13:$AF13,$D$1:$AF$1,AK$2) -> 0 | AL13: =SUMIFS($D13:$AF13,$D$1:$AF$1,AL$2) -> 0 | AM13: =SUMIFS($D13:$AF13,$D$1:$AF$1,AM$2) -> 0 | AN13: =SUMIFS($D13:$AF13,$D$1:$AF$1,AN$2) -> 0
A14: 45717.25 | B14: 45717.25 | C14: 018, Київ, Голосіївський пр-т 104 | H14: 9.852 | J14: 689.354 | AB14: 480.286 | AG14: {=INDEX(tex!C:C,MATCH(C14,tex!B:B,0),)} -> 148 | AH14: =YEAR(A14) -> 2025 | AI14: =MONTH(A14) -> 3 | AJ14: =SUMIFS($D14:$AF14,$D$1:$AF$1,AJ$2) -> 480.286 | AK14: =SUMIFS($D14:$AF14,$D$1:$AF$1,AK$2) -> 9.852 | AL14: =SUMIFS($D14:$AF14,$D$1:$AF$1,AL$2) -> 0 | AM14: =SUMIFS($D14:$AF14,$D$1:$AF$1,AM$2) -> 689.354 | AN14: =SUMIFS($D14:$AF14,$D$1:$AF$1,AN$2) -> 0
A15: 45717.25 | B15: 45717.25 | C15: 019, Київ, бул. Верховної Ради 27 | AG15: {=INDEX(tex!C:C,MATCH(C15,tex!B:B,0),)} -> 285 | AH15: =YEAR(A15) -> 2025 | AI15: =MONTH(A15) -> 3 | AJ15: =SUMIFS($D15:$AF15,$D$1:$AF$1,AJ$2) -> 0 | AK15: =SUMIFS($D15:$AF15,$D$1:$AF$1,AK$2) -> 0 | AL15: =SUMIFS($D15:$AF15,$D$1:$AF$1,AL$2) -> 0 | AM15: =SUMIFS($D15:$AF15,$D$1:$AF$1,AM$2) -> 0 | AN15: =SUMIFS($D15:$AF15,$D$1:$AF$1,AN$2) -> 0
A16: 45717.25 | B16: 45717.25 | C16: 020, Київ, Левицького 5 | H16: 679.634 | J16: 572.287 | AB16: 321.349 | AF16: 1802.488 | AG16: {=INDEX(tex!C:C,MATCH(C16,tex!B:B,0),)} -> 162 | AH16: =YEAR(A16) -> 2025 | AI16: =MONTH(A16) -> 3 | AJ16: =SUMIFS($D16:$AF16,$D$1:$AF$1,AJ$2) -> 2123.837 | AK16: =SUMIFS($D16:$AF16,$D$1:$AF$1,AK$2) -> 679.634 | AL16: =SUMIFS($D16:$AF16,$D$1:$AF$1,AL$2) -> 0 | AM16: =SUMIFS($D16:$AF16,$D$1:$AF$1,AM$2) -> 572.287 | AN16: =SUMIFS($D16:$AF16,$D$1:$AF$1,AN$2) -> 0
A17: 45717.25 | B17: 45717.25 | C17: 021, Київ, Воскресенський пр-т, 23-Б | H17: 779.317 | AB17: 291.78 | AG17: {=INDEX(tex!C:C,MATCH(C17,tex!B:B,0),)} -> 287 | AH17: =YEAR(A17) -> 2025 | AI17: =MONTH(A17) -> 3 | AJ17: =SUMIFS($D17:$AF17,$D$1:$AF$1,AJ$2) -> 291.78 | AK17: =SUMIFS($D17:$AF17,$D$1:$AF$1,AK$2) -> 779.317 | AL17: =SUMIFS($D17:$AF17,$D$1:$AF$1,AL$2) -> 0 | AM17: =SUMIFS($D17:$AF17,$D$1:$AF$1,AM$2) -> 0 | AN17: =SUMIFS($D17:$AF17,$D$1:$AF$1,AN$2) -> 0
A18: 45717.25 | B18: 45717.25 | C18: 022, Київ, Воскресенський пр-т 14 | J18: 1176.413 | AG18: {=INDEX(tex!C:C,MATCH(C18,tex!B:B,0),)} -> 169 | AH18: =YEAR(A18) -> 2025 | AI18: =MONTH(A18) -> 3 | AJ18: =SUMIFS($D18:$AF18,$D$1:$AF$1,AJ$2) -> 0 | AK18: =SUMIFS($D18:$AF18,$D$1:$AF$1,AK$2) -> 0 | AL18: =SUMIFS($D18:$AF18,$D$1:$AF$1,AL$2) -> 0 | AM18: =SUMIFS($D18:$AF18,$D$1:$AF$1,AM$2) -> 1176.413 | AN18: =SUMIFS($D18:$AF18,$D$1:$AF$1,AN$2) -> 0
A19: 45717.25 | B19: 45717.25 | C19: 023, Київ, бул. Верховної Ради 17 | AB19: 53.173 | AG19: {=INDEX(tex!C:C,MATCH(C19,tex!B:B,0),)} -> 286 | AH19: =YEAR(A19) -> 2025 | AI19: =MONTH(A19) -> 3 | AJ19: =SUMIFS($D19:$AF19,$D$1:$AF$1,AJ$2) -> 53.173 | AK19: =SUMIFS($D19:$AF19,$D$1:$AF$1,AK$2) -> 0 | AL19: =SUMIFS($D19:$AF19,$D$1:$AF$1,AL$2) -> 0 | AM19: =SUMIFS($D19:$AF19,$D$1:$AF$1,AM$2) -> 0 | AN19: =SUMIFS($D19:$AF19,$D$1:$AF$1,AN$2) -> 0
A20: 45717.25 | B20: 45717.25 | C20: 027, Київ, Павла Вірського б-р 6А | H20: 649.911 | J20: 722.242 | AB20: 232.44 | AF20: 3187.954 | AG20: {=INDEX(tex!C:C,MATCH(C20,tex!B:B,0),)} -> 189 | AH20: =YEAR(A20) -> 2025 | AI20: =MONTH(A20) -> 3 | AJ20: =SUMIFS($D20:$AF20,$D$1:$AF$1,AJ$2) -> 3420.394 | AK20: =SUMIFS($D20:$AF20,$D$1:$AF$1,AK$2) -> 649.911 | AL20: =SUMIFS($D20:$AF20,$D$1:$AF$1,AL$2) -> 0 | AM20: =SUMIFS($D20:$AF20,$D$1:$AF$1,AM$2) -> 722.242 | AN20: =SUMIFS($D20:$AF20,$D$1:$AF$1,AN$2) -> 0
A21: 45717.25 | B21: 45717.25 | C21: 028, Київ, Голосіївський пр-т, 118 | H21: 988.453 | J21: 650.15 | O21: 1124.525 | AB21: 397.384 | AF21: 2171.468 | AG21: {=INDEX(tex!C:C,MATCH(C21,tex!B:B,0),)} -> 199 | AH21: =YEAR(A21) -> 2025 | AI21: =MONTH(A21) -> 3 | AJ21: =SUMIFS($D21:$AF21,$D$1:$AF$1,AJ$2) -> 3693.377 | AK21: =SUMIFS($D21:$AF21,$D$1:$AF$1,AK$2) -> 988.453 | AL21: =SUMIFS($D21:$AF21,$D$1:$AF$1,AL$2) -> 0 | AM21: =SUMIFS($D21:$AF21,$D$1:$AF$1,AM$2) -> 650.15 | AN21: =SUMIFS($D21:$AF21,$D$1:$AF$1,AN$2) -> 0
A22: 45717.25 | B22: 45717.25 | C22: 033, Київ, Зодчих 52 | J22: 1191.128 | AB22: 558.036 | AG22: {=INDEX(tex!C:C,MATCH(C22,tex!B:B,0),)} -> 239 | AH22: =YEAR(A22) -> 2025 | AI22: =MONTH(A22) -> 3 | AJ22: =SUMIFS($D22:$AF22,$D$1:$AF$1,AJ$2) -> 558.036 | AK22: =SUMIFS($D22:$AF22,$D$1:$AF$1,AK$2) -> 0 | AL22: =SUMIFS($D22:$AF22,$D$1:$AF$1,AL$2) -> 0 | AM22: =SUMIFS($D22:$AF22,$D$1:$AF$1,AM$2) -> 1191.128 | AN22: =SUMIFS($D22:$AF22,$D$1:$AF$1,AN$2) -> 0
A23: 45717.25 | B23: 45717.25 | C23: 039, Київ, Горлівська 124/143 | AG23: {=INDEX(tex!C:C,MATCH(C23,tex!B:B,0),)} -> 258 | AH23: =YEAR(A23) -> 2025 | AI23: =MONTH(A23) -> 3 | AJ23: =SUMIFS($D23:$AF23,$D$1:$AF$1,AJ$2) -> 0 | AK23: =SUMIFS($D23:$AF23,$D$1:$AF$1,AK$2) -> 0 | AL23: =SUMIFS($D23:$AF23,$D$1:$AF$1,AL$2) -> 0 | AM23: =SUMIFS($D23:$AF23,$D$1:$AF$1,AM$2) -> 0 | AN23: =SUMIFS($D23:$AF23,$D$1:$AF$1,AN$2) -> 0
A24: 45717.25 | B24: 45717.25 | C24: 041, Київ, Бажана 30 | AG24: {=INDEX(tex!C:C,MATCH(C24,tex!B:B,0),)} -> 260 | AH24: =YEAR(A24) -> 2025 | AI24: =MONTH(A24) -> 3 | AJ24: =SUMIFS($D24:$AF24,$D$1:$AF$1,AJ$2) -> 0 | AK24: =SUMIFS($D24:$AF24,$D$1:$AF$1,AK$2) -> 0 | AL24: =SUMIFS($D24:$AF24,$D$1:$AF$1,AL$2) -> 0 | AM24: =SUMIFS($D24:$AF24,$D$1:$AF$1,AM$2) -> 0 | AN24: =SUMIFS($D24:$AF24,$D$1:$AF$1,AN$2) -> 0
A25: 45717.25 | B25: 45717.25 | C25: 042, Київ, Воскресенський пр-т, 44 | AF25: 1355.298 | AG25: {=INDEX(tex!C:C,MATCH(C25,tex!B:B,0),)} -> 282 | AH25: =YEAR(A25) -> 2025 | AI25: =MONTH(A25) -> 3 | AJ25: =SUMIFS($D25:$AF25,$D$1:$AF$1,AJ$2) -> 1355.298 | AK25: =SUMIFS($D25:$AF25,$D$1:$AF$1,AK$2) -> 0 | AL25: =SUMIFS($D25:$AF25,$D$1:$AF$1,AL$2) -> 0 | AM25: =SUMIFS($D25:$AF25,$D$1:$AF$1,AM$2) -> 0 | AN25: =SUMIFS($D25:$AF25,$D$1:$AF$1,AN$2) -> 0
A26: 45717.25 | B26: 45717.25 | C26: 046, Бровари, Броварської сотні 12 | AG26: {=INDEX(tex!C:C,MATCH(C26,tex!B:B,0),)} -> 295 | AH26: =YEAR(A26) -> 2025 | AI26: =MONTH(A26) -> 3 | AJ26: =SUMIFS($D26:$AF26,$D$1:$AF$1,AJ$2) -> 0 | AK26: =SUMIFS($D26:$AF26,$D$1:$AF$1,AK$2) -> 0 | AL26: =SUMIFS($D26:$AF26,$D$1:$AF$1,AL$2) -> 0 | AM26: =SUMIFS($D26:$AF26,$D$1:$AF$1,AM$2) -> 0 | AN26: =SUMIFS($D26:$AF26,$D$1:$AF$1,AN$2) -> 0
A27: 45717.25 | B27: 45717.25 | C27: 047, Київ, Мрії 24 | H27: 923.239 | J27: 700.718 | O27: 1201.525 | AB27: 635.376 | AG27: {=INDEX(tex!C:C,MATCH(C27,tex!B:B,0),)} -> 298 | AH27: =YEAR(A27) -> 2025 | AI27: =MONTH(A27) -> 3 | AJ27: =SUMIFS($D27:$AF27,$D$1:$AF$1,AJ$2) -> 1836.901 | AK27: =SUMIFS($D27:$AF27,$D$1:$AF$1,AK$2) -> 923.239 | AL27: =SUMIFS($D27:$AF27,$D$1:$AF$1,AL$2) -> 0 | AM27: =SUMIFS($D27:$AF27,$D$1:$AF$1,AM$2) -> 700.718 | AN27: =SUMIFS($D27:$AF27,$D$1:$AF$1,AN$2) -> 0
A28: 45717.25 | B28: 45717.25 | C28: 048, Київ, Лісовий пр. 23 | H28: 828.77 | J28: 886.551 | AB28: 387.769 | AF28: 2149.469 | AG28: {=INDEX(tex!C:C,MATCH(C28,tex!B:B,0),)} -> 294 | AH28: =YEAR(A28) -> 2025 | AI28: =MONTH(A28) -> 3 | AJ28: =SUMIFS($D28:$AF28,$D$1:$AF$1,AJ$2) -> 2537.238 | AK28: =SUMIFS($D28:$AF28,$D$1:$AF$1,AK$2) -> 828.77 | AL28: =SUMIFS($D28:$AF28,$D$1:$AF$1,AL$2) -> 0 | AM28: =SUMIFS($D28:$AF28,$D$1:$AF$1,AM$2) -> 886.551 | AN28: =SUMIFS($D28:$AF28,$D$1:$AF$1,AN$2) -> 0
A29: 45717.25 | B29: 45717.25 | C29: 049, Київ, Північна 46 | H29: 506.94 | J29: 1256.239 | AB29: 517.46 | AG29: {=INDEX(tex!C:C,MATCH(C29,tex!B:B,0),)} -> 310 | AH29: =YEAR(A29) -> 2025 | AI29: =MONTH(A29) -> 3 | AJ29: =SUMIFS($D29:$AF29,$D$1:$AF$1,AJ$2) -> 517.46 | AK29: =SUMIFS($D29:$AF29,$D$1:$AF$1,AK$2) -> 506.94 | AL29: =SUMIFS($D29:$AF29,$D$1:$AF$1,AL$2) -> 0 | AM29: =SUMIFS($D29:$AF29,$D$1:$AF$1,AM$2) -> 1256.239 | AN29: =SUMIFS($D29:$AF29,$D$1:$AF$1,AN$2) -> 0
A30: 45717.25 | B30: 45717.25 | C30: 064, Бородянка, Центральна 343 | H30: 561.09 | J30: 848.318 | AB30: 320.371 | AF30: 3199.659 | AG30: {=INDEX(tex!C:C,MATCH(C30,tex!B:B,0),)} -> 318 | AH30: =YEAR(A30) -> 2025 | AI30: =MONTH(A30) -> 3 | AJ30: =SUMIFS($D30:$AF30,$D$1:$AF$1,AJ$2) -> 3520.03 | AK30: =SUMIFS($D30:$AF30,$D$1:$AF$1,AK$2) -> 561.09 | AL30: =SUMIFS($D30:$AF30,$D$1:$AF$1,AL$2) -> 0 | AM30: =SUMIFS($D30:$AF30,$D$1:$AF$1,AM$2) -> 848.318 | AN30: =SUMIFS($D30:$AF30,$D$1:$AF$1,AN$2) -> 0
A31: 45717.25 | B31: 45717.25 | C31: 065, Київ, Драйзера 24 | H31: 682.602 | J31: 662.27 | O31: 1280.866 | AB31: 269.153 | AF31: 2184.113 | AG31: {=INDEX(tex!C:C,MATCH(C31,tex!B:B,0),)} -> 320 | AH31: =YEAR(A31) -> 2025 | AI31: =MONTH(A31) -> 3 | AJ31: =SUMIFS($D31:$AF31,$D$1:$AF$1,AJ$2) -> 3734.132 | AK31: =SUMIFS($D31:$AF31,$D$1:$AF$1,AK$2) -> 682.602 | AL31: =SUMIFS($D31:$AF31,$D$1:$AF$1,AL$2) -> 0 | AM31: =SUMIFS($D31:$AF31,$D$1:$AF$1,AM$2) -> 662.27 | AN31: =SUMIFS($D31:$AF31,$D$1:$AF$1,AN$2) -> 0
A32: 45717.25 | B32: 45717.25 | C32: 066, Київ, Іжакевича 1/24 | H32: 335.638 | AG32: {=INDEX(tex!C:C,MATCH(C32,tex!B:B,0),)} -> 321 | AH32: =YEAR(A32) -> 2025 | AI32: =MONTH(A32) -> 3 | AJ32: =SUMIFS($D32:$AF32,$D$1:$AF$1,AJ$2) -> 0 | AK32: =SUMIFS($D32:$AF32,$D$1:$AF$1,AK$2) -> 335.638 | AL32: =SUMIFS($D32:$AF32,$D$1:$AF$1,AL$2) -> 0 | AM32: =SUMIFS($D32:$AF32,$D$1:$AF$1,AM$2) -> 0 | AN32: =SUMIFS($D32:$AF32,$D$1:$AF$1,AN$2) -> 0
A33: 45717.25 | B33: 45717.25 | C33: 067, Київ, Василенко 19 | AG33: {=INDEX(tex!C:C,MATCH(C33,tex!B:B,0),)} -> 323 | AH33: =YEAR(A33) -> 2025 | AI33: =MONTH(A33) -> 3 | AJ33: =SUMIFS($D33:$AF33,$D$1:$AF$1,AJ$2) -> 0 | AK33: =SUMIFS($D33:$AF33,$D$1:$AF$1,AK$2) -> 0 | AL33: =SUMIFS($D33:$AF33,$D$1:$AF$1,AL$2) -> 0 | AM33: =SUMIFS($D33:$AF33,$D$1:$AF$1,AM$2) -> 0 | AN33: =SUMIFS($D33:$AF33,$D$1:$AF$1,AN$2) -> 0
A34: 45717.25 | B34: 45717.25 | C34: 068, Київ, Білецького 11 | AG34: {=INDEX(tex!C:C,MATCH(C34,tex!B:B,0),)} -> 429 | AH34: =YEAR(A34) -> 2025 | AI34: =MONTH(A34) -> 3 | AJ34: =SUMIFS($D34:$AF34,$D$1:$AF$1,AJ$2) -> 0 | AK34: =SUMIFS($D34:$AF34,$D$1:$AF$1,AK$2) -> 0 | AL34: =SUMIFS($D34:$AF34,$D$1:$AF$1,AL$2) -> 0 | AM34: =SUMIFS($D34:$AF34,$D$1:$AF$1,AM$2) -> 0 | AN34: =SUMIFS($D34:$AF34,$D$1:$AF$1,AN$2) -> 0
A35: 45717.25 | B35: 45717.25 | C35: 070, Київ, Ялтинська 6 | AG35: {=INDEX(tex!C:C,MATCH(C35,tex!B:B,0),)} -> 367 | AH35: =YEAR(A35) -> 2025 | AI35: =MONTH(A35) -> 3 | AJ35: =SUMIFS($D35:$AF35,$D$1:$AF$1,AJ$2) -> 0 | AK35: =SUMIFS($D35:$AF35,$D$1:$AF$1,AK$2) -> 0 | AL35: =SUMIFS($D35:$AF35,$D$1:$AF$1,AL$2) -> 0 | AM35: =SUMIFS($D35:$AF35,$D$1:$AF$1,AM$2) -> 0 | AN35: =SUMIFS($D35:$AF35,$D$1:$AF$1,AN$2) -> 0
A36: 45717.25 | B36: 45717.25 | C36: 077, Київ, Кубанської України 55 | AG36: {=INDEX(tex!C:C,MATCH(C36,tex!B:B,0),)} -> 434 | AH36: =YEAR(A36) -> 2025 | AI36: =MONTH(A36) -> 3 | AJ36: =SUMIFS($D36:$AF36,$D$1:$AF$1,AJ$2) -> 0 | AK36: =SUMIFS($D36:$AF36,$D$1:$AF$1,AK$2) -> 0 | AL36: =SUMIFS($D36:$AF36,$D$1:$AF$1,AL$2) -> 0 | AM36: =SUMIFS($D36:$AF36,$D$1:$AF$1,AM$2) -> 0 | AN36: =SUMIFS($D36:$AF36,$D$1:$AF$1,AN$2) -> 0
A37: 45717.25 | B37: 45717.25 | C37: 079, Вишневе, Освіти 2 | AG37: {=INDEX(tex!C:C,MATCH(C37,tex!B:B,0),)} -> 426 | AH37: =YEAR(A37) -> 2025 | AI37: =MONTH(A37) -> 3 | AJ37: =SUMIFS($D37:$AF37,$D$1:$AF$1,AJ$2) -> 0 | AK37: =SUMIFS($D37:$AF37,$D$1:$AF$1,AK$2) -> 0 | AL37: =SUMIFS($D37:$AF37,$D$1:$AF$1,AL$2) -> 0 | AM37: =SUMIFS($D37:$AF37,$D$1:$AF$1,AM$2) -> 0 | AN37: =SUMIFS($D37:$AF37,$D$1:$AF$1,AN$2) -> 0
A38: 45717.25 | B38: 45717.25 | C38: 081, Київ, Р.Ратушного 21а | AG38: {=INDEX(tex!C:C,MATCH(C38,tex!B:B,0),)} -> 442 | AH38: =YEAR(A38) -> 2025 | AI38: =MONTH(A38) -> 3 | AJ38: =SUMIFS($D38:$AF38,$D$1:$AF$1,AJ$2) -> 0 | AK38: =SUMIFS($D38:$AF38,$D$1:$AF$1,AK$2) -> 0 | AL38: =SUMIFS($D38:$AF38,$D$1:$AF$1,AL$2) -> 0 | AM38: =SUMIFS($D38:$AF38,$D$1:$AF$1,AM$2) -> 0 | AN38: =SUMIFS($D38:$AF38,$D$1:$AF$1,AN$2) -> 0
A39: 45717.25 | B39: 45717.25 | C39: 082, Київ, Антонова 11 | AG39: {=INDEX(tex!C:C,MATCH(C39,tex!B:B,0),)} -> 440 | AH39: =YEAR(A39) -> 2025 | AI39: =MONTH(A39) -> 3 | AJ39: =SUMIFS($D39:$AF39,$D$1:$AF$1,AJ$2) -> 0 | AK39: =SUMIFS($D39:$AF39,$D$1:$AF$1,AK$2) -> 0 | AL39: =SUMIFS($D39:$AF39,$D$1:$AF$1,AL$2) -> 0 | AM39: =SUMIFS($D39:$AF39,$D$1:$AF$1,AM$2) -> 0 | AN39: =SUMIFS($D39:$AF39,$D$1:$AF$1,AN$2) -> 0
A40: 45717.25 | B40: 45717.25 | C40: 083, Київ, Соломянська 40/4 | H40: 539.81 | J40: 621.743 | AF40: 1679.168 | AG40: {=INDEX(tex!C:C,MATCH(C40,tex!B:B,0),)} -> 444 | AH40: =YEAR(A40) -> 2025 | AI40: =MONTH(A40) -> 3 | AJ40: =SUMIFS($D40:$AF40,$D$1:$AF$1,AJ$2) -> 1679.168 | AK40: =SUMIFS($D40:$AF40,$D$1:$AF$1,AK$2) -> 539.81 | AL40: =SUMIFS($D40:$AF40,$D$1:$AF$1,AL$2) -> 0 | AM40: =SUMIFS($D40:$AF40,$D$1:$AF$1,AM$2) -> 621.743 | AN40: =SUMIFS($D40:$AF40,$D$1:$AF$1,AN$2) -> 0
...

Sheet Аркуш2
A1: Дата | B1: Час | C1: Магазин | D1: Витяжка ПКВ | E1: Гриль шаурма | F1: Ел. плита | G1: Модульна піч | H1: ПКВ | I1: ПКВ гриль | J1: ПКВ допік | K1: ПКВ копчення | L1: ПКВ піч | M1: Піч Піца1 | N1: Піч піца | O1: Піч піца1 | P1: Піч піца2 | Q1: Розстоєчна шафа | R1: Ротаційна піч | S1: Тензометрія ПКВ | T1: Тензометрія ПКВ гриль | U1: Тензометрія ПКВ допік | V1: Тензометрія ПКВ копчення | W1: Тензометрія Теплова вітрина | X1: Тензометрія Теплова вітрина1 | Y1: Тензометрія Теплова вітрина2 | Z1: Теплова вітрина | AA1: Теплова вітрина 1 | AB1: Теплова вітрина1 | AC1: Теплова вітрина2 | AD1: ЩС Піца | AE1: ЩС пекарня | AF1: ЩС піца
A3: ="""" & A1 & """" &"," -> "Дата", | B3: ="""" & B1 & """" &"," -> "Час", | C3: ="""" & C1 & """" &"," -> "Магазин", | D3: ="""" & D1 & """" &"," -> "Витяжка ПКВ", | E3: ="""" & E1 & """" &"," -> "Гриль шаурма", | F3: ="""" & F1 & """" &"," -> "Ел. плита", | G3: ="""" & G1 & """" &"," -> "Модульна піч", | H3: ="""" & H1 & """" &"," -> "ПКВ", | ... AE3: ="""" & AE1 & """" &"," -> "ЩС пекарня", | AF3: ="""" & AF1 & """" -> "ЩС піца"

Sheet Аркуш3
A1: Filid year month Пиццерия Гриль Стріт-Фуд Допёк Пекарня
A2: 0 NaN 2026 4 0.000 NaN NaN NaN NaN
A3: 1 NaN 2026 4 0.000 NaN NaN NaN NaN
A4: 2 NaN 2026 4 0.000 NaN NaN NaN NaN
A5: 3 NaN 2026 4 0.000 NaN NaN NaN NaN
A6: 4 NaN 2026 4 0.000 NaN NaN NaN NaN
A7: 5 NaN 2026 4 1881.272 NaN NaN NaN NaN
A8: 6 NaN 2026 4 0.000 NaN NaN NaN NaN
A9: 7 NaN 2026 4 4090.008 NaN NaN NaN NaN
A10: 8 NaN 2026 4 14725.008 NaN NaN NaN NaN
A11: 9 NaN 2026 4 13118.256 NaN NaN NaN NaN
A12: 10 NaN 2026 4 0.000 NaN NaN NaN NaN
... A438: 436 4359.0 2026 4 0.000 NaN NaN NaN NaN

Sheet січень 2026
D1: {=INDEX(довід_обладнання!$B:$B,MATCH(D2,довід_обладнання!$A:$A,0),)} -> Гриль | E1: {=INDEX(довід_обладнання!$B:$B,MATCH(E2,довід_обладнання!$A:$A,0),)} -> Стрит-Фуд | F1: {=INDEX(довід_обладнання!$B:$B,MATCH(F2,довід_обладнання!$A:$A,0),)} -> 0 | G1: {=INDEX(довід_обладнання!$B:$B,MATCH(G2,довід_обладнання!$A:$A,0),)} -> 0 | H1: {=INDEX(довід_обладнання!$B:$B,MATCH(H2,довід_обладнання!$A:$A,0),)} -> Гриль | I1: {=INDEX(довід_обладнання!$B:$B,MATCH(I2,довід_обладнання!$A:$A,0),)} -> Гриль | J1: {=INDEX(довід_обладнання!$B:$B,MATCH(J2,довід_обладнання!$A:$A,0),)} -> Допёк | K1: {=INDEX(довід_обладнання!$B:$B,MATCH(K2,довід_обладнання!$A:$A,0),)} -> Гриль | ... AF1: {=INDEX(довід_обладнання!$B:$B,MATCH(AF2,довід_обладнання!$A:$A,0),)} -> Пиццерия
A2: Дата | B2: Час | C2: Магазин | D2: Витяжка ПКВ | E2: Гриль шаурма | F2: Ел. плита | G2: Модульна піч | H2: ПКВ | I2: ПКВ гриль | J2: ПКВ допік | K2: ПКВ копчення | L2: ПКВ піч | M2: Піч Піца1 | N2: Піч піца | O2: Піч піца1 | P2: Піч піца2 | Q2: Розстоєчна шафа | R2: Ротаційна піч | S2: Тензометрія ПКВ | T2: Тензометрія ПКВ гриль | U2: Тензометрія ПКВ допік | V2: Тензометрія ПКВ копчення | W2: Тензометрія Теплова вітрина | X2: Тензометрія Теплова вітрина1 | Y2: Тензометрія Теплова вітрина2 | Z2: Теплова вітрина | AA2: Теплова вітрина 1 | AB2: Теплова вітрина1 | AC2: Теплова вітрина2 | AD2: ЩС Піца | AE2: ЩС пекарня | AF2: ЩС піца | AG2: Filid | AH2: year | AI2: month | AJ2: Пиццерия | AK2: Гриль | AL2: Стрит-Фуд | AM2: Допёк | AN2: Пекарня
A3: 46023 | B3: 46023 | C3: 000, Київ (МРЦ), Зрошувальна 5 | AG3: {=INDEX(tex!C:C,MATCH(C3,tex!B:B,0),)} -> #N/A | AH3: =YEAR(A3) -> 2026 | AI3: =MONTH(A3) -> 1 | AJ3: =SUMIFS($D3:$AF3,$D$1:$AF$1,AJ$2) -> 0 | AK3: =SUMIFS($D3:$AF3,$D$1:$AF$1,AK$2) -> 0 | AL3: =SUMIFS($D3:$AF3,$D$1:$AF$1,AL$2) -> 0 | AM3: =SUMIFS($D3:$AF3,$D$1:$AF$1,AM$2) -> 0 | AN3: =SUMIFS($D3:$AF3,$D$1:$AF$1,AN$2) -> 0 | AO3: ="insert into [Business_Analytic].[prod].[temp] values ("&AG3&", "&AH3&", "&AI3&", "&AJ3&", "&AK3&", "&AL3&", "&AM3&", "&AN3&");" -> #N/A
A4: 46023 | B4: 46023 | C4: 000, Київ, Алішера Навої 76 | AG4: {=INDEX(tex!C:C,MATCH(C4,tex!B:B,0),)} -> #N/A | AH4: =YEAR(A4) -> 2026 | AI4: =MONTH(A4) -> 1 | AJ4: =SUMIFS($D4:$AF4,$D$1:$AF$1,AJ$2) -> 0 | AK4: =SUMIFS($D4:$AF4,$D$1:$AF$1,AK$2) -> 0 | AL4: =SUMIFS($D4:$AF4,$D$1:$AF$1,AL$2) -> 0 | AM4: =SUMIFS($D4:$AF4,$D$1:$AF$1,AM$2) -> 0 | AN4: =SUMIFS($D4:$AF4,$D$1:$AF$1,AN$2) -> 0 | AO4: ="insert into [Business_Analytic].[prod].[temp] values ("&AG4&", "&AH4&", "&AI4&", "&AJ4&", "&AK4&", "&AL4&", "&AM4&", "&AN4&");" -> #N/A
A5: 46023 | B5: 46023 | C5: 000, Київ, Пластова 15 | AG5: {=INDEX(tex!C:C,MATCH(C5,tex!B:B,0),)} -> #N/A | AH5: =YEAR(A5) -> 2026 | AI5: =MONTH(A5) -> 1 | AJ5: =SUMIFS($D5:$AF5,$D$1:$AF$1,AJ$2) -> 0 | AK5: =SUMIFS($D5:$AF5,$D$1:$AF$1,AK$2) -> 0 | AL5: =SUMIFS($D5:$AF5,$D$1:$AF$1,AL$2) -> 0 | AM5: =SUMIFS($D5:$AF5,$D$1:$AF$1,AM$2) -> 0 | AN5: =SUMIFS($D5:$AF5,$D$1:$AF$1,AN$2) -> 0 | AO5: ="insert into [Business_Analytic].[prod].[temp] values ("&AG5&", "&AH5&", "&AI5&", "&AJ5&", "&AK5&", "&AL5&", "&AM5&", "&AN5&");" -> #N/A
A6: 46023 | B6: 46023 | C6: 000, Київ, Стальського, 23 | AG6: {=INDEX(tex!C:C,MATCH(C6,tex!B:B,0),)} -> #N/A | AH6: =YEAR(A6) -> 2026 | AI6: =MONTH(A6) -> 1 | AJ6: =SUMIFS($D6:$AF6,$D$1:$AF$1,AJ$2) -> 0 | AK6: =SUMIFS($D6:$AF6,$D$1:$AF$1,AK$2) -> 0 | AL6: =SUMIFS($D6:$AF6,$D$1:$AF$1,AL$2) -> 0 | AM6: =SUMIFS($D6:$AF6,$D$1:$AF$1,AM$2) -> 0 | AN6: =SUMIFS($D6:$AF6,$D$1:$AF$1,AN$2) -> 0 | AO6: ="insert into [Business_Analytic].[prod].[temp] values ("&AG6&", "&AH6&", "&AI6&", "&AJ6&", "&AK6&", "&AL6&", "&AM6&", "&AN6&");" -> #N/A
A7: 46023 | B7: 46023 | C7: 000, Київ, Харківське шосе 172 | AG7: {=INDEX(tex!C:C,MATCH(C7,tex!B:B,0),)} -> #N/A | AH7: =YEAR(A7) -> 2026 | AI7: =MONTH(A7) -> 1 | AJ7: =SUMIFS($D7:$AF7,$D$1:$AF$1,AJ$2) -> 0 | AK7: =SUMIFS($D7:$AF7,$D$1:$AF$1,AK$2) -> 0 | AL7: =SUMIFS($D7:$AF7,$D$1:$AF$1,AL$2) -> 0 | AM7: =SUMIFS($D7:$AF7,$D$1:$AF$1,AM$2) -> 0 | AN7: =SUMIFS($D7:$AF7,$D$1:$AF$1,AN$2) -> 0 | AO7: ="insert into [Business_Analytic].[prod].[temp] values ("&AG7&", "&AH7&", "&AI7&", "&AJ7&", "&AK7&", "&AL7&", "&AM7&", "&AN7&");" -> #N/A
A8: 46023 | B8: 46023 | C8: 001, Київ, Йорданська 20 | D8: 5.99 | H8: 142.504 | J8: 754.915 | AB8: 504.585 | AG8: {=INDEX(tex!C:C,MATCH(C8,tex!B:B,0),)} -> 47 | AH8: =YEAR(A8) -> 2026 | AI8: =MONTH(A8) -> 1 | AJ8: =SUMIFS($D8:$AF8,$D$1:$AF$1,AJ$2) -> 504.585 | AK8: =SUMIFS($D8:$AF8,$D$1:$AF$1,AK$2) -> 148.494 | AL8: =SUMIFS($D8:$AF8,$D$1:$AF$1,AL$2) -> 0 | AM8: =SUMIFS($D8:$AF8,$D$1:$AF$1,AM$2) -> 754.915 | AN8: =SUMIFS($D8:$AF8,$D$1:$AF$1,AN$2) -> 0 | AO8: ="insert into [Business_Analytic].[prod].[temp] values ("&AG8&", "&AH8&", "&AI8&", "&AJ8&", "&AK8&", "&AL8&", "&AM8&", "&AN8&");" -> insert into [Business_Analytic].[prod].[temp] values (47, 2026, 1, 504.585, 148.494, 0, 754.915, 0);
A9: 46023 | B9: 46023 | C9: 002, Київ, пр. Ак.Вернадського 16 | J9: 321.751 | AF9: 2711.688 | AG9: {=INDEX(tex!C:C,MATCH(C9,tex!B:B,0),)} -> 48 | AH9: =YEAR(A9) -> 2026 | AI9: =MONTH(A9) -> 1 | AJ9: =SUMIFS($D9:$AF9,$D$1:$AF$1,AJ$2) -> 2711.688 | AK9: =SUMIFS($D9:$AF9,$D$1:$AF$1,AK$2) -> 0 | AL9: =SUMIFS($D9:$AF9,$D$1:$AF$1,AL$2) -> 0 | AM9: =SUMIFS($D9:$AF9,$D$1:$AF$1,AM$2) -> 321.751 | AN9: =SUMIFS($D9:$AF9,$D$1:$AF$1,AN$2) -> 0 | AO9: ="insert into [Business_Analytic].[prod].[temp] values ("&AG9&", "&AH9&", "&AI9&", "&AJ9&", "&AK9&", "&AL9&", "&AM9&", "&AN9&");" -> insert into [Business_Analytic].[prod].[temp] values (48, 2026, 1, 2711.688, 0, 0, 321.751, 0);
A10: 46023 | B10: 46023 | C10: 003, Київ, Шолуденка 16 | D10: 23.919 | AF10: 1319.969 | AG10: {=INDEX(tex!C:C,MATCH(C10,tex!B:B,0),)} -> 92 | AH10: =YEAR(A10) -> 2026 | AI10: =MONTH(A10) -> 1 | AJ10: =SUMIFS($D10:$AF10,$D$1:$AF$1,AJ$2) -> 1319.969 | AK10: =SUMIFS($D10:$AF10,$D$1:$AF$1,AK$2) -> 23.919 | AL10: =SUMIFS($D10:$AF10,$D$1:$AF$1,AL$2) -> 0 | AM10: =SUMIFS($D10:$AF10,$D$1:$AF$1,AM$2) -> 0 | AN10: =SUMIFS($D10:$AF10,$D$1:$AF$1,AN$2) -> 0 | AO10: ="insert into [Business_Analytic].[prod].[temp] values ("&AG10&", "&AH10&", "&AI10&", "&AJ10&", "&AK10&", "&AL10&", "&AM10&", "&AN10&");" -> insert into [Business_Analytic].[prod].[temp] values (92, 2026, 1, 1319.969, 23.919, 0, 0, 0);
A11: 46023 | B11: 46023 | C11: 005, Київ, Воскресенський пр-т, 20 | D11: 62.966 | H11: 758.152 | J11: 1175.026 | AB11: 494.76 | AC11: 275.065 | AF11: 3383.862 | AG11: {=INDEX(tex!C:C,MATCH(C11,tex!B:B,0),)} -> 21 | AH11: =YEAR(A11) -> 2026 | AI11: =MONTH(A11) -> 1 | AJ11: =SUMIFS($D11:$AF11,$D$1:$AF$1,AJ$2) -> 3878.622 | AK11: =SUMIFS($D11:$AF11,$D$1:$AF$1,AK$2) -> 1096.183 | AL11: =SUMIFS($D11:$AF11,$D$1:$AF$1,AL$2) -> 0 | AM11: =SUMIFS($D11:$AF11,$D$1:$AF$1,AM$2) -> 1175.026 | AN11: =SUMIFS($D11:$AF11,$D$1:$AF$1,AN$2) -> 0 | AO11: ="insert into [Business_Analytic].[prod].[temp] values ("&AG11&", "&AH11&", "&AI11&", "&AJ11&", "&AK11&", "&AL11&", "&AM11&", "&AN11&");" -> insert into [Business_Analytic].[prod].[temp] values (21, 2026, 1, 3878.622, 1096.183, 0, 1175.026, 0);
A12: 46023 | B12: 46023 | C12: 007, Київ, Будівельників 29 | H12: 661.446 | AB12: 333.85 | AF12: 3271.061 | AG12: {=INDEX(tex!C:C,MATCH(C12,tex!B:B,0),)} -> 112 | AH12: =YEAR(A12) -> 2026 | AI12: =MONTH(A12) -> 1 | AJ12: =SUMIFS($D12:$AF12,$D$1:$AF$1,AJ$2) -> 3604.911 | AK12: =SUMIFS($D12:$AF12,$D$1:$AF$1,AK$2) -> 661.446 | AL12: =SUMIFS($D12:$AF12,$D$1:$AF$1,AL$2) -> 0 | AM12: =SUMIFS($D12:$AF12,$D$1:$AF$1,AM$2) -> 0 | AN12: =SUMIFS($D12:$AF12,$D$1:$AF$1,AN$2) -> 0 | AO12: ="insert into [Business_Analytic].[prod].[temp] values ("&AG12&", "&AH12&", "&AI12&", "&AJ12&", "&AK12&", "&AL12&", "&AM12&", "&AN12&");" -> insert into [Business_Analytic].[prod].[temp] values (112, 2026, 1, 3604.911, 661.446, 0, 0, 0);
A13: 46023 | B13: 46023 | C13: 008, Київ, Котляревського бул 2 | AG13: {=INDEX(tex!C:C,MATCH(C13,tex!B:B,0),)} -> 113 | AH13: =YEAR(A13) -> 2026 | AI13: =MONTH(A13) -> 1 | AJ13: =SUMIFS($D13:$AF13,$D$1:$AF$1,AJ$2) -> 0 | AK13: =SUMIFS($D13:$AF13,$D$1:$AF$1,AK$2) -> 0 | AL13: =SUMIFS($D13:$AF13,$D$1:$AF$1,AL$2) -> 0 | AM13: =SUMIFS($D13:$AF13,$D$1:$AF$1,AM$2) -> 0 | AN13: =SUMIFS($D13:$AF13,$D$1:$AF$1,AN$2) -> 0 | AO13: ="insert into [Business_Analytic].[prod].[temp] values ("&AG13&", "&AH13&", "&AI13&", "&AJ13&", "&AK13&", "&AL13&", "&AM13&", "&AN13&");" -> insert into [Business_Analytic].[prod].[temp] values (113, 2026, 1, 0, 0, 0, 0, 0);
A14: 46023 | B14: 46023 | C14: 010, Київ, Малишка 15 | J14: 1399.026 | AG14: {=INDEX(tex!C:C,MATCH(C14,tex!B:B,0),)} -> 117 | AH14: =YEAR(A14) -> 2026 | AI14: =MONTH(A14) -> 1 | AJ14: =SUMIFS($D14:$AF14,$D$1:$AF$1,AJ$2) -> 0 | AK14: =SUMIFS($D14:$AF14,$D$1:$AF$1,AK$2) -> 0 | AL14: =SUMIFS($D14:$AF14,$D$1:$AF$1,AL$2) -> 0 | AM14: =SUMIFS($D14:$AF14,$D$1:$AF$1,AM$2) -> 1399.026 | AN14: =SUMIFS($D14:$AF14,$D$1:$AF$1,AN$2) -> 0 | AO14: ="insert into [Business_Analytic].[prod].[temp] values ("&AG14&", "&AH14&", "&AI14&", "&AJ14&", "&AK14&", "&AL14&", "&AM14&", "&AN14&");" -> insert into [Business_Analytic].[prod].[temp] values (117, 2026, 1, 0, 0, 0, 1399.026, 0);
A15: 46023 | B15: 46023 | C15: 011, Київ, Харківське шосе 9 | AG15: {=INDEX(tex!C:C,MATCH(C15,tex!B:B,0),)} -> 118 | AH15: =YEAR(A15) -> 2026 | AI15: =MONTH(A15) -> 1 | AJ15: =SUMIFS($D15:$AF15,$D$1:$AF$1,AJ$2) -> 0 | AK15: =SUMIFS($D15:$AF15,$D$1:$AF$1,AK$2) -> 0 | AL15: =SUMIFS($D15:$AF15,$D$1:$AF$1,AL$2) -> 0 | AM15: =SUMIFS($D15:$AF15,$D$1:$AF$1,AM$2) -> 0 | AN15: =SUMIFS($D15:$AF15,$D$1:$AF$1,AN$2) -> 0 | AO15: ="insert into [Business_Analytic].[prod].[temp] values ("&AG15&", "&AH15&", "&AI15&", "&AJ15&", "&AK15&", "&AL15&", "&AM15&", "&AN15&");" -> insert into [Business_Analytic].[prod].[temp] values (118, 2026, 1, 0, 0, 0, 0, 0);
A16: 46023 | B16: 46023 | C16: 013, Київ, Л.Каденюка пр 2/35 | H16: 705.243 | J16: 139.375 | AB16: 504.027 | AG16: {=INDEX(tex!C:C,MATCH(C16,tex!B:B,0),)} -> 123 | AH16: =YEAR(A16) -> 2026 | AI16: =MONTH(A16) -> 1 | AJ16: =SUMIFS($D16:$AF16,$D$1:$AF$1,AJ$2) -> 504.027 | AK16: =SUMIFS($D16:$AF16,$D$1:$AF$1,AK$2) -> 705.243 | AL16: =SUMIFS($D16:$AF16,$D$1:$AF$1,AL$2) -> 0 | AM16: =SUMIFS($D16:$AF16,$D$1:$AF$1,AM$2) -> 139.375 | AN16: =SUMIFS($D16:$AF16,$D$1:$AF$1,AN$2) -> 0 | AO16: ="insert into [Business_Analytic].[prod].[temp] values ("&AG16&", "&AH16&", "&AI16&", "&AJ16&", "&AK16&", "&AL16&", "&AM16&", "&AN16&");" -> insert into [Business_Analytic].[prod].[temp] values (123, 2026, 1, 504.027, 705.243, 0, 139.375, 0);
A17: 46023 | B17: 46023 | C17: 014, Київ, Миропільська 19 | D17: 9.353 | H17: 159.09 | J17: 725.046 | AB17: 396.686 | AG17: {=INDEX(tex!C:C,MATCH(C17,tex!B:B,0),)} -> 130 | AH17: =YEAR(A17) -> 2026 | AI17: =MONTH(A17) -> 1 | AJ17: =SUMIFS($D17:$AF17,$D$1:$AF$1,AJ$2) -> 396.686 | AK17: =SUMIFS($D17:$AF17,$D$1:$AF$1,AK$2) -> 168.443 | AL17: =SUMIFS($D17:$AF17,$D$1:$AF$1,AL$2) -> 0 | AM17: =SUMIFS($D17:$AF17,$D$1:$AF$1,AM$2) -> 725.046 | AN17: =SUMIFS($D17:$AF17,$D$1:$AF$1,AN$2) -> 0 | AO17: ="insert into [Business_Analytic].[prod].[temp] values ("&AG17&", "&AH17&", "&AI17&", "&AJ17&", "&AK17&", "&AL17&", "&AM17&", "&AN17&");" -> insert into [Business_Analytic].[prod].[temp] values (130, 2026, 1, 396.686, 168.443, 0, 725.046, 0);
A18: 46023 | B18: 46023 | C18: 015, Київ, Гродненська 1/35 | J18: 637.533 | AF18: 2467.323 | AG18: {=INDEX(tex!C:C,MATCH(C18,tex!B:B,0),)} -> 131 | AH18: =YEAR(A18) -> 2026 | AI18: =MONTH(A18) -> 1 | AJ18: =SUMIFS($D18:$AF18,$D$1:$AF$1,AJ$2) -> 2467.323 | AK18: =SUMIFS($D18:$AF18,$D$1:$AF$1,AK$2) -> 0 | AL18: =SUMIFS($D18:$AF18,$D$1:$AF$1,AL$2) -> 0 | AM18: =SUMIFS($D18:$AF18,$D$1:$AF$1,AM$2) -> 637.533 | AN18: =SUMIFS($D18:$AF18,$D$1:$AF$1,AN$2) -> 0 | AO18: ="insert into [Business_Analytic].[prod].[temp] values ("&AG18&", "&AH18&", "&AI18&", "&AJ18&", "&AK18&", "&AL18&", "&AM18&", "&AN18&");" -> insert into [Business_Analytic].[prod].[temp] values (131, 2026, 1, 2467.323, 0, 0, 637.533, 0);
A19: 46023 | B19: 46023 | C19: 016, Київ, Алматинська 54 | H19: 651.263 | J19: 1109.447 | O19: 1464.357 | AB19: 754.941 | AF19: 2668.697 | AG19: {=INDEX(tex!C:C,MATCH(C19,tex!B:B,0),)} -> 288 | AH19: =YEAR(A19) -> 2026 | AI19: =MONTH(A19) -> 1 | AJ19: =SUMIFS($D19:$AF19,$D$1:$AF$1,AJ$2) -> 4887.995 | AK19: =SUMIFS($D19:$AF19,$D$1:$AF$1,AK$2) -> 651.263 | AL19: =SUMIFS($D19:$AF19,$D$1:$AF$1,AL$2) -> 0 | AM19: =SUMIFS($D19:$AF19,$D$1:$AF$1,AM$2) -> 1109.447 | AN19: =SUMIFS($D19:$AF19,$D$1:$AF$1,AN$2) -> 0 | AO19: ="insert into [Business_Analytic].[prod].[temp] values ("&AG19&", "&AH19&", "&AI19&", "&AJ19&", "&AK19&", "&AL19&", "&AM19&", "&AN19&");" -> insert into [Business_Analytic].[prod].[temp] values (288, 2026, 1, 4887.995, 651.263, 0, 1109.447, 0);
A20: 46023 | B20: 46023 | C20: 017, Київ, Миропільська 1 | AG20: {=INDEX(tex!C:C,MATCH(C20,tex!B:B,0),)} -> 149 | AH20: =YEAR(A20) -> 2026 | AI20: =MONTH(A20) -> 1 | AJ20: =SUMIFS($D20:$AF20,$D$1:$AF$1,AJ$2) -> 0 | AK20: =SUMIFS($D20:$AF20,$D$1:$AF$1,AK$2) -> 0 | AL20: =SUMIFS($D20:$AF20,$D$1:$AF$1,AL$2) -> 0 | AM20: =SUMIFS($D20:$AF20,$D$1:$AF$1,AM$2) -> 0 | AN20: =SUMIFS($D20:$AF20,$D$1:$AF$1,AN$2) -> 0 | AO20: ="insert into [Business_Analytic].[prod].[temp] values ("&AG20&", "&AH20&", "&AI20&", "&AJ20&", "&AK20&", "&AL20&", "&AM20&", "&AN20&");" -> insert into [Business_Analytic].[prod].[temp] values (149, 2026, 1, 0, 0, 0, 0, 0);
A21: 46023 | B21: 46023 | C21: 018, Київ, Голосіївський пр-т 104 | H21: 594.198 | J21: 880.84 | AB21: 672.904 | AG21: {=INDEX(tex!C:C,MATCH(C21,tex!B:B,0),)} -> 148 | AH21: =YEAR(A21) -> 2026 | AI21: =MONTH(A21) -> 1 | AJ21: =SUMIFS($D21:$AF21,$D$1:$AF$1,AJ$2) -> 672.904 | AK21: =SUMIFS($D21:$AF21,$D$1:$AF$1,AK$2) -> 594.198 | AL21: =SUMIFS($D21:$AF21,$D$1:$AF$1,AL$2) -> 0 | AM21: =SUMIFS($D21:$AF21,$D$1:$AF$1,AM$2) -> 880.84 | AN21: =SUMIFS($D21:$AF21,$D$1:$AF$1,AN$2) -> 0 | AO21: ="insert into [Business_Analytic].[prod].[temp] values ("&AG21&", "&AH21&", "&AI21&", "&AJ21&", "&AK21&", "&AL21&", "&AM21&", "&AN21&");" -> insert into [Business_Analytic].[prod].[temp] values (148, 2026, 1, 672.904, 594.198, 0, 880.84, 0);
A22: 46023 | B22: 46023 | C22: 019, Київ, бул. Верховної Ради 27 | AG22: {=INDEX(tex!C:C,MATCH(C22,tex!B:B,0),)} -> 285 | AH22: =YEAR(A22) -> 2026 | AI22: =MONTH(A22) -> 1 | AJ22: =SUMIFS($D22:$AF22,$D$1:$AF$1,AJ$2) -> 0 | AK22: =SUMIFS($D22:$AF22,$D$1:$AF$1,AK$2) -> 0 | AL22: =SUMIFS($D22:$AF22,$D$1:$AF$1,AL$2) -> 0 | AM22: =SUMIFS($D22:$AF22,$D$1:$AF$1,AM$2) -> 0 | AN22: =SUMIFS($D22:$AF22,$D$1:$AF$1,AN$2) -> 0 | AO22: ="insert into [Business_Analytic].[prod].[temp] values ("&AG22&", "&AH22&", "&AI22&", "&AJ22&", "&AK22&", "&AL22&", "&AM22&", "&AN22&");" -> insert into [Business_Analytic].[prod].[temp] values (285, 2026, 1, 0, 0, 0, 0, 0);
A23: 46023 | B23: 46023 | C23: 020, Київ, Левицького 5 | H23: 542.351 | J23: 760.961 | AB23: 182.537 | AF23: 1893.066 | AG23: {=INDEX(tex!C:C,MATCH(C23,tex!B:B,0),)} -> 162 | AH23: =YEAR(A23) -> 2026 | AI23: =MONTH(A23) -> 1 | AJ23: =SUMIFS($D23:$AF23,$D$1:$AF$1,AJ$2) -> 2075.603 | AK23: =SUMIFS($D23:$AF23,$D$1:$AF$1,AK$2) -> 542.351 | AL23: =SUMIFS($D23:$AF23,$D$1:$AF$1,AL$2) -> 0 | AM23: =SUMIFS($D23:$AF23,$D$1:$AF$1,AM$2) -> 760.961 | AN23: =SUMIFS($D23:$AF23,$D$1:$AF$1,AN$2) -> 0 | AO23: ="insert into [Business_Analytic].[prod].[temp] values ("&AG23&", "&AH23&", "&AI23&", "&AJ23&", "&AK23&", "&AL23&", "&AM23&", "&AN23&");" -> insert into [Business_Analytic].[prod].[temp] values (162, 2026, 1, 2075.603, 542.351, 0, 760.961, 0);
A24: 46023 | B24: 46023 | C24: 021, Київ, Воскресенський пр-т, 23-Б | H24: 876.265 | AB24: 304.89 | AG24: {=INDEX(tex!C:C,MATCH(C24,tex!B:B,0),)} -> 287 | AH24: =YEAR(A24) -> 2026 | AI24: =MONTH(A24) -> 1 | AJ24: =SUMIFS($D24:$AF24,$D$1:$AF$1,AJ$2) -> 304.89 | AK24: =SUMIFS($D24:$AF24,$D$1:$AF$1,AK$2) -> 876.265 | AL24: =SUMIFS($D24:$AF24,$D$1:$AF$1,AL$2) -> 0 | AM24: =SUMIFS($D24:$AF24,$D$1:$AF$1,AM$2) -> 0 | AN24: =SUMIFS($D24:$AF24,$D$1:$AF$1,AN$2) -> 0 | AO24: ="insert into [Business_Analytic].[prod].[temp] values ("&AG24&", "&AH24&", "&AI24&", "&AJ24&", "&AK24&", "&AL24&", "&AM24&", "&AN24&");" -> insert into [Business_Analytic].[prod].[temp] values (287, 2026, 1, 304.89, 876.265, 0, 0, 0);
A25: 46023 | B25: 46023 | C25: 022, Київ, Воскресенський пр-т 14 | J25: 1150.98 | AG25: {=INDEX(tex!C:C,MATCH(C25,tex!B:B,0),)} -> 169 | AH25: =YEAR(A25) -> 2026 | AI25: =MONTH(A25) -> 1 | AJ25: =SUMIFS($D25:$AF25,$D$1:$AF$1,AJ$2) -> 0 | AK25: =SUMIFS($D25:$AF25,$D$1:$AF$1,AK$2) -> 0 | AL25: =SUMIFS($D25:$AF25,$D$1:$AF$1,AL$2) -> 0 | AM25: =SUMIFS($D25:$AF25,$D$1:$AF$1,AM$2) -> 1150.98 | AN25: =SUMIFS($D25:$AF25,$D$1:$AF$1,AN$2) -> 0 | AO25: ="insert into [Business_Analytic].[prod].[temp] values ("&AG25&", "&AH25&", "&AI25&", "&AJ25&", "&AK25&", "&AL25&", "&AM25&", "&AN25&");" -> insert into [Business_Analytic].[prod].[temp] values (169, 2026, 1, 0, 0, 0, 1150.98, 0);
A26: 46023 | B26: 46023 | C26: 023, Київ, бул. Верховної Ради 17 | I26: 953.018 | AB26: 237.599 | AF26: 2726.559 | AG26: {=INDEX(tex!C:C,MATCH(C26,tex!B:B,0),)} -> 286 | AH26: =YEAR(A26) -> 2026 | AI26: =MONTH(A26) -> 1 | AJ26: =SUMIFS($D26:$AF26,$D$1:$AF$1,AJ$2) -> 2964.158 | AK26: =SUMIFS($D26:$AF26,$D$1:$AF$1,AK$2) -> 953.018 | AL26: =SUMIFS($D26:$AF26,$D$1:$AF$1,AL$2) -> 0 | AM26: =SUMIFS($D26:$AF26,$D$1:$AF$1,AM$2) -> 0 | AN26: =SUMIFS($D26:$AF26,$D$1:$AF$1,AN$2) -> 0 | AO26: ="insert into [Business_Analytic].[prod].[temp] values ("&AG26&", "&AH26&", "&AI26&", "&AJ26&", "&AK26&", "&AL26&", "&AM26&", "&AN26&");" -> insert into [Business_Analytic].[prod].[temp] values (286, 2026, 1, 2964.158, 953.018, 0, 0, 0);
A27: 46023 | B27: 46023 | C27: 027, Київ, Павла Вірського б-р 6А | H27: 330.033 | J27: 508.605 | AB27: 233.845 | AF27: 2657.141 | AG27: {=INDEX(tex!C:C,MATCH(C27,tex!B:B,0),)} -> 189 | AH27: =YEAR(A27) -> 2026 | AI27: =MONTH(A27) -> 1 | AJ27: =SUMIFS($D27:$AF27,$D$1:$AF$1,AJ$2) -> 2890.986 | AK27: =SUMIFS($D27:$AF27,$D$1:$AF$1,AK$2) -> 330.033 | AL27: =SUMIFS($D27:$AF27,$D$1:$AF$1,AL$2) -> 0 | AM27: =SUMIFS($D27:$AF27,$D$1:$AF$1,AM$2) -> 508.605 | AN27: =SUMIFS($D27:$AF27,$D$1:$AF$1,AN$2) -> 0 | AO27: ="insert into [Business_Analytic].[prod].[temp] values ("&AG27&", "&AH27&", "&AI27&", "&AJ27&", "&AK27&", "&AL27&", "&AM27&", "&AN27&");" -> insert into [Business_Analytic].[prod].[temp] values (189, 2026, 1, 2890.986, 330.033, 0, 508.605, 0);
A28: 46023 | B28: 46023 | C28: 028, Київ, Голосіївський пр-т, 118 | H28: 758.153 | J28: 535.594 | O28: 1329.052 | AB28: 281.069 | AF28: 2394.604 | AG28: {=INDEX(tex!C:C,MATCH(C28,tex!B:B,0),)} -> 199 | AH28: =YEAR(A28) -> 2026 | AI28: =MONTH(A28) -> 1 | AJ28: =SUMIFS($D28:$AF28,$D$1:$AF$1,AJ$2) -> 4004.725 | AK28: =SUMIFS($D28:$AF28,$D$1:$AF$1,AK$2) -> 758.153 | AL28: =SUMIFS($D28:$AF28,$D$1:$AF$1,AL$2) -> 0 | AM28: =SUMIFS($D28:$AF28,$D$1:$AF$1,AM$2) -> 535.594 | AN28: =SUMIFS($D28:$AF28,$D$1:$AF$1,AN$2) -> 0 | AO28: ="insert into [Business_Analytic].[prod].[temp] values ("&AG28&", "&AH28&", "&AI28&", "&AJ28&", "&AK28&", "&AL28&", "&AM28&", "&AN28&");" -> insert into [Business_Analytic].[prod].[temp] values (199, 2026, 1, 4004.725, 758.153, 0, 535.594, 0);
A29: 46023 | B29: 46023 | C29: 033, Київ, Зодчих 52 | J29: 1094.895 | AB29: 457.822 | AG29: {=INDEX(tex!C:C,MATCH(C29,tex!B:B,0),)} -> 239 | AH29: =YEAR(A29) -> 2026 | AI29: =MONTH(A29) -> 1 | AJ29: =SUMIFS($D29:$AF29,$D$1:$AF$1,AJ$2) -> 457.822 | AK29: =SUMIFS($D29:$AF29,$D$1:$AF$1,AK$2) -> 0 | AL29: =SUMIFS($D29:$AF29,$D$1:$AF$1,AL$2) -> 0 | AM29: =SUMIFS($D29:$AF29,$D$1:$AF$1,AM$2) -> 1094.895 | AN29: =SUMIFS($D29:$AF29,$D$1:$AF$1,AN$2) -> 0 | AO29: ="insert into [Business_Analytic].[prod].[temp] values ("&AG29&", "&AH29&", "&AI29&", "&AJ29&", "&AK29&", "&AL29&", "&AM29&", "&AN29&");" -> insert into [Business_Analytic].[prod].[temp] values (239, 2026, 1, 457.822, 0, 0, 1094.895, 0);
A30: 46023 | B30: 46023 | C30: 039, Київ, Горлівська 124/143 | AG30: {=INDEX(tex!C:C,MATCH(C30,tex!B:B,0),)} -> 258 | AH30: =YEAR(A30) -> 2026 | AI30: =MONTH(A30) -> 1 | AJ30: =SUMIFS($D30:$AF30,$D$1:$AF$1,AJ$2) -> 0 | AK30: =SUMIFS($D30:$AF30,$D$1:$AF$1,AK$2) -> 0 | AL30: =SUMIFS($D30:$AF30,$D$1:$AF$1,AL$2) -> 0 | AM30: =SUMIFS($D30:$AF30,$D$1:$AF$1,AM$2) -> 0 | AN30: =SUMIFS($D30:$AF30,$D$1:$AF$1,AN$2) -> 0 | AO30: ="insert into [Business_Analytic].[prod].[temp] values ("&AG30&", "&AH30&", "&AI30&", "&AJ30&", "&AK30&", "&AL30&", "&AM30&", "&AN30&");" -> insert into [Business_Analytic].[prod].[temp] values (258, 2026, 1, 0, 0, 0, 0, 0);
A31: 46023 | B31: 46023 | C31: 041, Київ, Бажана 30 | AG31: {=INDEX(tex!C:C,MATCH(C31,tex!B:B,0),)} -> 260 | AH31: =YEAR(A31) -> 2026 | AI31: =MONTH(A31) -> 1 | AJ31: =SUMIFS($D31:$AF31,$D$1:$AF$1,AJ$2) -> 0 | AK31: =SUMIFS($D31:$AF31,$D$1:$AF$1,AK$2) -> 0 | AL31: =SUMIFS($D31:$AF31,$D$1:$AF$1,AL$2) -> 0 | AM31: =SUMIFS($D31:$AF31,$D$1:$AF$1,AM$2) -> 0 | AN31: =SUMIFS($D31:$AF31,$D$1:$AF$1,AN$2) -> 0 | AO31: ="insert into [Business_Analytic].[prod].[temp] values ("&AG31&", "&AH31&", "&AI31&", "&AJ31&", "&AK31&", "&AL31&", "&AM31&", "&AN31&");" -> insert into [Business_Analytic].[prod].[temp] values (260, 2026, 1, 0, 0, 0, 0, 0);
A32: 46023 | B32: 46023 | C32: 042, Київ, Воскресенський пр-т, 44 | AF32: 1547.018 | AG32: {=INDEX(tex!C:C,MATCH(C32,tex!B:B,0),)} -> 282 | AH32: =YEAR(A32) -> 2026 | AI32: =MONTH(A32) -> 1 | AJ32: =SUMIFS($D32:$AF32,$D$1:$AF$1,AJ$2) -> 1547.018 | AK32: =SUMIFS($D32:$AF32,$D$1:$AF$1,AK$2) -> 0 | AL32: =SUMIFS($D32:$AF32,$D$1:$AF$1,AL$2) -> 0 | AM32: =SUMIFS($D32:$AF32,$D$1:$AF$1,AM$2) -> 0 | AN32: =SUMIFS($D32:$AF32,$D$1:$AF$1,AN$2) -> 0 | AO32: ="insert into [Business_Analytic].[prod].[temp] values ("&AG32&", "&AH32&", "&AI32&", "&AJ32&", "&AK32&", "&AL32&", "&AM32&", "&AN32&");" -> insert into [Business_Analytic].[prod].[temp] values (282, 2026, 1, 1547.018, 0, 0, 0, 0);
A33: 46023 | B33: 46023 | C33: 046, Бровари, Броварської сотні 12 (Рефіт) | AG33: {=INDEX(tex!C:C,MATCH(C33,tex!B:B,0),)} -> #N/A | AH33: =YEAR(A33) -> 2026 | AI33: =MONTH(A33) -> 1 | AJ33: =SUMIFS($D33:$AF33,$D$1:$AF$1,AJ$2) -> 0 | AK33: =SUMIFS($D33:$AF33,$D$1:$AF$1,AK$2) -> 0 | AL33: =SUMIFS($D33:$AF33,$D$1:$AF$1,AL$2) -> 0 | AM33: =SUMIFS($D33:$AF33,$D$1:$AF$1,AM$2) -> 0 | AN33: =SUMIFS($D33:$AF33,$D$1:$AF$1,AN$2) -> 0 | AO33: ="insert into [Business_Analytic].[prod].[temp] values ("&AG33&", "&AH33&", "&AI33&", "&AJ33&", "&AK33&", "&AL33&", "&AM33&", "&AN33&");" -> #N/A
A34: 46023 | B34: 46023 | C34: 047, Київ, Мрії 24 | H34: 685.337 | J34: 674.061 | O34: 904.908 | AB34: 624.592 | AF34: 4161.415 | AG34: {=INDEX(tex!C:C,MATCH(C34,tex!B:B,0),)} -> 298 | AH34: =YEAR(A34) -> 2026 | AI34: =MONTH(A34) -> 1 | AJ34: =SUMIFS($D34:$AF34,$D$1:$AF$1,AJ$2) -> 5690.915 | AK34: =SUMIFS($D34:$AF34,$D$1:$AF$1,AK$2) -> 685.337 | AL34: =SUMIFS($D34:$AF34,$D$1:$AF$1,AL$2) -> 0 | AM34: =SUMIFS($D34:$AF34,$D$1:$AF$1,AM$2) -> 674.061 | AN34: =SUMIFS($D34:$AF34,$D$1:$AF$1,AN$2) -> 0 | AO34: ="insert into [Business_Analytic].[prod].[temp] values ("&AG34&", "&AH34&", "&AI34&", "&AJ34&", "&AK34&", "&AL34&", "&AM34&", "&AN34&");" -> insert into [Business_Analytic].[prod].[temp] values (298, 2026, 1, 5690.915, 685.337, 0, 674.061, 0);
A35: 46023 | B35: 46023 | C35: 048, Київ, Лісовий пр. 23 | H35: 686.905 | AB35: 405.141 | AF35: 2006.78 | AG35: {=INDEX(tex!C:C,MATCH(C35,tex!B:B,0),)} -> 294 | AH35: =YEAR(A35) -> 2026 | AI35: =MONTH(A35) -> 1 | AJ35: =SUMIFS($D35:$AF35,$D$1:$AF$1,AJ$2) -> 2411.921 | AK35: =SUMIFS($D35:$AF35,$D$1:$AF$1,AK$2) -> 686.905 | AL35: =SUMIFS($D35:$AF35,$D$1:$AF$1,AL$2) -> 0 | AM35: =SUMIFS($D35:$AF35,$D$1:$AF$1,AM$2) -> 0 | AN35: =SUMIFS($D35:$AF35,$D$1:$AF$1,AN$2) -> 0 | AO35: ="insert into [Business_Analytic].[prod].[temp] values ("&AG35&", "&AH35&", "&AI35&", "&AJ35&", "&AK35&", "&AL35&", "&AM35&", "&AN35&");" -> insert into [Business_Analytic].[prod].[temp] values (294, 2026, 1, 2411.921, 686.905, 0, 0, 0);
A36: 46023 | B36: 46023 | C36: 049, Київ, Північна 46 | H36: 554.492 | J36: 1372.297 | AB36: 485.566 | AG36: {=INDEX(tex!C:C,MATCH(C36,tex!B:B,0),)} -> 310 | AH36: =YEAR(A36) -> 2026 | AI36: =MONTH(A36) -> 1 | AJ36: =SUMIFS($D36:$AF36,$D$1:$AF$1,AJ$2) -> 485.566 | AK36: =SUMIFS($D36:$AF36,$D$1:$AF$1,AK$2) -> 554.492 | AL36: =SUMIFS($D36:$AF36,$D$1:$AF$1,AL$2) -> 0 | AM36: =SUMIFS($D36:$AF36,$D$1:$AF$1,AM$2) -> 1372.297 | AN36: =SUMIFS($D36:$AF36,$D$1:$AF$1,AN$2) -> 0 | AO36: ="insert into [Business_Analytic].[prod].[temp] values ("&AG36&", "&AH36&", "&AI36&", "&AJ36&", "&AK36&", "&AL36&", "&AM36&", "&AN36&");" -> insert into [Business_Analytic].[prod].[temp] values (310, 2026, 1, 485.566, 554.492, 0, 1372.297, 0);
A37: 46023 | B37: 46023 | C37: 064, Бородянка, Центральна 343 | H37: 539.632 | J37: 765.695 | AB37: 412.175 | AF37: 991.669 | AG37: {=INDEX(tex!C:C,MATCH(C37,tex!B:B,0),)} -> 318 | AH37: =YEAR(A37) -> 2026 | AI37: =MONTH(A37) -> 1 | AJ37: =SUMIFS($D37:$AF37,$D$1:$AF$1,AJ$2) -> 1403.844 | AK37: =SUMIFS($D37:$AF37,$D$1:$AF$1,AK$2) -> 539.632 | AL37: =SUMIFS($D37:$AF37,$D$1:$AF$1,AL$2) -> 0 | AM37: =SUMIFS($D37:$AF37,$D$1:$AF$1,AM$2) -> 765.695 | AN37: =SUMIFS($D37:$AF37,$D$1:$AF$1,AN$2) -> 0 | AO37: ="insert into [Business_Analytic].[prod].[temp] values ("&AG37&", "&AH37&", "&AI37&", "&AJ37&", "&AK37&", "&AL37&", "&AM37&", "&AN37&");" -> insert into [Business_Analytic].[prod].[temp] values (318, 2026, 1, 1403.844, 539.632, 0, 765.695, 0);
A38: 46023 | B38: 46023 | C38: 065, Київ, Драйзера 24 | H38: 1354.725 | J38: 662.799 | O38: 1424.403 | AB38: 258.135 | AF38: 2269.217 | AG38: {=INDEX(tex!C:C,MATCH(C38,tex!B:B,0),)} -> 320 | AH38: =YEAR(A38) -> 2026 | AI38: =MONTH(A38) -> 1 | AJ38: =SUMIFS($D38:$AF38,$D$1:$AF$1,AJ$2) -> 3951.755 | AK38: =SUMIFS($D38:$AF38,$D$1:$AF$1,AK$2) -> 1354.725 | AL38: =SUMIFS($D38:$AF38,$D$1:$AF$1,AL$2) -> 0 | AM38: =SUMIFS($D38:$AF38,$D$1:$AF$1,AM$2) -> 662.799 | AN38: =SUMIFS($D38:$AF38,$D$1:$AF$1,AN$2) -> 0 | AO38: ="insert into [Business_Analytic].[prod].[temp] values ("&AG38&", "&AH38&", "&AI38&", "&AJ38&", "&AK38&", "&AL38&", "&AM38&", "&AN38&");" -> insert into [Business_Analytic].[prod].[temp] values (320, 2026, 1, 3951.755, 1354.725, 0, 662.799, 0);
A39: 46023 | B39: 46023 | C39: 066, Київ, Іжакевича 1/24 | H39: 274.49 | AG39: {=INDEX(tex!C:C,MATCH(C39,tex!B:B,0),)} -> 321 | AH39: =YEAR(A39) -> 2026 | AI39: =MONTH(A39) -> 1 | AJ39: =SUMIFS($D39:$AF39,$D$1:$AF$1,AJ$2) -> 0 | AK39: =SUMIFS($D39:$AF39,$D$1:$AF$1,AK$2) -> 274.49 | AL39: =SUMIFS($D39:$AF39,$D$1:$AF$1,AL$2) -> 0 | AM39: =SUMIFS($D39:$AF39,$D$1:$AF$1,AM$2) -> 0 | AN39: =SUMIFS($D39:$AF39,$D$1:$AF$1,AN$2) -> 0 | AO39: ="insert into [Business_Analytic].[prod].[temp] values ("&AG39&", "&AH39&", "&AI39&", "&AJ39&", "&AK39&", "&AL39&", "&AM39&", "&AN39&");" -> insert into [Business_Analytic].[prod].[temp] values (321, 2026, 1, 0, 274.49, 0, 0, 0);
A40: 46023 | B40: 46023 | C40: 067, Київ, Василенко 19 | AG40: {=INDEX(tex!C:C,MATCH(C40,tex!B:B,0),)} -> 323 | AH40: =YEAR(A40) -> 2026 | AI40: =MONTH(A40) -> 1 | AJ40: =SUMIFS($D40:$AF40,$D$1:$AF$1,AJ$2) -> 0 | AK40: =SUMIFS($D40:$AF40,$D$1:$AF$1,AK$2) -> 0 | AL40: =SUMIFS($D40:$AF40,$D$1:$AF$1,AL$2) -> 0 | AM40: =SUMIFS($D40:$AF40,$D$1:$AF$1,AM$2) -> 0 | AN40: =SUMIFS($D40:$AF40,$D$1:$AF$1,AN$2) -> 0 | AO40: ="insert into [Business_Analytic].[prod].[temp] values ("&AG40&", "&AH40&", "&AI40&", "&AJ40&", "&AK40&", "&AL40&", "&AM40&", "&AN40&");" -> insert into [Business_Analytic].[prod].[temp] values (323, 2026, 1, 0, 0, 0, 0, 0);
...

Sheet Аркуш1
A1: Дата | B1: Час | C1: Магазин | D1: Теплова вітрина1 | E1: ЩС піца
A2: 46054 | B2: 46054 | C2: 395, Попільня, Віталія Шайдюка 5А | D2: 4290094.1 | E2: 2002.512
A3: 46054 | B3: 46054 | C3: 399, Київ, пр-т Науки 58В | D3: 512.781 | E3: 4244135.5
A4: 46054 | B4: 46054 | C4: 411, Київ, Гавела Вацлава бул 4 | D4: 4294973.5 | E4: 2560.016
A10: Дата | B10: Час | C10: Магазин | D10: ПКВ | E10: ПКВ допік | F10: Піч піца1 | G10: Піч піца2 | H10: Теплова вітрина1 | I10: ЩС піца | J10: Filid | K10: year | L10: month | M10: Пиццерия | N10: Гриль | O10: Стрит-Фуд | P10: Допёк | Q10: Пекарня
A11: 46082 | B11: 46082 | C11: 102, Конотоп, Лазаревського 12 | D11: 70377.167 | E11: 1541.489 | F11: 2224 | G11: 2017.3 | H11: 342.395 | I11: 9953.749 | J11: 491 | K11: 2026 | L11: 3 | M11: 14537.444 | N11: 70377.167 | O11: 0 | P11: 1541.489 | Q11: 0
A12: 46082 | B12: 46082 | C12: 503, Теплик, Незалежності 28 | D12: 423.04 | E12: 702.579 | F12: 1364.876 | H12: 35646.717 | I12: 3543.658 | J12: 3860 | K12: 2026 | L12: 3 | M12: 40555.251 | N12: 423.04 | O12: 0 | P12: 702.579 | Q12: 0

Sheet tex
A1: 1 | B1: 001, Київ, Йорданська 20 | C1: {=INDEX(дов_філ!C:C,MATCH(A1,дов_філ!F:F,0),)} -> 47
A2: 2 | B2: 002, Київ, пр. Ак.Вернадського 16 | C2: {=INDEX(дов_філ!C:C,MATCH(A2,дов_філ!F:F,0),)} -> 48
A3: 3 | B3: 003, Київ, Шолуденка 16 | C3: {=INDEX(дов_філ!C:C,MATCH(A3,дов_філ!F:F,0),)} -> 92
A4: 5 | B4: 005, Київ, Воскресенський пр-т, 20 | C4: {=INDEX(дов_філ!C:C,MATCH(A4,дов_філ!F:F,0),)} -> 21
A5: 7 | B5: 007, Київ, Будівельників 29 | C5: {=INDEX(дов_філ!C:C,MATCH(A5,дов_філ!F:F,0),)} -> 112
A6: 8 | B6: 008, Київ, Котляревського бул 2 | C6: {=INDEX(дов_філ!C:C,MATCH(A6,дов_філ!F:F,0),)} -> 113
A7: 10 | B7: 010, Київ, Малишка 15 | C7: {=INDEX(дов_філ!C:C,MATCH(A7,дов_філ!F:F,0),)} -> 117
A8: 11 | B8: 011, Київ, Харківське шосе 9 | C8: {=INDEX(дов_філ!C:C,MATCH(A8,дов_філ!F:F,0),)} -> 118
A9: 13 | B9: 013, Київ, Л.Каденюка пр 2/35 | C9: {=INDEX(дов_філ!C:C,MATCH(A9,дов_філ!F:F,0),)} -> 123
A10: 14 | B10: 014, Київ, Миропільська 19 | C10: {=INDEX(дов_філ!C:C,MATCH(A10,дов_філ!F:F,0),)} -> 130
A11: 15 | B11: 015, Київ, Гродненська 1/35 | C11: {=INDEX(дов_філ!C:C,MATCH(A11,дов_філ!F:F,0),)} -> 131
A12: 16 | B12: 016, Київ, Алматинська 54 | C12: {=INDEX(дов_філ!C:C,MATCH(A12,дов_філ!F:F,0),)} -> 288
... A374: 535 | B374: 535, Погребище, Хмельницького 107 | C374: {=INDEX(дов_філ!C:C,MATCH(A374,дов_філ!F:F,0),)} -> 4094
A375: 538 | B375: 538, Чернігів, пр-т Миру 68 | C375: 4076
A376: 541 | B376: 541, Корюківка, Шевченка 73а | C376: 4139
A377: 506 | B377: 506, С. Борщагівка, Житня 12 | C377: 4151
A378: 509 | B378: 509, Бережани, Тернопільська 9 | C378: 3918
B379: 542, Ільїнці, Європейська 22 | C379: 4147
B380: 544, Ірпінь, Котляревського 56 | C380: 4164
B381: 545, Київ, Анатолія Солов'яненка 7 | C381: 4187
B382: 547, Київ, Чорних Запорожців 21 | C382: 4189
B383: 382, Красилівка, Європейська 1 (Оренда) | C383: 2961
B384: 462, Ірпінь, Антонова 6 | C384: 3739
B385: 528, Полонне, Л.Українки, 174 Б (Оренда) | C385: 4007
B386: 540, Київ, Столичне Шосе 1 П10 | C386: 4128
B387: 542, Іллінці, Європейська 22 | C387: 4142
B388: 548, Київ, Райдужна 67 | C388: 4190
B389: 552, Київ, Світлицького 23 | C389: 4192
B390: 421, Біла Церква, Шевченка 87 | C390: 4127
... B419: 587, Рокитне, Шевченка 9 | C419: 4354

Sheet дов_філ
A1: Магазин | B1: Магазин (укр) | C1: ID магазину | D1: SAP ID | E1: МВЗ | F1: № магазина
A3: Д КИЕВ Перова бул, 20 | B3: Д КИЇВ Перова бул, 20 | C3: 21 | D3: F005 | E3: 2021100500 | F3: 5
A4: Д КИЕВ Иорданская ул, 20 | B4: Д КИЇВ Йорданська вул, 20 | C4: 47 | D4: F001 | E4: 2021100100 | F4: 1
A5: Д КИЇВ Ак. Вернадського пр-т, 16 | B5: Д КИЇВ Ак. Вернадського пр-т, 16 | C5: 48 | D5: F002 | E5: 2021100200 | F5: 2
A6: Д КИЕВ Шолуденко ул, 16 | B6: Д КИЇВ Шолуденка вул, 16 | C6: 92 | D6: F003 | E6: 2021100300 | F6: 3
A7: Д КИЇВ Будівельників вул, 29 | B7: Д КИЇВ Будівельників вул, 29 | C7: 112 | D7: F007 | E7: 2021100700 | F7: 7
A8: Д КИЕВ Котляревського бул, 2 | B8: Д КИЇВ Котляревського бул, 2 | C8: 113 | D8: F008 | E8: 2021100800 | F8: 8
A9: Д КИЇВ Малишка вул, 15 | B9: Д КИЇВ Малишка вул, 15 | C9: 117 | D9: F010 | E9: 2021101000 | F9: 10
A10: Д КИЕВ Харьковское ш, 9 | B10: Д КИЇВ Харьківске шосе 9 | C10: 118 | D10: F011 | E10: 2021101100 | F10: 11
A11: Д КИЕВ Л.Каденюка пр, 2/35 | B11: Д КИЇВ Л.Каденюка пр, 2/35 | C11: 123 | D11: F013 | E11: 2021101300 | F11: 13
A12: Д КИЇВ Миропільська вул, 19 | B12: Д КИЇВ Миропільська, вул. 19 | C12: 130 | D12: F014 | E12: 2021101400 | F12: 14
A13: Д КИЇВ Гродненська вул, 1/35 | B13: Д КИЇВ Гродненська, вул. 1/35 | C13: 131 | D13: F015 | E13: 2021101500 | F13: 15
A14: Д КИЕВ Голосеевский пр-т, 104 | B14: Д КИЇВ Голосіївський пр-т, 104 | C14: 148 | D14: F019 | E14: 2021101900 | F14: 18
... A201: Д С.БОРЩАГОВКА Сагайдачного ул,20А | B201: Д С.БОРЩАГІВКА Сагайдачного вул,20А | C201: 2344 | D201: F369 | E201: 2021129900 | F201: 319
A202: П С.БОРЩАГОВ Сагайдачного ул,20А ВЦ | B202: П С.БОРЩАГ Сагайдачного вул,20А ВЦ | C202: 2345 | D202: P071 | E202: 20211I0412 | F202: #VALUE!
A203: Д ПОГРЕБЫ Соборная ул, 2 | B203: Д ПОГРЕБИ Соборна вул, 2 | C203: 2359 | D203: F370 | E203: 2021129600 | F203: 316
A204: Д П.БОРЩАГОВКА Львовская ул, 1 А | B204: Д П.БОРЩАГІВКА Львівська вул, 1 А | C204: 2364 | D204: F371 | E204: 2021129800 | F204: 318
A205: Д ИРПЕНЬ Университетская ул, 2Ф/3 | B205: Д ІРПІНЬ Університетська вул, 2Ф/3 | C205: 2368 | D205: F373 | E205: 2021130000 | F205: 320
A206: Д ГЛЕВАХА Грушевского ул, 42 | B206: Д ГЛЕВАХА Грушевського вул, 42 | C206: 2378 | D206: F375 | E206: 2021130200 | F206: 322
A207: Д БОРИСПОЛЬ Головатого ул, 30 | B207: Д БОРИСПІЛЬ Головатого вул, 30 | C207: 2379 | D207: F376 | E207: 2021130300 | F207: 323
A208: Д КОЦЮБИНСКОЕ Доковская ул, 14/1 | B208: Д КОЦЮБИНСЬКЕ Доківська вул, 14/1 | C208: 2392 | D208: F377 | E208: 2021130400 | F208: 324
A209: Д ВОРОНЬКОВ Вишневая ул, 18 | B209: Д ВОРОНЬКІВ Вишнева вул, 18 | C209: 2394 | D209: F379 | E209: 2021130600 | F209: 326
A210: Д КАЛИНОВКА Черниговская ул, 12 БР | B210: Д КАЛИНІВКА Чернігівська вул, 12 БР | C210: 2413 | D210: F380 | E210: 2021131200 | F210: 332
A211: Д ИРПЕНЬ Ново-Оскольская ул, 2П | B211: Д ІРПІНЬ Ново-Оскольська вул, 2П | C211: 2422 | D211: F381 | E211: 2021131300 | F211: 333
A212: Д ГАТНОЕ Институтская ул, 16 | B212: Д ГАТНЕ Інститутська вул, 16 | C212: 2472 | D212: F382 | E212: 2021130900 | F212: 329
A213: Д ЛЮТЕЖ Освободителей ул, 56А | B213: Д ЛЮТІЖ Визволителів вул, 56А | C213: 2473 | D213: F383 | E213: 2021131000 | F213: 330
A214: Д ХОТЯНОВКА Валовая ул, 2В | B214: Д ХОТЯНІВКА Валова вул, 2В | C214: 2474 | D214: F384 | E214: 2021130700 | F214: 327
... A377: Д УКРАЇНКА Соснова вул. 5А | B377: Д УКРАЇНКА Соснова вул. 5А | C377: 4070 | D377: F569 | E377: 2021108300 | F377: 480
A378: Д ПОГРЕБИЩЕ Хмельницького вул, 107 | B378: Д ПОГРЕБИЩЕ Хмельницького вул, 107 | C378: 4094 | D378: F574 | E378: 2021500800 | F378: 535 | G378: ?
A379: Д БУЧА Гмирі вул, 7-Б | B379: Д БУЧА Гмирі вул, 7-Б | C379: 4125 | D379: F576 | E379: 2021147100 | F379: 514
A380: Д КИЇВ Столичне шосе, 1 П10 | B380: Д КИЇВ Столичне шосе, 1 П10 | C380: 4128 | D380: F578 | E380: 2021148900
A381: Д КОРЮКІВКА Шевченка вул, 73-А | B381: Д КОРЮКІВКА Шевченка вул, 73-А | C381: 4139 | D381: F579 | E381: 2021301900
A382: Д КРЮКІВЩИНА Жулянська вул, 1 А | B382: Д КРЮКІВЩИНА Жулянська вул, 1 А | C382: 2680 | D382: F342 | E382: 2021127700 | F382: 294
B383: 382, Красилівка, Європейська 1 (Оренда) | C383: 2961
B384: 421, Біла Церква, Шевченка 87 | C384: 4127
B385: 513, Коростень Базарна 18в | C385: 4165
B386: 553, Бердичів, Вінницька 71 | C386: 4232
A387: Д КОЗИН Партизанська вул, 2-Д | B387: 555, Козин, Партизанська 2Д | C387: 4229 | D387: F592 | E387: 2021202800
B388: 558, Київ, Павла Вірського б-р 37 | C388: 4254
B389: 560, Київ, Тростянецька 4_2 | C389: 4259
...

Sheet довід_обладнання
A1: Большая мясорубка
A2: М`ясорубка | G2: Пиццерия | I2: якщо є ЩС піца - берем ЩС піца, інакше беремо суму по обладнанню
A3: Мешалка | G3: Гриль
A4: Витяжка ПКВ | B4: Гриль | G4: Стрит-Фуд
A5: Гриль шаурма | B5: Стрит-Фуд | G5: Допёк
A6: Ел. плита | G6: Пекарня
A7: Модульна піч
A8: ПКВ | B8: Гриль
A9: ПКВ - Помилка
A10: ПКВ гриль | B10: Гриль
A11: ПКВ допік | B11: Допёк
A12: ПКВ копчення | B12: Гриль
A13: ПКВ піч | B13: Гриль
A14: Піч піца1 | B14: Пиццерия
A15: Піч піца2 | B15: Пиццерия
A16: Розстоєчна шафа
A17: Ротаційна піч
A18: Суші | B18: Стрит-Фуд
A19: Теплова вітрина
A20: Теплова вітрина1 | B20: Пиццерия
A21: Теплова вітрина2 | B21: Гриль
A22: ЩС пекарня | B22: Пекарня
A23: ЩС піца | B23: Пиццерия
A24: Піч піца | B24: Пиццерия
