Workbook

Sheet custom.report.sheet.name
D1: {=INDEX([1]довід_обладнання!$B:$B,MATCH(D2,[1]довід_обладнання!$A:$A,0),)} -> Гриль | E1: {=INDEX([1]довід_обладнання!$B:$B,MATCH(E2,[1]довід_обладнання!$A:$A,0),)} -> Стрит-Фуд | F1: {=INDEX([1]довід_обладнання!$B:$B,MATCH(F2,[1]довід_обладнання!$A:$A,0),)} -> 0 | G1: {=INDEX([1]довід_обладнання!$B:$B,MATCH(G2,[1]довід_обладнання!$A:$A,0),)} -> 0 | H1: {=INDEX([1]довід_обладнання!$B:$B,MATCH(H2,[1]довід_обладнання!$A:$A,0),)} -> Гриль | I1: {=INDEX([1]довід_обладнання!$B:$B,MATCH(I2,[1]довід_обладнання!$A:$A,0),)} -> Гриль | J1: {=INDEX([1]довід_обладнання!$B:$B,MATCH(J2,[1]довід_обладнання!$A:$A,0),)} -> Допёк | K1: {=INDEX([1]довід_обладнання!$B:$B,MATCH(K2,[1]довід_обладнання!$A:$A,0),)} -> Гриль | ... AF1: {=INDEX([1]довід_обладнання!$B:$B,MATCH(AF2,[1]довід_обладнання!$A:$A,0),)} -> Пиццерия
A2: Дата | B2: Час | C2: Магазин | D2: Витяжка ПКВ | E2: Гриль шаурма | F2: Ел. плита | G2: Модульна піч | H2: ПКВ | I2: ПКВ гриль | J2: ПКВ допік | K2: ПКВ копчення | L2: ПКВ піч | M2: Піч Піца1 | N2: Піч піца | O2: Піч піца1 | P2: Піч піца2 | Q2: Розстоєчна шафа | R2: Ротаційна піч | S2: Тензометрія ПКВ | T2: Тензометрія ПКВ гриль | U2: Тензометрія ПКВ допік | V2: Тензометрія ПКВ копчення | W2: Тензометрія Теплова вітрина | X2: Тензометрія Теплова вітрина1 | Y2: Тензометрія Теплова вітрина2 | Z2: Теплова вітрина | AA2: Теплова вітрина 1 | AB2: Теплова вітрина1 | AC2: Теплова вітрина2 | AD2: ЩС Піца | AE2: ЩС пекарня | AF2: ЩС піца | AG2: Filid | AH2: year | AI2: month | AJ2: Пиццерия | AK2: Гриль | AL2: Стрит-Фуд | AM2: Допёк | AN2: Пекарня
A3: Дата | B3: Час | C3: Магазин | D3: Витяжка ПКВ | E3: Гриль шаурма | F3: Ел. плита | G3: Модульна піч | H3: ПКВ | I3: ПКВ Допік | J3: ПКВ гриль | K3: ПКВ допік | L3: ПКВ копчення | M3: ПКВ піч | N3: Піч піца | O3: Піч піца1 | P3: Піч піца2 | Q3: Розстоєчна шафа | R3: Ротаційна піч | S3: Тезометрія ПКВ Допік | T3: Тензометрія ПКВ | U3: Тензометрія ПКВ гриль | V3: Тензометрія ПКВ допік | W3: Тензометрія ПКВ копчення | X3: Тензометрія Теплова вітрина1 | Y3: Тензометрія Теплова вітрина2 | Z3: Тензометрія теплова вітрина1 | AA3: Теплова вітрина1 | AB3: Теплова вітрина2 | AC3: ЩС Піца | AD3: ЩС пекарня | AE3: ЩС піца
A4: 46113 | B4: 46113 | C4: 000, Київ (МРЦ), Зрошувальна 5
A5: 46113 | B5: 46113 | C5: 000, Київ, Алішера Навої 76
A6: 46113 | B6: 46113 | C6: 000, Київ, Пластова 15
A7: 46113 | B7: 46113 | C7: 000, Київ, Стальського, 23
A8: 46113 | B8: 46113 | C8: 000, Київ, Харківське шосе 172
A9: 46113 | B9: 46113 | C9: 001, Київ, Йорданська 20 | D9: 6.405 | H9: 132.837 | K9: 801.818 | AA9: 470.318
A10: 46113 | B10: 46113 | C10: 002, Київ, пр. Ак.Вернадського 16 (Рефіт)
A11: 46113 | B11: 46113 | C11: 003, Київ, Шолуденка 16 | D11: 33.235 | AE11: 1022.502
A12: 46113 | B12: 46113 | C12: 005, Київ, Воскресенський пр-т, 20 | D12: 70.815 | H12: 725.554 | K12: 1185.057 | AA12: 483.524 | AB12: 273.258 | AE12: 3197.728
A13: 46113 | B13: 46113 | C13: 007, Київ, Будівельників 29 | H13: 830.006 | AA13: 297.376 | AE13: 2982.188
A14: 46113 | B14: 46113 | C14: 008, Київ, Котляревського бул 2
A15: 46113 | B15: 46113 | C15: 010, Київ, Малишка 15 | K15: 1423.51
A16: 46113 | B16: 46113 | C16: 011, Київ, Харківське шосе 9
A17: 46113 | B17: 46113 | C17: 013, Київ, Л.Каденюка пр 2/35 | H17: 708.427 | K17: 119.553 | AA17: 507.858
A18: 46113 | B18: 46113 | C18: 014, Київ, Миропільська 19 | H18: 173.279 | K18: 742.143 | AA18: 407.534
A19: 46113 | B19: 46113 | C19: 015, Київ, Гродненська 1/35 | K19: 648.723 | AE19: 2686.181
A20: 46113 | B20: 46113 | C20: 016, Київ, Алматинська 54 | H20: 718.832 | K20: 1030.224 | O20: 1576.935 | AA20: 734.402 | AE20: 2778.298
A21: 46113 | B21: 46113 | C21: 017, Київ, Миропільська 1
A22: 46113 | B22: 46113 | C22: 018, Київ, Голосіївський пр-т 104 | H22: 619.644 | K22: 787.892 | AA22: 585.782
A23: 46113 | B23: 46113 | C23: 019, Київ, бул. Верховної Ради 27
A24: 46113 | B24: 46113 | C24: 020, Київ, Левицького 5 | H24: 668.121 | K24: 808.876 | AA24: 359.392 | AE24: 2029.52
A25: 46113 | B25: 46113 | C25: 021, Київ, Воскресенський пр-т, 23-Б | H25: 805.925 | AA25: 0.01
A26: 46113 | B26: 46113 | C26: 022, Київ, Воскресенський пр-т 14 | K26: 1231.273
A27: 46113 | B27: 46113 | C27: 023, Київ, бул. Верховної Ради 17 | H27: 278.36 | J27: 912.599 | AA27: 244.913 | AE27: 2654.572
A28: 46113 | B28: 46113 | C28: 027, Київ, Павла Вірського б-р 6А | H28: 448.825 | K28: 659.776 | AA28: 261.593 | AE28: 1906.321
A29: 46113 | B29: 46113 | C29: 028, Київ, Голосіївський пр-т, 118 | H29: 1153.362 | K29: 511.496 | O29: 1375.753 | AA29: 262.221 | AE29: 2604.364
A30: 46113 | B30: 46113 | C30: 033, Київ, Зодчих 52 | K30: 1084.32 | AA30: 344.555
A31: 46113 | B31: 46113 | C31: 039, Київ, Горлівська 124/143
A32: 46113 | B32: 46113 | C32: 041, Київ, Бажана 30
A33: 46113 | B33: 46113 | C33: 042, Київ, Воскресенський пр-т, 44 | AE33: 1436.68
A34: 46113 | B34: 46113 | C34: 046, Бровари, Броварської сотні 12 | H34: 570.699 | K34: 790.54 | O34: 1435.341 | AE34: 3147.328
A35: 46113 | B35: 46113 | C35: 047, Київ, Мрії 24 | H35: 657.393 | K35: 555.675 | O35: 507.213 | AA35: 4.032 | AE35: 3299.475
A36: 46113 | B36: 46113 | C36: 048, Київ, Лісовий пр. 23 | H36: 649.468 | K36: 848.059 | AA36: 391.965 | AE36: 2032.044
A37: 46113 | B37: 46113 | C37: 049, Київ, Північна 46 | H37: 561.527 | K37: 1281.618 | AA37: 329.318
A38: 46113 | B38: 46113 | C38: 064, Бородянка, Центральна 343 | H38: 563.18 | K38: 726.262 | AA38: 373.269 | AE38: 2758.12
A39: 46113 | B39: 46113 | C39: 065, Київ, Драйзера 24 | H39: 606.59 | K39: 707.782 | O39: 1616.028 | AA39: 205.833 | AE39: 2526.339
A40: 46113 | B40: 46113 | C40: 066, Київ, Іжакевича 1/24 | H40: 302.132
...

Sheet Аркуш1
D1: {=INDEX([1]довід_обладнання!$B:$B,MATCH(D2,[1]довід_обладнання!$A:$A,0),)} -> Гриль | E1: {=INDEX([1]довід_обладнання!$B:$B,MATCH(E2,[1]довід_обладнання!$A:$A,0),)} -> Стрит-Фуд | F1: {=INDEX([1]довід_обладнання!$B:$B,MATCH(F2,[1]довід_обладнання!$A:$A,0),)} -> 0 | G1: {=INDEX([1]довід_обладнання!$B:$B,MATCH(G2,[1]довід_обладнання!$A:$A,0),)} -> 0 | H1: {=INDEX([1]довід_обладнання!$B:$B,MATCH(H2,[1]довід_обладнання!$A:$A,0),)} -> Гриль | I1: {=INDEX([1]довід_обладнання!$B:$B,MATCH(I2,[1]довід_обладнання!$A:$A,0),)} -> Гриль | J1: {=INDEX([1]довід_обладнання!$B:$B,MATCH(J2,[1]довід_обладнання!$A:$A,0),)} -> Допёк | K1: {=INDEX([1]довід_обладнання!$B:$B,MATCH(K2,[1]довід_обладнання!$A:$A,0),)} -> Гриль | ... AF1: {=INDEX([1]довід_обладнання!$B:$B,MATCH(AF2,[1]довід_обладнання!$A:$A,0),)} -> Пиццерия
A2: Дата | B2: Час | C2: Магазин | D2: Витяжка ПКВ | E2: Гриль шаурма | F2: Ел. плита | G2: Модульна піч | H2: ПКВ | I2: ПКВ гриль | J2: ПКВ допік | K2: ПКВ копчення | L2: ПКВ піч | M2: Піч Піца1 | N2: Піч піца | O2: Піч піца1 | P2: Піч піца2 | Q2: Розстоєчна шафа | R2: Ротаційна піч | S2: Тензометрія ПКВ | T2: Тензометрія ПКВ гриль | U2: Тензометрія ПКВ допік | V2: Тензометрія ПКВ копчення | W2: Тензометрія Теплова вітрина | X2: Тензометрія Теплова вітрина1 | Y2: Тензометрія Теплова вітрина2 | Z2: Теплова вітрина | AA2: Теплова вітрина 1 | AB2: Теплова вітрина1 | AC2: Теплова вітрина2 | AD2: ЩС Піца | AE2: ЩС пекарня | AF2: ЩС піца | AG2: Filid | AH2: year | AI2: month | AJ2: Пиццерия | AK2: Гриль | AL2: Стрит-Фуд | AM2: Допёк | AN2: Пекарня
